Workbook

Sheet Sheet1
C2: 職種 | E2: 適正 | F2: 12月 | G2: 1月 | H2: 2月 | I2: 3月 | J2: 適正 | K2: 4月 | L2: 5月 | M2: 6月 | N2: 適正 | O2: 7月 | P2: 8月 | Q2: 9月 | R2: 適正 | S2: 10月 | T2: 11月 | U2: 12月 | V2: 総合職→200ｈ 一般職→165h 新卒→100h 時短→ 130h スタッフ→60h
C3: 経理 | D3: 社員 （人数） | E3: 4 | F3: 4 | G3: 3 | H3: 3 | I3: 5 | J3: 4 | K3: 4 | L3: 4 | M3: 3 | N3: 4 | O3: 1 | V3: ※昨年11月は社員5名（寺川、後藤、本間、石原、興梠）
F4: =F3-E3 -> 0 | G4: =G3-E3 -> -1 | H4: =H3-E3 -> -1 | I4: =I3-E3 -> 1 | K4: =K3-E3 -> 0 | L4: =L3-E3 -> 0 | M4: =M3-E3 -> -1 | O4: =O3-N3 -> -3 | V4: ※1-2月の社員1名は派遣社員
D5: 労働時間 | E5: 590 | F5: 590 | G5: 460 | H5: 460 | I5: 755 | J5: 590 | K5: 625 | L5: 625 | M5: 495 | O5: 495 | V5: ※3-6月の社員2名は派遣社員
F6: =F5-E5 -> 0 | G6: =G5-E5 -> -130 | H6: =H5-E5 -> -130 | I6: =I5-E5 -> 165 | K6: =K5-J5 -> 35 | L6: =L5-E5 -> 35 | M6: =M5-E5 -> -95 | O6: =O5-G5 -> 35 | V6: ※1月以降は休職中の本間さんノーカウント
D7: パート （人数） | E7: 6 | F7: 6 | G7: 6 | H7: 5 | I7: 4 | J7: 4 | K7: 4 | L7: 4 | M7: 4 | O7: 4 | V7: ※大戸さんは週1出勤のため25hでカウント
F8: =F7-E7 -> 0 | G8: =G7-E7 -> 0 | H8: =H7-E7 -> -1 | I8: =I7-E7 -> -2 | K8: =K7-J7 -> 0 | L8: =L7-J7 -> 0 | M8: =M7-L7 -> 0 | O8: =O7-N7 -> 4
D9: 労働時間 | E9: 325 | F9: 325 | G9: 325 | H9: 265 | I9: 205 | J9: 325 | K9: 205 | L9: 205 | M9: 205 | O9: 205
F10: =F9-E9 -> 0 | G10: =G9-E9 -> 0 | H10: =H9-E9 -> -60 | I10: =I9-E9 -> -120 | K10: =K9-E9 -> -120 | L10: =L9-E9 -> -120 | M10: =M9-E9 -> -120 | O10: =O9-G9 -> -120
F11: 【入社】 12月：スタッフ並木さん、濱里さん 1月：派遣社員松本さん ※6月末まで 2月：スタッフ松浦さん 3月：本間さん復帰 3月：派遣社員もう1名 | H11: 【退職/休職】 12月：石原さん（兼任） 1月：本間さん※休職 スタッフ山本さん、三木さん 2月：今西さん 3月：寺川さん | J11: 【入社】 | L11: 【退職/休職】 6月：本間さん※産休 派遣社員松本さん※6月までの契約 | N11: 【入社】 | P11: 【退職/休職】 | R11: 【入社】 | T11: 【退職/休職】
C20: 職種 | E20: 適正 | F20: 12月 | G20: 1月 | H20: 2月 | I20: 3月 | J20: 適正 | K20: 4月 | L20: 5月 | M20: 6月 | N20: 適正 | O20: 7月 | P20: 8月 | Q20: 9月 | R20: 適正 | S20: 10月 | T20: 11月 | U20: 12月
C21: 総務 | D21: 社員 （人数） | E21: 1 | F21: 1 | G21: 1 | H21: 1 | I21: 1 | J21: 1 | K21: 1 | L21: 1 | M21: 1
F22: =F21-E21 -> 0 | G22: =G21-E21 -> 0 | H22: =H21-F21 -> 0 | I22: =I21-E21 -> 0 | K22: =K21-E21 -> 0 | L22: =L21-E21 -> 0 | M22: =M21-E21 -> 0
D23: 労働時間 | E23: 165 | F23: 165 | G23: 165 | H23: 165 | I23: 165 | J23: 165 | K23: 165 | L23: 165 | M23: 165
F24: =F23-E23 -> 0 | G24: =G23-E23 -> 0 | H24: =H23-E23 -> 0 | I24: =I23-E23 -> 0 | K24: =K23-E23 -> 0 | L24: =L23-E23 -> 0 | M24: =M23-E23 -> 0
D25: パート （人数） | E25: 1 | F25: 0 | G25: 1 | H25: 1 | I25: 1 | J25: 1 | K25: 1 | L25: 1 | M25: 1
F26: =F25-E25 -> -1 | G26: =G25-E25 -> 0 | H26: =H25-E25 -> 0 | I26: =I25-E25 -> 0 | K26: =K25-E25 -> 0 | L26: =L25-E25 -> 0 | M26: =M25-E25 -> 0
D27: 労働時間 | E27: 60 | F27: 0 | G27: 60 | H27: 60 | I27: 60 | J27: 60 | K27: 60 | L27: 60 | M27: 60
F28: =F27-E27 -> -60 | G28: =G27-E27 -> 0 | H28: =H27-E27 -> 0 | I28: =I27-E27 -> 0 | K28: =K27-E27 -> 0 | L28: =L27-E27 -> 0 | M28: =M27-E27 -> 0
F29: 【入社】 1月：スタッフ嵯峨さん | H29: 【退職/休職】 12月：石原さん（兼任） ※人数としては経理でカウント | J29: 【入社】 | L29: 【退職/休職】 | N29: 【入社】 | P29: 【退職/休職】 | R29: 【入社】 | T29: 【退職/休職】
C30: 職種 | E30: 適正 | F30: 12月 | G30: 1月 | H30: 2月 | I30: 3月 | J30: 適正 | K30: 4月 | L30: 5月 | M30: 6月 | N30: 適正 | O30: 7月 | P30: 8月 | Q30: 9月 | R30: 適正 | S30: 10月 | T30: 11月 | U30: 12月 | V30: 総合職→200ｈ 一般職→165h 時短→ 130ｈ
C31: 人事 労務 | D31: 社員 | E31: 3 | F31: 3 | G31: 2 | H31: 2 | I31: 4 | J31: 3 | K31: 3 | L31: 3 | M31: 3 | V31: ※11月は社員4名（まゆか、目黒、伊東、長濱）
F32: =F32-E31 -> -9 | G32: =G31-E31 -> -1 | H32: =H31-E31 -> -1 | I32: =I31-E31 -> 1 | K32: =K31-J31 -> 0 | L32: =L31-K31 -> 0 | M32: =M31-L31 -> 0
D33: 労働時間 | E33: 425 | F33: 425 | G33: 260 | H33: 260 | I33: 555 | J33: 425 | K33: 425 | L33: 425 | M33: 425
F34: =F33-E33 -> 0 | G34: =G33-E33 -> -165 | H34: =H33-E33 -> -165 | I34: =I33-E33 -> 130 | K34: =K33-E33 -> 0 | L34: =L33-E33 -> 0 | M34: =M33-E33 -> 0
F35: 【入社】 3月：川下さん 3月：目黒さん復帰 | H35: 【退職/休職】 1月：目黒さん※休職 | J35: 【入社】 | L35: 【退職/休職】 4月：伊東さん※産休 | N35: 【入社】 | P35: 【退職/休職】 | R35: 【入社】 | T35: 【退職/休職】
C36: 職種 | E36: 適正 | F36: 12月 | G36: 1月 | H36: 2月 | I36: 3月 | J36: 適正 | K36: 4月 | L36: 5月 | M36: 6月 | N36: 適正 | O36: 7月 | P36: 8月 | Q36: 9月 | R36: 適正 | S36: 10月 | T36: 11月 | U36: 12月 | V36: 総合職→200ｈ 一般職→165h 新卒→100h 時短→ 130ｈ
C37: LP | D37: 社員 | E37: 13 | F37: 12 | G37: 12 | H37: 12 | I37: 11 | J37: 15 | K37: 13 | L37: 14 | M37: 14 | V37: ※11月は13名（佐藤さん、小澤さんが退職）
F38: =F37-E37 -> -1 | G38: =G37-E37 -> -1 | H38: =H37-E37 -> -1 | I38: =I37-E37 -> -2 | K38: =K37-J37 -> -2 | L38: =L37-J37 -> -1 | M38: =M37-J37 -> -1
D39: 労働時間 | E39: 2180 | F39: 1850 | G39: 2050 | H39: 2050 | I39: 2050 | J39: 2545 | K39: 2250 | L39: 2380 | M39: 2380
F40: =F39-E39 -> -330 | G40: =G39-E39 -> -130 | H40: =H39-E39 -> -130 | I40: =I39-E39 -> -130 | K40: =K39-J39 -> -295 | L40: =L39-J39 -> -165 | M40: =M39-J39 -> -165
F41: 【入社】 1月：提箸さん | H41: 【退職/休職】 12月：小澤さん 3月：安齋さん | J41: 【入社】 4月：宮内さん、森山さん※新卒 5月：中田さん復帰? | L41: 【退職/休職】 | N41: 【入社】 | P41: 【退職/休職】 | R41: 【入社】 | T41: 【退職/休職】 | V41: ・総合職3、一般職8、時短1(1月) | W41: ・新卒2名配属予定 ・新卒は100h換算
C42: 職種 | E42: 適正 | F42: 12月 | G42: 1月 | H42: 2月 | I42: 3月 | J42: 適正 | K42: 4月 | L42: 5月 | M42: 6月 | N42: 適正 | O42: 7月 | P42: 8月 | Q42: 9月 | R42: 適正 | S42: 10月 | T42: 11月 | U42: 12月 | V42: 総合職→200ｈ 一般職→165h 時短→ 130ｈ
C43: 受注 | D43: 社員 | E43: 16 | F43: 16 | G43: 16 | H43: 16 | I43: 17 | J43: 18 | K43: 15 | L43: 15 | M43: 16 | N43: 18 | O43: 17 | P43: 17 | Q43: 17 | R43: 20 | S43: 19 | T43: 19 | U43: 20 | V43: 受注候補は入社時に人数カウントなし（管理でカウント）
F44: =F43-E43 -> 0 | G44: =G43-E43 -> 0 | H44: =H43-E43 -> 0 | I44: =I43-E43 -> 1 | K44: =K43-J43 -> -3 | L44: =L43-J43 -> -3 | M44: =M43-J43 -> -2 | O44: =O43-N43 -> -1 | P44: =P43-N43 -> -1 | Q44: =Q43-N43 -> -1 | S44: =S43-R43 -> -1 | T44: =S43-R43 -> -1 | U44: =U43-R43 -> 0 | V44: 受注デビュー月から人数カウント
D45: 労働時間 | E45: 3130 | F45: 3130 | G45: 3130 | H45: 3130 | I45: 3295 | J45: 3500 | K45: 2895 | L45: 2895 | M45: 3095 | N45: 3500 | O45: 3295 | P45: 3295 | Q45: 3295 | R45: 3860 | S45: 3660 | T45: 3660 | U45: 3860
F46: =F45-E45 -> 0 | G46: =G45-E45 -> 0 | H46: =H45-E45 -> 0 | I46: =I45-E45 -> 165 | K46: =K45-J45 -> -605 | L46: =L45-J45 -> -605 | M46: =M45-J45 -> -405 | O46: =O45-N45 -> -205 | P46: =O45-N45 -> -205 | Q46: =Q45-N45 -> -205 | S46: =S45-R45 -> -200 | T46: =T45-R45 -> -200 | U46: =U45-R45 -> 0
F47: 【入社/デビュー】 1月；登坂さん、市川さん、加藤さん入社 2月：鎌田さん入社 3月：加藤さんデビュー | H47: 【退職/休職】 3月：鵜飼さん、伊藤さん | J47: 【入社/デビュー】 4月：太田さん入社 6月：鎌田さんデビュー | L47: 【退職/休職】 | N47: 【入社/デビュー】 7月：上村さんデビュー | P47: 【退職/休職】 | R47: 【入社/デビュー】 10月：登坂さん、市川さんデビュー 12月：太田さんデビュー | T47: 【退職/休職】
C48: 職種 | E48: 適正 | F48: 12月 | G48: 1月 | H48: 2月 | I48: 3月 | J48: 適正 | K48: 4月 | L48: 5月 | M48: 6月 | N48: 適正 | O48: 7月 | P48: 8月 | Q48: 9月 | R48: 適正 | S48: 10月 | T48: 11月 | U48: 12月 | V48: 総合職→200ｈ 一般職→165h 新卒→100h 時短→ 130ｈ
C49: 管理 | D49: 社員 | E49: 19 | F49: 15 | G49: 19 | H49: 20 | I49: 19 | J49: 22 | K49: 26 | L49: 26 | M49: 25 | N49: 23 | O49: 24 | P49: 24 | Q49: 24 | R49: 25 | S49: 22 | T49: 22 | U49: 21 | V49: 受注はデビュー月から人数マイナス
...

Sheet Sheet3
A2: 経理 | B2: 寺川 | D2: 大戸
B3: 後藤 | D3: 並木
B4: 松本（派遣） | D4: 濱里
D5: 松浦
A6: 総務 | B6: 滝澤
A8: 労務 | B8: まゆか
B9: 伊東
B10: 目黒
B11: 川下
A13: LP

Sheet Sheet2
A1: 氏名 | B1: 入社年月 | C1: 勤続年数 | D1: 勤務形態
A2: 第一事業部・藤沢
A3: 山田 | B3: 40787 | C3: 14年4ヶ月 | D3: 総合職
A4: 嶋津 | B4: 43831 | C4: 6年0ヶ月 | D4: 総合職
A5: 五十嵐 | B5: 42339 | C5: 10年1ヶ月 | D5: 総合職
A6: 伊藤 | B6: 44287 | C6: 4年9ヶ月 | D6: 総合職
A7: 渡邉 | B7: 45413 | C7: 1年8ヶ月 | D7: 総合職
A8: 梅澤 | B8: 45748 | C8: 0年9ヶ月 | D8: 総合職
A9: 鵜飼 | B9: 42095 | C9: 10年9ヶ月 | D9: 総合職
A10: 齋藤 | B10: 45261 | C10: 2年1ヶ月 | D10: 総合職
A11: 藤田(早) | B11: 42856 | C11: 8年8ヶ月 | D11: 時短
A12: 馬場 | B12: 43647 | C12: 6年6ヶ月 | D12: 総合職
A13: 角田 | B13: 45748 | C13: 0年9ヶ月 | D13: 総合職
A14: 山崎（亮） | B14: 41214 | C14: 13年2ヶ月 | D14: 総合職
... A19: 杉原 | B19: 43191 | C19: 7年9ヶ月 | D19: 総合職
A23: 受注候補
A24: 筆野 | B24: 42705 | C24: 9年1ヶ月 | D24: 総合職
A27: 上村 | B27: 45931 | C27: 0年3ヶ月 | D27: 総合職
A30: 市川 | B30: 46023 | C30: 0年0ヶ月 | D30: 総合職
A33: 登坂 | B33: 46023 | C33: 0年0ヶ月 | D33: 総合職
A36: 加藤 | B36: 46023 | C36: 0年0ヶ月 | D36: 総合職
A39: 鎌田 | B39: 46054 | C39: #NUM! | D39: 総合職
D44: 総計

Sheet 受注
C1: 職種 | E1: 12月 | F1: 1月 | G1: 2月 | H1: 3月 | I1: 4月 | J1: 5月 | K1: 6月 | L1: 7月 | M1: 8月 | N1: 9月 | O1: 10月 | P1: 11月 | Q1: 12月 | R1: 総合職→200ｈ 一般職→165h 時短→ 130ｈ
C2: 受注 | D2: 適正人数 | E2: 16 | F2: 16 | G2: 16 | H2: 17 | I2: 15 | J2: 15 | K2: 16 | L2: 17 | M2: 17 | N2: 17 | O2: 19 | P2: 19 | Q2: 20 | R2: 受注候補は入社時に人数カウントなし（管理でカウント）
D3: デビュー済
D4: デビュー前
D5: 差 | E5: =E2-#REF! -> #REF! | F5: =F2-#REF! -> #REF! | G5: =G2-#REF! -> #REF! | H5: =H2-#REF! -> #REF! | I5: =I2-#REF! -> #REF! | J5: =J2-#REF! -> #REF! | K5: =K2-#REF! -> #REF! | L5: =L2-#REF! -> #REF! | ... O5: =O2-#REF! -> #REF! | P5: =O2-#REF! -> #REF! | Q5: =Q2-#REF! -> #REF! | R5: 受注デビュー月から人数カウント
C6: 労働時間 | D6: 3130 | E6: 3130 | F6: 3130 | G6: 3130 | H6: 3295 | I6: 2895 | J6: 2895 | K6: 3095 | L6: 3295 | M6: 3295 | N6: 3295 | O6: 3660 | P6: 3660 | Q6: 3860
E7: =E6-#REF! -> #REF! | F7: =F6-#REF! -> #REF! | G7: =G6-#REF! -> #REF! | H7: =H6-#REF! -> #REF! | I7: =I6-#REF! -> #REF! | J7: =J6-#REF! -> #REF! | K7: =K6-#REF! -> #REF! | L7: =L6-#REF! -> #REF! | M7: =L6-#REF! -> #REF! | N7: =N6-#REF! -> #REF! | O7: =O6-#REF! -> #REF! | P7: =P6-#REF! -> #REF! | Q7: =Q6-#REF! -> #REF!
E8: 【入社/デビュー】 1月；登坂さん、市川さん、加藤さん入社 2月：鎌田さん入社 3月：加藤さんデビュー | G8: 【退職/休職】 3月：鵜飼さん、伊藤さん | I8: 【入社/デビュー】 4月：太田さん入社 6月：鎌田さんデビュー | J8: 【退職/休職】 | L8: 【入社/デビュー】 7月：上村さんデビュー | M8: 【退職/休職】 | O8: 【入社/デビュー】 10月：登坂さん、市川さんデビュー 12月：太田さんデビュー | P8: 【退職/休職】
C9: 職種 | E9: 12月 | F9: 1月 | G9: 2月 | H9: 3月 | I9: 4月 | J9: 5月 | K9: 6月 | L9: 7月 | M9: 8月 | N9: 9月 | O9: 10月 | P9: 11月 | Q9: 12月 | R9: 総合職→200ｈ 一般職→165h 新卒→100h 時短→ 130ｈ
C10: 管理 | D10: 社員 | E10: 15 | F10: 19 | G10: 20 | H10: 19 | I10: 26 | J10: 26 | K10: 25 | L10: 24 | M10: 24 | N10: 24 | O10: 22 | P10: 22 | Q10: 21 | R10: 受注はデビュー月から人数マイナス
E11: =E10-#REF! -> #REF! | F11: =F10-#REF! -> #REF! | G11: =G10-#REF! -> #REF! | H11: =H10-#REF! -> #REF! | I11: =I10-#REF! -> #REF! | J11: =J10-#REF! -> #REF! | K11: =K10-#REF! -> #REF! | L11: =L10-#REF! -> #REF! | ... Q11: =Q10-#REF! -> #REF!
D12: 労働時間 | E12: 2720 | F12: 3450 | G12: 3650 | H12: 3485 | I12: 4185 | J12: 4185 | K12: 3985 | L12: 3785 | M12: 3785 | N12: 3785 | O12: 3420 | P12: 3420 | Q12: 3220
E13: =E12-#REF! -> #REF! | F13: =F12-#REF! -> #REF! | G13: =G12-#REF! -> #REF! | H13: =H12-#REF! -> #REF! | I13: =I12-#REF! -> #REF! | J13: =J12-#REF! -> #REF! | K13: =K12-#REF! -> #REF! | L13: =L12-#REF! -> #REF! | ... Q13: =Q12-#REF! -> #REF!
E14: 【入社】 1月：藤倉さん、登坂さん、市川さん、加藤さん 2月：鎌田さん | G14: 【退職/休職】 2月：森下さん 3月：根本さん 3月：加藤さん受注へ | I14: 【入社】 4月：太田さん 間瀬さん、芹ケ野さん、肥後さん、外所さん、守友さん※新卒 | J14: 【退職/休職】 6月：鎌田さん受注へ | L14: 【入社】 | M14: 【退職/休職】 7月：上村さん受注へ | O14: 【入社】 | P14: 【退職/休職】 10月：登坂さん、市川さん受注へ 12月：太田さん受注へ

Sheet 受注推移
A1: 受注マンパワー推移2026
C2: 12月 | E2: 1月 | G2: 2月 | I2: 3月 | K2: 4月 | M2: 5月 | O2: 6月 | Q2: 7月 | S2: 8月 | U2: 9月 | W2: 10月 | Y2: 11月 | AA2: 12月
A3: 適正人数 | C3: 16 | E3: 16 | G3: 16 | I3: 16 | K3: 18 | M3: 18 | O3: 18 | Q3: 18 | S3: 18 | U3: 18 | W3: 20 | Y3: 20 | AA3: 20
A4: 受注担当 | C4: =C36 -> 16 | E4: =E36 -> 16 | G4: =G36 -> 16 | I4: =I36 -> 15 | K4: =K36 -> 15 | M4: =M36 -> 15 | O4: =O36 -> 16 | Q4: =Q36 -> 17 | S4: =S36 -> 17 | U4: =U36 -> 17 | W4: =W36 -> 19 | Y4: =Y36 -> 19 | AA4: =AA36 -> 21
A5: 差異 | C5: =C3-C4 -> 0 | E5: =E4-E3 -> 0 | G5: =G4-G3 -> 0 | I5: =I4-I3 -> -1 | K5: =K4-K3 -> -3 | M5: =M4-M3 -> -3 | O5: =O4-O3 -> -2 | Q5: =Q4-Q3 -> -1 | S5: =S4-S3 -> -1 | U5: =U4-U3 -> -1 | W5: =W4-W3 -> -1 | Y5: =Y4-Y3 -> -1 | AA5: =AA4-AA3 -> 1
A6: 労働時間 | C6: =D36 -> 2940 | E6: =F36 -> 2940 | G6: =H36 -> 2940 | I6: =J36 -> 2705 | K6: =L36 -> 2705 | M6: =N36 -> 2705 | O6: =P36 -> 2905 | Q6: =R36 -> 3105 | S6: =T36 -> 3105 | U6: =V36 -> 3105 | W6: =X36 -> 3470 | Y6: =Z36 -> 3470 | AA6: =AB36 -> 3870
A8: 受注候補 | C8: =C47 -> 1 | E8: =E47 -> 4 | G8: =G47 -> 5 | I8: =I47 -> 4 | K8: =K47 -> 6 | M8: =M47 -> 6 | O8: =O47 -> 5 | Q8: =Q47 -> 4 | S8: =S47 -> 4 | U8: =U47 -> 4 | W8: =W47 -> 2 | Y8: =Y47 -> 2 | AA8: =AA47 -> 0
I9: 受注人数不足
C10: 受注担当内訳
C11: 12月 | E11: 1月 | G11: 2月 | I11: 3月 | K11: 4月 | M11: 5月 | O11: 6月 | Q11: 7月 | S11: 8月 | U11: 9月 | W11: 10月 | Y11: 11月 | AA11: 12月
C12: 山田 | D12: 200 | E12: 山田 | F12: 200 | G12: 山田 | H12: 200 | I12: 山田 | J12: 200 | K12: 山田 | L12: 200 | M12: 山田 | N12: 200 | O12: 山田 | P12: 200 | Q12: 山田 | R12: 200 | S12: 山田 | T12: 200 | U12: 山田 | V12: 200 | W12: 山田 | X12: 200 | Y12: 山田 | Z12: 200 | AA12: 山田 | AB12: 200
C13: 嶋津 | D13: 200 | E13: 嶋津 | F13: 200 | G13: 嶋津 | H13: 200 | I13: 嶋津 | J13: 200 | K13: 嶋津 | L13: 200 | M13: 嶋津 | N13: 200 | O13: 嶋津 | P13: 200 | Q13: 嶋津 | R13: 200 | S13: 嶋津 | T13: 200 | U13: 嶋津 | V13: 200 | W13: 嶋津 | X13: 200 | Y13: 嶋津 | Z13: 200 | AA13: 嶋津 | AB13: 200
C14: 五十嵐 | D14: 200 | E14: 五十嵐 | F14: 200 | G14: 五十嵐 | H14: 200 | I14: 五十嵐 | J14: 200 | K14: 五十嵐 | L14: 200 | M14: 五十嵐 | N14: 200 | O14: 五十嵐 | P14: 200 | Q14: 五十嵐 | R14: 200 | S14: 五十嵐 | T14: 200 | U14: 五十嵐 | V14: 200 | W14: 五十嵐 | X14: 200 | Y14: 五十嵐 | Z14: 200 | AA14: 五十嵐 | AB14: 200
C15: 伊藤 | D15: 200 | E15: 伊藤 | F15: 200 | G15: 伊藤 | H15: 200
C16: 渡邉 | D16: 200 | E16: 渡邉 | F16: 200 | G16: 渡邉 | H16: 200 | I16: 渡邉 | J16: 200 | K16: 渡邉 | L16: 200 | M16: 渡邉 | N16: 200 | O16: 渡邉 | P16: 200 | Q16: 渡邉 | R16: 200 | S16: 渡邉 | T16: 200 | U16: 渡邉 | V16: 200 | W16: 渡邉 | X16: 200 | Y16: 渡邉 | Z16: 200 | AA16: 渡邉 | AB16: 200
C17: 梅澤 | D17: 200 | E17: 梅澤 | F17: 200 | G17: 梅澤 | H17: 200 | I17: 梅澤 | J17: 200 | K17: 梅澤 | L17: 200 | M17: 梅澤 | N17: 200 | O17: 梅澤 | P17: 200 | Q17: 梅澤 | R17: 200 | S17: 梅澤 | T17: 200 | U17: 梅澤 | V17: 200 | W17: 梅澤 | X17: 200 | Y17: 梅澤 | Z17: 200 | AA17: 梅澤 | AB17: 200
C18: 鵜飼 | D18: 200 | E18: 鵜飼 | F18: 200 | G18: 鵜飼 | H18: 200
C19: 齋藤 | D19: 200 | E19: 齋藤 | F19: 200 | G19: 齋藤 | H19: 200 | I19: 齋藤 | J19: 200 | K19: 齋藤 | L19: 200 | M19: 齋藤 | N19: 200 | O19: 齋藤 | P19: 200 | Q19: 齋藤 | R19: 200 | S19: 齋藤 | T19: 200 | U19: 齋藤 | V19: 200 | W19: 齋藤 | X19: 200 | Y19: 齋藤 | Z19: 200 | AA19: 齋藤 | AB19: 200
C20: 藤田 | D20: 130 | E20: 藤田 | F20: 130 | G20: 藤田 | H20: 130 | I20: 藤田 | J20: 130 | K20: 藤田 | L20: 130 | M20: 藤田 | N20: 130 | O20: 藤田 | P20: 130 | Q20: 藤田 | R20: 130 | S20: 藤田 | T20: 130 | U20: 藤田 | V20: 130 | W20: 藤田 | X20: 130 | Y20: 藤田 | Z20: 130 | AA20: 藤田 | AB20: 130
C21: 馬場 | D21: 200 | E21: 馬場 | F21: 200 | G21: 馬場 | H21: 200 | I21: 馬場 | J21: 200 | K21: 馬場 | L21: 200 | M21: 馬場 | N21: 200 | O21: 馬場 | P21: 200 | Q21: 馬場 | R21: 200 | S21: 馬場 | T21: 200 | U21: 馬場 | V21: 200 | W21: 馬場 | X21: 200 | Y21: 馬場 | Z21: 200 | AA21: 馬場 | AB21: 200
C22: 角田 | D22: 200 | E22: 角田 | F22: 200 | G22: 角田 | H22: 200 | I22: 角田 | J22: 200 | K22: 角田 | L22: 200 | M22: 角田 | N22: 200 | O22: 角田 | P22: 200 | Q22: 角田 | R22: 200 | S22: 角田 | T22: 200 | U22: 角田 | V22: 200 | W22: 角田 | X22: 200 | Y22: 角田 | Z22: 200 | AA22: 角田 | AB22: 200
C23: 山崎 | D23: 200 | E23: 山崎 | F23: 200 | G23: 山崎 | H23: 200 | I23: 山崎 | J23: 200 | K23: 山崎 | L23: 200 | M23: 山崎 | N23: 200 | O23: 山崎 | P23: 200 | Q23: 山崎 | R23: 200 | S23: 山崎 | T23: 200 | U23: 山崎 | V23: 200 | W23: 山崎 | X23: 200 | Y23: 山崎 | Z23: 200 | AA23: 山崎 | AB23: 200
C24: 森谷 | D24: 200 | E24: 森谷 | F24: 200 | G24: 森谷 | H24: 200 | I24: 森谷 | J24: 200 | K24: 森谷 | L24: 200 | M24: 森谷 | N24: 200 | O24: 森谷 | P24: 200 | Q24: 森谷 | R24: 200 | S24: 森谷 | T24: 200 | U24: 森谷 | V24: 200 | W24: 森谷 | X24: 200 | Y24: 森谷 | Z24: 200 | AA24: 森谷 | AB24: 200
C25: 新井 | D25: 100 | E25: 新井 | F25: 100 | G25: 新井 | H25: 100 | I25: 新井 | J25: 100 | K25: 新井 | L25: 100 | M25: 新井 | N25: 100 | O25: 新井 | P25: 100 | Q25: 新井 | R25: 100 | S25: 新井 | T25: 100 | U25: 新井 | V25: 100 | W25: 新井 | X25: 100 | Y25: 新井 | Z25: 100 | AA25: 新井 | AB25: 100
C26: 花井 | D26: 200 | E26: 花井 | F26: 200 | G26: 花井 | H26: 200 | I26: 花井 | J26: 200 | K26: 花井 | L26: 200 | M26: 花井 | N26: 200 | O26: 花井 | P26: 200 | Q26: 花井 | R26: 200 | S26: 花井 | T26: 200 | U26: 花井 | V26: 200 | W26: 花井 | X26: 200 | Y26: 花井 | Z26: 200 | AA26: 花井 | AB26: 200
C27: 杉原 | D27: 110 | E27: 杉原 | F27: 110 | G27: 杉原 | H27: 110 | I27: 杉原 | J27: 110 | K27: 杉原 | L27: 110 | M27: 杉原 | N27: 110 | O27: 杉原 | P27: 110 | Q27: 杉原 | R27: 110 | S27: 杉原 | T27: 110 | U27: 杉原 | V27: 110 | W27: 杉原 | X27: 110 | Y27: 杉原 | Z27: 110 | AA27: 杉原 | AB27: 110
I28: 加藤 | J28: 165 | K28: 加藤 | L28: 165 | M28: 加藤 | N28: 165 | O28: 加藤 | P28: 165 | Q28: 加藤 | R28: 165 | S28: 加藤 | T28: 165 | U28: 加藤 | V28: 165 | W28: 加藤 | X28: 165 | Y28: 加藤 | Z28: 165 | AA28: 加藤 | AB28: 165
O29: 鎌田 | P29: 200 | Q29: 鎌田 | R29: 200 | S29: 鎌田 | T29: 200 | U29: 鎌田 | V29: 200 | W29: 鎌田 | X29: 200 | Y29: 鎌田 | Z29: 200 | AA29: 鎌田 | AB29: 200
Q30: 上村 | R30: 200 | S30: 上村 | T30: 200 | U30: 上村 | V30: 200 | W30: 上村 | X30: 200 | Y30: 上村 | Z30: 200 | AA30: 上村 | AB30: 200
W31: 登坂 | X31: 200 | Y31: 登坂 | Z31: 200 | AA31: 登坂 | AB31: 200
W32: 市川 | X32: 165 | Y32: 市川 | Z32: 165 | AA32: 市川 | AB32: 165
AA33: 太田 | AB33: 200
AA34: 西原 | AB34: 200
C36: =COUNTA(C12:C35) -> 16 | D36: =SUM(D12:D35) -> 2940 | E36: =COUNTA(E12:E35) -> 16 | F36: =SUM(F12:F35) -> 2940 | G36: =COUNTA(G12:G35) -> 16 | H36: =SUM(H12:H35) -> 2940 | I36: =COUNTA(I12:I35) -> 15 | J36: =SUM(J12:J35) -> 2705 | K36: =COUNTA(K12:K35) -> 15 | L36: =SUM(L12:L35) -> 2705 | M36: =COUNTA(M12:M35) -> 15 | N36: =SUM(N12:N35) -> 2705 | O36: =COUNTA(O12:O35) -> 16 | P36: =SUM(P12:P35) -> 2905 | Q36: =COUNTA(Q12:Q35) -> 17 | R36: =SUM(R12:R35) -> 3105 | S36: =COUNTA(S12:S35) -> 17 | T36: =SUM(T12:T35) -> 3105 | U36: =COUNTA(U12:U35) -> 17 | V36: =SUM(V12:V35) -> 3105 | W36: =COUNTA(W12:W35) -> 19 | X36: =SUM(X12:X35) -> 3470 | Y36: =COUNTA(Y12:Y35) -> 19 | Z36: =SUM(Z12:Z35) -> 3470 | AA36: =COUNTA(AA12:AA35) -> 21 | AB36: =SUM(AB12:AB35) -> 3870
C38: 受注候補内訳
C39: 12月 | E39: 1月 | G39: 2月 | I39: 3月 | K39: 4月 | M39: 5月 | O39: 6月 | Q39: 7月 | S39: 8月 | U39: 9月 | W39: 10月 | Y39: 11月 | AA39: 12月
C40: 上村 | D40: 200 | E40: 加藤 | F40: 165 | G40: 加藤 | H40: 165 | I40: 鎌田 | J40: 200 | K40: 鎌田 | L40: 200 | M40: 鎌田 | N40: 200 | O40: 上村 | P40: 200 | Q40: 登坂 | R40: 200 | S40: 登坂 | T40: 200 | U40: 登坂 | V40: 200 | W40: 太田 | X40: 200 | Y40: 太田 | Z40: 200
E41: 上村 | F41: 200 | G41: 鎌田 | H41: 200 | I41: 上村 | J41: 200 | K41: 上村 | L41: 200 | M41: 上村 | N41: 200 | O41: 登坂 | P41: 200 | Q41: 市川 | R41: 165 | S41: 市川 | T41: 165 | U41: 市川 | V41: 165 | W41: 西原 | X41: 200 | Y41: 西原 | Z41: 200
E42: 登坂 | F42: 200 | G42: 上村 | H42: 200 | I42: 登坂 | J42: 200 | K42: 登坂 | L42: 200 | M42: 登坂 | N42: 200 | O42: 市川 | P42: 165 | Q42: 太田 | R42: 200 | S42: 太田 | T42: 200 | U42: 太田 | V42: 200
E43: 市川 | F43: 165 | G43: 登坂 | H43: 165 | I43: 市川 | J43: 165 | K43: 市川 | L43: 165 | M43: 市川 | N43: 165 | O43: 太田 | P43: 200 | Q43: 西原 | R43: 200 | S43: 西原 | T43: 200 | U43: 西原 | V43: 200
...

Sheet 相続以外
A1: マンパワー推移2026
A2: 経理 | C2: 12月 | F2: 1月 | I2: 2月 | L2: 3月 | O2: 4月 | R2: 5月 | U2: 6月 | X2: 7月 | AA2: 8月 | AD2: 9月 | AG2: 10月 | AJ2: 11月 | AM2: 12月
A3: 適正人数 | C3: 4 | F3: 4 | I3: 4 | L3: 4 | O3: 4 | R3: 4 | U3: 4 | X3: 4 | AA3: 4 | AD3: 4 | AG3: 4 | AJ3: 4 | AM3: 4
A4: 社員数 | C4: =C17 -> 4 | F4: =F17 -> 3 | I4: =I17 -> 3 | L4: =L17 -> 5 | O4: =O17 -> 4 | R4: =R17 -> 4 | U4: =U17 -> 3 | X4: =X17 -> 3 | AA4: =AA17 -> 3 | AD4: =AD17 -> 3 | AG4: =AG17 -> 3 | AJ4: =AJ17 -> 1 | AM4: =AM17 -> 1
A5: 差異 | C5: =C3-C4 -> 0 | F5: =F4-F3 -> -1 | I5: =I4-I3 -> -1 | L5: =L4-L3 -> 1 | O5: =O4-O3 -> 0 | R5: =R4-R3 -> 0 | U5: =U4-U3 -> -1 | X5: =X4-X3 -> -1 | AA5: =AA4-AA3 -> -1 | AD5: =AD4-AD3 -> -1 | AG5: =AG4-AG3 -> -1 | AJ5: =AJ4-AJ3 -> -3 | AM5: =AM4-AM3 -> -3
A6: 労働時間 | C6: =E17 -> 590 | F6: =H17 -> 460 | I6: =K17 -> 460 | L6: =N17 -> 755 | O6: =Q17 -> 625 | R6: =T17 -> 625 | U6: =W17 -> 495 | X6: =Z17 -> 495 | AA6: =AC17 -> 495 | AD6: =AF17 -> 495 | AG6: =AI17 -> 495 | AJ6: =AL17 -> 165 | AM6: =AO17 -> 165
A8: スタッフ | C8: =C27 -> 6 | F8: =F27 -> 5 | I8: =I27 -> 5 | L8: =L27 -> 4 | O8: =O27 -> 4 | R8: =R27 -> 3 | U8: =U27 -> 3 | X8: =X27 -> 3 | AA8: =AA27 -> 3 | AD8: =AD27 -> 3 | AG8: =AG27 -> 3 | AJ8: =AJ27 -> 3 | AM8: =AM27 -> 3
C10: 社員内訳 | AD10: 総合職→200ｈ 一般職→165h 時短→ 130ｈ
C11: 12月 | F11: 1月 | I11: 2月 | L11: 3月 | O11: 4月 | R11: 5月 | U11: 6月 | X11: 7月 | AA11: 8月 | AD11: 9月 | AG11: 10月 | AJ11: 11月 | AM11: 12月
C12: 寺川 | E12: 130 | F12: 寺川 | H12: 130 | I12: 寺川 | K12: 130 | L12: 寺川 | N12: 130 | O12: 後藤 | Q12: 165 | R12: 後藤 | T12: 165 | U12: 後藤 | W12: 165 | X12: 後藤 | Z12: 165 | AA12: 後藤 | AC12: 165 | AD12: 後藤 | AF12: 165 | AG12: 後藤 | AI12: 165 | AJ12: 後藤 | AL12: 165 | AM12: 後藤 | AO12: 165
C13: 後藤 | E13: 165 | F13: 後藤 | H13: 165 | I13: 後藤 | K13: 165 | L13: 後藤 | N13: 165 | O13: 本間 | Q13: 130 | R13: 本間 | T13: 130 | U13: 派遣 | W13: 165 | X13: 派遣 | Z13: 165 | AA13: 派遣 | AC13: 165 | AD13: 派遣 | AF13: 165 | AG13: 派遣 | AI13: 165
C14: 本間 | E14: 165 | F14: 派遣 | H14: 165 | I14: 派遣 | K14: 165 | L14: 派遣 | N14: 165 | O14: 派遣 | Q14: 165 | R14: 派遣 | T14: 165 | U14: 派遣 | W14: 165 | X14: 派遣 | Z14: 165 | AA14: 派遣 | AC14: 165 | AD14: 派遣 | AF14: 165 | AG14: 派遣 | AI14: 165
C15: 石原 | E15: 130 | L15: 派遣 | N15: 165 | O15: 派遣 | Q15: 165 | R15: 派遣 | T15: 165
L16: 本間 | N16: 130
C17: =COUNTA(C12:C15) -> 4 | E17: =SUM(E12:E15) -> 590 | F17: =COUNTA(F12:F15) -> 3 | H17: =SUM(H12:H15) -> 460 | I17: =COUNTA(I12:I15) -> 3 | K17: =SUM(K12:K15) -> 460 | L17: =COUNTA(L12:L16) -> 5 | N17: =SUM(N12:N16) -> 755 | O17: =COUNTA(O12:O15) -> 4 | Q17: =SUM(Q12:Q15) -> 625 | R17: =COUNTA(R12:R15) -> 4 | T17: =SUM(T12:T15) -> 625 | U17: =COUNTA(U12:U15) -> 3 | W17: =SUM(W12:W15) -> 495 | X17: =COUNTA(X12:X15) -> 3 | Z17: =SUM(Z12:Z15) -> 495 | AA17: =COUNTA(AA12:AA15) -> 3 | AC17: =SUM(AC12:AC15) -> 495 | AD17: =COUNTA(AD12:AD15) -> 3 | AF17: =SUM(AF12:AF15) -> 495 | AG17: =COUNTA(AG12:AG15) -> 3 | AI17: =SUM(AI12:AI15) -> 495 | AJ17: =COUNTA(AJ12:AJ15) -> 1 | AL17: =SUM(AL12:AL15) -> 165 | AM17: =COUNTA(AM12:AM15) -> 1 | AO17: =SUM(AO12:AO15) -> 165
C19: スタッフ内訳
C20: 12月 | F20: 1月 | I20: 2月 | L20: 3月 | O20: 4月 | R20: 5月 | U20: 6月 | X20: 7月 | AA20: 8月 | AD20: 9月 | AG20: 10月 | AJ20: 11月 | AM20: 12月
C21: 今西 | E21: 70 | F21: 今西 | H21: 70 | I21: 今西 | K21: 70 | L21: 大戸 | N21: 25 | O21: 大戸 | Q21: 25 | R21: 大戸 | T21: 25 | U21: 大戸 | W21: 25 | X21: 大戸 | Z21: 25 | AA21: 大戸 | AC21: 25 | AD21: 大戸 | AF21: 25 | AG21: 大戸 | AI21: 25 | AJ21: 大戸 | AL21: 25 | AM21: 大戸 | AO21: 25
C22: 山本 | E22: 70 | F22: 大戸 | H22: 25 | I22: 大戸 | K22: 25 | L22: 濱里 | N22: 70 | O22: 濱里 | Q22: 70 | R22: 濱里 | T22: 70 | U22: 濱里 | W22: 70 | X22: 濱里 | Z22: 70 | AA22: 濱里 | AC22: 70 | AD22: 濱里 | AF22: 70 | AG22: 濱里 | AI22: 70 | AJ22: 濱里 | AL22: 70 | AM22: 濱里 | AO22: 70
C23: 大戸 | E23: 25 | F23: 三木 | H23: 70 | I23: 濱里 | K23: 70 | L23: 並木 | N23: 70 | O23: 並木 | Q23: 70 | R23: 並木 | T23: 70 | U23: 並木 | W23: 70 | X23: 並木 | Z23: 70 | AA23: 並木 | AC23: 70 | AD23: 並木 | AF23: 70 | AG23: 並木 | AI23: 70 | AJ23: 並木 | AL23: 70 | AM23: 並木 | AO23: 70
C24: 三木 | E24: 70 | F24: 濱里 | H24: 70 | I24: 並木 | K24: 70 | L24: 松浦 | N24: 70 | O24: 松浦 | Q24: 70
C25: 濱里 | E25: 70 | F25: 並木 | H25: 70 | I25: 松浦 | K25: 70
C26: 並木 | E26: 70
C27: =COUNTA(C21:C26) -> 6 | E27: =SUM(E21:E26) -> 375 | F27: =COUNTA(F21:F26) -> 5 | H27: =SUM(H21:H26) -> 305 | I27: =COUNTA(I21:I26) -> 5 | K27: =SUM(K21:K26) -> 305 | L27: =COUNTA(L21:L26) -> 4 | N27: =SUM(N21:N26) -> 235 | O27: =COUNTA(O21:O26) -> 4 | Q27: =SUM(Q21:Q26) -> 235 | R27: =COUNTA(R21:R26) -> 3 | T27: =SUM(T21:T26) -> 165 | U27: =COUNTA(U21:U26) -> 3 | W27: =SUM(W21:W26) -> 165 | X27: =COUNTA(X21:X26) -> 3 | Z27: =SUM(Z21:Z26) -> 165 | AA27: =COUNTA(AA21:AA26) -> 3 | AC27: =SUM(AC21:AC26) -> 165 | AD27: =COUNTA(AD21:AD26) -> 3 | AF27: =SUM(AF21:AF26) -> 165 | AG27: =COUNTA(AG21:AG26) -> 3 | AI27: =SUM(AI21:AI26) -> 165 | AJ27: =COUNTA(AJ21:AJ26) -> 3 | AL27: =SUM(AL21:AL26) -> 165 | AM27: =COUNTA(AM21:AM26) -> 3 | AO27: =SUM(AO21:AO26) -> 165
AD29: 総合職→200ｈ 一般職→165h 時短→ 130ｈ
A31: 人事労務 | C31: 12月 | F31: 1月 | I31: 2月 | L31: 3月 | O31: 4月 | R31: 5月 | U31: 6月 | X31: 7月 | AA31: 8月 | AD31: 9月 | AG31: 10月 | AJ31: 11月 | AM31: 12月
A32: 適正人数 | C32: 3 | F32: 3 | I32: 3 | L32: 3 | O32: 3 | R32: 3 | U32: 3 | X32: 3 | AA32: 3 | AD32: 3 | AG32: 3 | AJ32: 3 | AM32: 3
A33: 社員数 | C33: =C43 -> 4 | F33: =F43 -> 2 | I33: =I43 -> 2 | L33: =L43 -> 4 | O33: =O43 -> 3 | R33: =R43 -> 3 | U33: =U43 -> 3 | X33: =X43 -> 3 | AA33: =AA43 -> 3 | AD33: =AD43 -> 3 | AG33: =AG43 -> 3 | AJ33: =AJ43 -> 3 | AM33: =AM43 -> 3
A34: 差異 | C34: =C33-C32 -> 1 | F34: =F33-F32 -> -1 | I34: =I33-I32 -> -1 | L34: =L33-L32 -> 1 | O34: =O33-O32 -> 0 | R34: =R33-R32 -> 0 | U34: =U33-U32 -> 0 | X34: =X33-X32 -> 0 | AA34: =AA33-AA32 -> 0 | AD34: =AD33-AD32 -> 0 | AG34: =AG33-AG32 -> 0 | AJ34: =AJ33-AJ32 -> 0 | AM34: =AM33-AM32 -> 0
A35: 労働時間 | C35: =E43 -> 590 | F35: =H43 -> 260 | I35: =K43 -> 260 | L35: =N43 -> 555 | O35: =Q43 -> 425 | R35: =T43 -> 425 | U35: =W43 -> 425 | X35: =Z43 -> 425 | AA35: =AC43 -> 425 | AD35: =AF43 -> 425 | AG35: =AI43 -> 425 | AJ35: =AL43 -> 425 | AM35: =AO43 -> 425
C37: 社員内訳
C38: 12月 | F38: 1月 | I38: 2月 | L38: 3月 | O38: 4月 | R38: 5月 | U38: 6月 | X38: 7月 | AA38: 8月 | AD38: 9月 | AG38: 10月 | AJ38: 11月 | AM38: 12月
C39: 佐藤 | E39: 130 | F39: 佐藤 | H39: 130 | I39: 佐藤 | K39: 130 | L39: 佐藤 | N39: 130 | O39: 佐藤 | Q39: 130 | R39: 佐藤 | T39: 130 | U39: 佐藤 | W39: 130 | X39: 佐藤 | Z39: 130 | AA39: 佐藤 | AC39: 130 | AD39: 佐藤 | AF39: 130 | AG39: 佐藤 | AI39: 130 | AJ39: 佐藤 | AL39: 130 | AM39: 佐藤 | AO39: 130
C40: 目黒 | E40: 165 | F40: 伊東 | H40: 130 | I40: 伊東 | K40: 130 | L40: 伊東 | N40: 130 | O40: 目黒 | Q40: 130 | R40: 目黒 | T40: 130 | U40: 目黒 | W40: 130 | X40: 目黒 | Z40: 130 | AA40: 目黒 | AC40: 130 | AD40: 目黒 | AF40: 130 | AG40: 目黒 | AI40: 130 | AJ40: 目黒 | AL40: 130 | AM40: 目黒 | AO40: 130
C41: 伊東 | E41: 130 | L41: 目黒 | N41: 130 | O41: 川下 | Q41: 165 | R41: 川下 | T41: 165 | U41: 川下 | W41: 165 | X41: 川下 | Z41: 165 | AA41: 川下 | AC41: 165 | AD41: 川下 | AF41: 165 | AG41: 川下 | AI41: 165 | AJ41: 川下 | AL41: 165 | AM41: 川下 | AO41: 165
C42: 長濱 | E42: 165 | L42: 川下 | N42: 165
C43: =COUNTA(C39:C42) -> 4 | E43: =SUM(E39:E42) -> 590 | F43: =COUNTA(F39:F42) -> 2 | H43: =SUM(H39:H42) -> 260 | I43: =COUNTA(I39:I42) -> 2 | K43: =SUM(K39:K42) -> 260 | L43: =COUNTA(L39:L42) -> 4 | N43: =SUM(N39:N42) -> 555 | O43: =COUNTA(O39:O42) -> 3 | Q43: =SUM(Q39:Q42) -> 425 | R43: =COUNTA(R39:R42) -> 3 | T43: =SUM(T39:T42) -> 425 | U43: =COUNTA(U39:U42) -> 3 | W43: =SUM(W39:W42) -> 425 | X43: =COUNTA(X39:X42) -> 3 | Z43: =SUM(Z39:Z42) -> 425 | AA43: =COUNTA(AA39:AA42) -> 3 | AC43: =SUM(AC39:AC42) -> 425 | AD43: =COUNTA(AD39:AD42) -> 3 | AF43: =SUM(AF39:AF42) -> 425 | AG43: =COUNTA(AG39:AG42) -> 3 | AI43: =SUM(AI39:AI42) -> 425 | AJ43: =COUNTA(AJ39:AJ42) -> 3 | AL43: =SUM(AL39:AL42) -> 425 | AM43: =COUNTA(AM39:AM42) -> 3 | AO43: =SUM(AO39:AO42) -> 425
A45: LP | C45: 12月 | F45: 1月 | I45: 2月 | L45: 3月 | O45: 4月 | R45: 5月 | U45: 6月 | X45: 7月 | AA45: 8月 | AD45: 9月 | AG45: 10月 | AJ45: 11月 | AM45: 12月
A46: 適正人数 | C46: 13 | F46: 13 | I46: 13 | L46: 13 | O46: 15 | R46: 15 | U46: 15
A47: 社員数 | C47: =C72 -> 14 | F47: =F72 -> 14 | I47: =I72 -> 14 | L47: =L72 -> 14 | O47: =O72 -> 15 | R47: =R72 -> 16 | U47: =U72 -> 16 | X47: =X72 -> 15 | AA47: =AA72 -> 15 | AD47: =AD72 -> 15 | AG47: =AG72 -> 15 | AJ47: =AJ72 -> 15 | AM47: =AM72 -> 15
...

Sheet LP
A1: LPマンパワー推移2026
A2: LP | C2: 12月 | H2: 1月 | M2: 2月 | R2: 3月 | W2: 4月 | AB2: 5月 | AG2: 6月 | AL2: 7月 | AQ2: 8月 | AV2: 9月 | BA2: 10月 | BF2: 11月 | BK2: 12月
A3: 適正人数 | C3: 13 | H3: 13 | M3: 13 | R3: 13 | W3: 17 | AB3: 18 | AG3: 17 | AL3: 17 | AQ3: 18 | AV3: 17 | BA3: 17 | BF3: 18 | BK3: 18
A4: 社員数 | C4: =C35 -> 11 | H4: =H35 -> 12 | M4: =M35 -> 12 | R4: =R35 -> 12 | W4: =W35 -> 15 | AB4: =AB35 -> 16 | AG4: =AG35 -> 16 | AL4: =AL35 -> 16 | AQ4: =AQ35 -> 16 | AV4: =AV35 -> 15 | BA4: =BA35 -> 15 | BF4: =BF35 -> 15 | BK4: =BK35 -> 15
A5: 差異 | C5: =C4-C3 -> -2 | H5: =H4-H3 -> -1 | M5: =M4-M3 -> -1 | R5: =R4-R3 -> -1 | W5: =W4-W3 -> -2 | AB5: =AB4-AB3 -> -2 | AG5: =AG4-AG3 -> -1 | AL5: =AL4-AL3 -> -1 | AQ5: =AQ4-AQ3 -> -2 | AV5: =AV4-AV3 -> -2 | BA5: =BA4-BA3 -> -2 | BF5: =BF4-BF3 -> -3 | BK5: =BK4-BK3 -> -3
A7: 実働×熟練度 | C7: =F35 -> 1186 | H7: =K35 -> 1200 | M7: 1279 | R7: =#REF! -> #REF! | W7: =Z35 -> 1444 | AB7: =AE35 -> 1614 | AG7: =AJ35 -> 1662 | AL7: =AO35 -> 1682 | AQ7: =AT35 -> 1700 | AV7: =AY35 -> 1510 | BA7: =BD35 -> 1610 | BF7: =BI35 -> 1635 | BK7: =BN35 -> 1651
A8: 差異 | C8: =C7-C6 -> 1186 | H8: =H7-H6 -> 1200 | M8: =M7-M6 -> 1279 | R8: =R7-R6 -> #REF!
A10: 総稼働時間
A11: 架電
A12: 架電以外
C13: 社員内訳
C14: 12月 | H14: 1月 | M14: 2月 | R14: 3月 | W14: 4月 | AB14: 5月 | AG14: 6月 | AL14: 7月 | AQ14: 8月 | AV14: 9月 | BA14: 10月 | BF14: 11月 | BK14: 12月
C15: 氏名 | D15: 実働 | E15: 相続 | F15: ×熟練度 | G15: 熟練度 | H15: 氏名 | I15: 実働 | J15: 相続 | K15: ×熟練度 | L15: 熟練度 | M15: 氏名 | N15: 実働 | O15: 相続 | P15: ×熟練度 | Q15: 熟練度 | R15: 氏名 | S15: 実働 | T15: 相続 | U15: ×熟練度 | V15: 熟練度 | W15: 氏名 | X15: 実働 | Y15: 相続 | Z15: ×熟練度 | AA15: 熟練度 | AB15: 氏名 | AC15: 実働 | AD15: 相続 | AE15: ×熟練度 | AF15: 熟練度 | AG15: 氏名 | AH15: 実働 | AI15: 相続 | AJ15: ×熟練度 | AK15: 熟練度 | AL15: 氏名 | AM15: 実働 | AN15: 相続 | AO15: ×熟練度 | AP15: 熟練度 | AQ15: 氏名 | AR15: 実働 | AS15: 相続 | AT15: ×熟練度 | AU15: 熟練度 | AV15: 氏名 | AW15: 実働 | AX15: 相続 | AY15: ×熟練度 | AZ15: 熟練度 | BA15: 氏名 | BB15: 実働 | BC15: 相続 | BD15: ×熟練度 | BE15: 熟練度 | BF15: 氏名 | BG15: 実働 | BH15: 相続 | BI15: ×熟練度 | BJ15: 熟練度 | BK15: 氏名 | BL15: 実働 | BM15: 相続 | BN15: ×熟練度 | BO15: 熟練度
C16: 赤坂 | D16: 165 | E16: 4 | F16: =ROUND((D16-E16)*G16,0) -> 153 | G16: 0.95 | H16: 赤坂 | I16: 165 | J16: 4 | K16: =ROUND((I16-J16)*L16,0) -> 153 | L16: 0.95 | M16: 赤坂 | N16: 165 | O16: 4 | P16: =ROUND((N16-O16)*Q16,0) -> 153 | Q16: 0.95 | R16: 赤坂 | S16: 165 | T16: 4 | U16: =ROUND((S16-T16)*V16,0) -> 153 | V16: 0.95 | W16: 赤坂 | X16: 165 | Y16: 4 | Z16: =ROUND((X16-Y16)*AA16,0) -> 153 | AA16: 0.95 | AB16: 赤坂 | AC16: 165 | AD16: 4 | AE16: =ROUND((AC16-AD16)*AF16,0) -> 153 | AF16: 0.95 | AG16: 赤坂 | AH16: 165 | AI16: 4 | AJ16: =ROUND((AH16-AI16)*AK16,0) -> 153 | AK16: 0.95 | AL16: 赤坂 | AM16: 165 | AN16: 4 | AO16: =ROUND((AM16-AN16)*AP16,0) -> 153 | AP16: 0.95 | AQ16: 赤坂 | AR16: 165 | AS16: 4 | AT16: =ROUND((AR16-AS16)*AU16,0) -> 153 | AU16: 0.95
C17: 土屋 | D17: 130 | E17: 4 | F17: =ROUND((D17-E17)*G17,0) -> 120 | G17: 0.95 | H17: 土屋 | I17: 130 | J17: 4 | K17: =ROUND((I17-J17)*L17,0) -> 120 | L17: 0.95 | M17: 土屋 | N17: 130 | O17: 4 | P17: =ROUND((N17-O17)*Q17,0) -> 120 | Q17: 0.95 | R17: 土屋 | S17: 130 | T17: 4 | U17: =ROUND((S17-T17)*V17,0) -> 120 | V17: 0.95 | W17: 土屋 | X17: 130 | Y17: 4 | Z17: =ROUND((X17-Y17)*AA17,0) -> 120 | AA17: 0.95 | AB17: 土屋 | AC17: 130 | AD17: 4 | AE17: =ROUND((AC17-AD17)*AF17,0) -> 120 | AF17: 0.95 | AG17: 土屋 | AH17: 130 | AI17: 4 | AJ17: =ROUND((AH17-AI17)*AK17,0) -> 120 | AK17: 0.95 | AL17: 土屋 | AM17: 130 | AN17: 4 | AO17: =ROUND((AM17-AN17)*AP17,0) -> 120 | AP17: 0.95 | AQ17: 土屋 | AR17: 130 | AS17: 4 | AT17: =ROUND((AR17-AS17)*AU17,0) -> 120 | AU17: 0.95 | AV17: 土屋 | AW17: 130 | AX17: 4 | AY17: =ROUND((AW17-AX17)*AZ17,0) -> 120 | AZ17: 0.95 | BA17: 土屋 | BB17: 130 | BC17: 4 | BD17: =ROUND((BB17-BC17)*BE17,0) -> 120 | BE17: 0.95 | BF17: 土屋 | BG17: 130 | BH17: 4 | BI17: =ROUND((BG17-BH17)*BJ17,0) -> 120 | BJ17: 0.95 | BK17: 土屋 | BL17: 130 | BM17: 4 | BN17: =ROUND((BL17-BM17)*BO17,0) -> 120 | BO17: 0.95
C18: 平川 | D18: 165 | E18: 10 | F18: =ROUND((D18-E18)*G18,0) -> 132 | G18: 0.85 | H18: 平川 | I18: 165 | J18: 10 | K18: =ROUND((I18-J18)*L18,0) -> 132 | L18: 0.85 | M18: 平川 | N18: 165 | O18: 10 | P18: =ROUND((N18-O18)*Q18,0) -> 132 | Q18: 0.85 | R18: 平川 | S18: 165 | T18: 10 | U18: =ROUND((S18-T18)*V18,0) -> 132 | V18: 0.85 | W18: 平川 | X18: 165 | Y18: 10 | Z18: =ROUND((X18-Y18)*AA18,0) -> 132 | AA18: 0.85 | AB18: 平川 | AC18: 165 | AD18: 10 | AE18: =ROUND((AC18-AD18)*AF18,0) -> 132 | AF18: 0.85 | AG18: 平川 | AH18: 165 | AI18: 10 | AJ18: =ROUND((AH18-AI18)*AK18,0) -> 132 | AK18: 0.85 | AL18: 平川 | AM18: 165 | AN18: 10 | AO18: =ROUND((AM18-AN18)*AP18,0) -> 132 | AP18: 0.85 | AQ18: 平川 | AR18: 165 | AS18: 10 | AT18: =ROUND((AR18-AS18)*AU18,0) -> 132 | AU18: 0.85 | AV18: 平川 | AW18: 165 | AX18: 10 | AY18: =ROUND((AW18-AX18)*AZ18,0) -> 132 | AZ18: 0.85 | BA18: 平川 | BB18: 165 | BC18: 10 | BD18: =ROUND((BB18-BC18)*BE18,0) -> 132 | BE18: 0.85 | BF18: 平川 | BG18: 165 | BH18: 10 | BI18: =ROUND((BG18-BH18)*BJ18,0) -> 132 | BJ18: 0.85 | BK18: 平川 | BL18: 165 | BM18: 10 | BN18: =ROUND((BL18-BM18)*BO18,0) -> 132 | BO18: 0.85
C19: 金森 | D19: 200 | E19: 20 | F19: =ROUND((D19-E19)*G19,0) -> 108 | G19: 0.6 | H19: 金森 | I19: 200 | J19: 20 | K19: =ROUND((I19-J19)*L19,0) -> 108 | L19: 0.6 | M19: 金森 | N19: 200 | O19: 20 | P19: =ROUND((N19-O19)*Q19,0) -> 108 | Q19: 0.6 | R19: 金森 | S19: 200 | T19: 20 | U19: =ROUND((S19-T19)*V19,0) -> 108 | V19: 0.6 | W19: 金森 | X19: 200 | Y19: 20 | Z19: =ROUND((X19-Y19)*AA19,0) -> 108 | AA19: 0.6 | AB19: 金森 | AC19: 200 | AD19: 20 | AE19: =ROUND((AC19-AD19)*AF19,0) -> 108 | AF19: 0.6 | AG19: 金森 | AH19: 200 | AI19: 20 | AJ19: =ROUND((AH19-AI19)*AK19,0) -> 108 | AK19: 0.6 | AL19: 金森 | AM19: 200 | AN19: 20 | AO19: =ROUND((AM19-AN19)*AP19,0) -> 108 | AP19: 0.6 | AQ19: 金森 | AR19: 200 | AS19: 20 | AT19: =ROUND((AR19-AS19)*AU19,0) -> 108 | AU19: 0.6 | AV19: 金森 | AW19: 200 | AX19: 20 | AY19: =ROUND((AW19-AX19)*AZ19,0) -> 108 | AZ19: 0.6 | BA19: 金森 | BB19: 200 | BC19: 20 | BD19: =ROUND((BB19-BC19)*BE19,0) -> 108 | BE19: 0.6 | BF19: 金森 | BG19: 200 | BH19: 20 | BI19: =ROUND((BG19-BH19)*BJ19,0) -> 108 | BJ19: 0.6 | BK19: 金森 | BL19: 200 | BM19: 20 | BN19: =ROUND((BL19-BM19)*BO19,0) -> 108 | BO19: 0.6
C20: 菅家 | D20: 200 | E20: 20 | F20: =ROUND((D20-E20)*G20,0) -> 162 | G20: 0.9 | H20: 菅家 | I20: 200 | J20: 20 | K20: =ROUND((I20-J20)*L20,0) -> 162 | L20: 0.9 | M20: 菅家 | N20: 200 | O20: 20 | P20: =ROUND((N20-O20)*Q20,0) -> 162 | Q20: 0.9 | R20: 菅家 | S20: 200 | T20: 20 | U20: =ROUND((S20-T20)*V20,0) -> 162 | V20: 0.9 | W20: 菅家 | X20: 200 | Y20: 20 | Z20: =ROUND((X20-Y20)*AA20,0) -> 162 | AA20: 0.9 | AB20: 菅家 | AC20: 200 | AD20: 20 | AE20: =ROUND((AC20-AD20)*AF20,0) -> 162 | AF20: 0.9 | AG20: 菅家 | AH20: 200 | AI20: 20 | AJ20: =ROUND((AH20-AI20)*AK20,0) -> 162 | AK20: 0.9 | AL20: 菅家 | AM20: 200 | AN20: 20 | AO20: =ROUND((AM20-AN20)*AP20,0) -> 162 | AP20: 0.9 | AQ20: 菅家 | AR20: 200 | AS20: 20 | AT20: =ROUND((AR20-AS20)*AU20,0) -> 162 | AU20: 0.9 | AV20: 菅家 | AW20: 200 | AX20: 20 | AY20: =ROUND((AW20-AX20)*AZ20,0) -> 162 | AZ20: 0.9 | BA20: 菅家 | BB20: 200 | BC20: 20 | BD20: =ROUND((BB20-BC20)*BE20,0) -> 162 | BE20: 0.9 | BF20: 菅家 | BG20: 200 | BH20: 20 | BI20: =ROUND((BG20-BH20)*BJ20,0) -> 162 | BJ20: 0.9 | BK20: 菅家 | BL20: 200 | BM20: 20 | BN20: =ROUND((BL20-BM20)*BO20,0) -> 162 | BO20: 0.9
W21: 小泉 | X21: 200 | Y21: 50 | Z21: =ROUND((X21-Y21)*AA21,0) -> 135 | AA21: 0.9 | AB21: 小泉 | AC21: 200 | AD21: 50 | AE21: =ROUND((AC21-AD21)*AF21,0) -> 135 | AF21: 0.9 | AG21: 小泉 | AH21: 200 | AI21: 50 | AJ21: =ROUND((AH21-AI21)*AK21,0) -> 135 | AK21: 0.9 | AL21: 小泉 | AM21: 200 | AN21: 50 | AO21: =ROUND((AM21-AN21)*AP21,0) -> 135 | AP21: 0.9 | AQ21: 小泉 | AR21: 200 | AS21: 50 | AT21: =ROUND((AR21-AS21)*AU21,0) -> 135 | AU21: 0.9 | AV21: 小泉 | AW21: 200 | AX21: 50 | AY21: =ROUND((AW21-AX21)*AZ21,0) -> 135 | AZ21: 0.9 | BA21: 小泉 | BB21: 200 | BC21: 50 | BD21: =ROUND((BB21-BC21)*BE21,0) -> 135 | BE21: 0.9 | BF21: 小泉 | BG21: 200 | BH21: 50 | BI21: =ROUND((BG21-BH21)*BJ21,0) -> 135 | BJ21: 0.9 | BK21: 小泉 | BL21: 200 | BM21: 50 | BN21: =ROUND((BL21-BM21)*BO21,0) -> 135 | BO21: 0.9
C22: 石井 | D22: 165 | E22: 20 | F22: =ROUND((D22-E22)*G22,0) -> 87 | G22: 0.6 | H22: 石井 | I22: 165 | J22: 20 | K22: =ROUND((I22-J22)*L22,0) -> 87 | L22: 0.6 | M22: 石井 | N22: 165 | O22: 20 | P22: =ROUND((N22-O22)*Q22,0) -> 87 | Q22: 0.6 | R22: 石井 | S22: 165 | T22: 20 | U22: =ROUND((S22-T22)*V22,0) -> 87 | V22: 0.6 | W22: 石井 | X22: 165 | Y22: 20 | Z22: =ROUND((X22-Y22)*AA22,0) -> 87 | AA22: 0.6 | AB22: 石井 | AC22: 165 | AD22: 20 | AE22: =ROUND((AC22-AD22)*AF22,0) -> 87 | AF22: 0.6 | AG22: 石井 | AH22: 165 | AI22: 20 | AJ22: =ROUND((AH22-AI22)*AK22,0) -> 87 | AK22: 0.6 | AL22: 石井 | AM22: 165 | AN22: 20 | AO22: =ROUND((AM22-AN22)*AP22,0) -> 87 | AP22: 0.6 | AQ22: 石井 | AR22: 165 | AS22: 20 | AT22: =ROUND((AR22-AS22)*AU22,0) -> 87 | AU22: 0.6 | AV22: 石井 | AW22: 165 | AX22: 20 | AY22: =ROUND((AW22-AX22)*AZ22,0) -> 87 | AZ22: 0.6 | BA22: 石井 | BB22: 165 | BC22: 20 | BD22: =ROUND((BB22-BC22)*BE22,0) -> 87 | BE22: 0.6 | BF22: 石井 | BG22: 165 | BH22: 20 | BI22: =ROUND((BG22-BH22)*BJ22,0) -> 87 | BJ22: 0.6 | BK22: 石井 | BL22: 165 | BM22: 20 | BN22: =ROUND((BL22-BM22)*BO22,0) -> 87 | BO22: 0.6
C23: 近藤 | D23: 165 | E23: 20 | F23: =ROUND((D23-E23)*G23,0) -> 131 | G23: 0.9 | H23: 近藤 | I23: 165 | J23: 20 | K23: =ROUND((I23-J23)*L23,0) -> 131 | L23: 0.9 | M23: 近藤 | N23: 165 | O23: 20 | P23: =ROUND((N23-O23)*Q23,0) -> 131 | Q23: 0.9 | R23: 近藤 | S23: 165 | T23: 20 | U23: =ROUND((S23-T23)*V23,0) -> 131 | V23: 0.9 | W23: 近藤 | X23: 165 | Y23: 20 | Z23: =ROUND((X23-Y23)*AA23,0) -> 131 | AA23: 0.9 | AB23: 近藤 | AC23: 165 | AD23: 20 | AE23: =ROUND((AC23-AD23)*AF23,0) -> 131 | AF23: 0.9 | AG23: 近藤 | AH23: 165 | AI23: 20 | AJ23: =ROUND((AH23-AI23)*AK23,0) -> 131 | AK23: 0.9 | AL23: 近藤 | AM23: 165 | AN23: 20 | AO23: =ROUND((AM23-AN23)*AP23,0) -> 131 | AP23: 0.9 | AQ23: 近藤 | AR23: 165 | AS23: 20 | AT23: =ROUND((AR23-AS23)*AU23,0) -> 131 | AU23: 0.9 | AV23: 近藤 | AW23: 165 | AX23: 20 | AY23: =ROUND((AW23-AX23)*AZ23,0) -> 131 | AZ23: 0.9 | BA23: 近藤 | BB23: 165 | BC23: 20 | BD23: =ROUND((BB23-BC23)*BE23,0) -> 131 | BE23: 0.9 | BF23: 近藤 | BG23: 165 | BH23: 20 | BI23: =ROUND((BG23-BH23)*BJ23,0) -> 131 | BJ23: 0.9 | BK23: 近藤 | BL23: 165 | BM23: 20 | BN23: =ROUND((BL23-BM23)*BO23,0) -> 131 | BO23: 0.9
C24: 氏家 | D24: 165 | E24: 50 | F24: =ROUND((D24-E24)*G24,0) -> 81 | G24: 0.7 | H24: 氏家 | I24: 165 | J24: 50 | K24: =ROUND((I24-J24)*L24,0) -> 81 | L24: 0.7 | M24: 氏家 | N24: 165 | O24: 50 | P24: =ROUND((N24-O24)*Q24,0) -> 81 | Q24: 0.7 | R24: 氏家 | S24: 165 | T24: 50 | U24: =ROUND((S24-T24)*V24,0) -> 81 | V24: 0.7 | W24: 氏家 | X24: 165 | Y24: 50 | Z24: =ROUND((X24-Y24)*AA24,0) -> 81 | AA24: 0.7 | AB24: 氏家 | AC24: 165 | AD24: 50 | AE24: =ROUND((AC24-AD24)*AF24,0) -> 81 | AF24: 0.7 | AG24: 氏家 | AH24: 165 | AI24: 50 | AJ24: =ROUND((AH24-AI24)*AK24,0) -> 81 | AK24: 0.7 | AL24: 氏家 | AM24: 165 | AN24: 50 | AO24: =ROUND((AM24-AN24)*AP24,0) -> 81 | AP24: 0.7 | AQ24: 氏家 | AR24: 165 | AS24: 50 | AT24: =ROUND((AR24-AS24)*AU24,0) -> 81 | AU24: 0.7 | AV24: 氏家 | AW24: 165 | AX24: 50 | AY24: =ROUND((AW24-AX24)*AZ24,0) -> 81 | AZ24: 0.7 | BA24: 氏家 | BB24: 165 | BC24: 50 | BD24: =ROUND((BB24-BC24)*BE24,0) -> 81 | BE24: 0.7 | BF24: 氏家 | BG24: 165 | BH24: 50 | BI24: =ROUND((BG24-BH24)*BJ24,0) -> 81 | BJ24: 0.7 | BK24: 氏家 | BL24: 165 | BM24: 50 | BN24: =ROUND((BL24-BM24)*BO24,0) -> 81 | BO24: 0.7
C25: 須田 | D25: 200 | E25: 10 | F25: =ROUND((D25-E25)*G25,0) -> 124 | G25: 0.65 | H25: 須田 | I25: 200 | J25: 10 | K25: =ROUND((I25-J25)*L25,0) -> 124 | L25: 0.65 | M25: 須田 | N25: 200 | O25: 10 | P25: =ROUND((N25-O25)*Q25,0) -> 124 | Q25: 0.65 | R25: 須田 | S25: 200 | T25: 10 | U25: =ROUND((S25-T25)*V25,0) -> 124 | V25: 0.65 | W25: 須田 | X25: 200 | Y25: 10 | Z25: =ROUND((X25-Y25)*AA25,0) -> 133 | AA25: 0.7 | AB25: 須田 | AC25: 200 | AD25: 10 | AE25: =ROUND((AC25-AD25)*AF25,0) -> 133 | AF25: 0.7 | AG25: 須田 | AH25: 200 | AI25: 10 | AJ25: =ROUND((AH25-AI25)*AK25,0) -> 143 | AK25: 0.75 | AL25: 須田 | AM25: 200 | AN25: 10 | AO25: =ROUND((AM25-AN25)*AP25,0) -> 143 | AP25: 0.75 | AQ25: 須田 | AR25: 200 | AS25: 10 | AT25: =ROUND((AR25-AS25)*AU25,0) -> 143 | AU25: 0.75 | AV25: 須田 | AW25: 200 | AX25: 10 | AY25: =ROUND((AW25-AX25)*AZ25,0) -> 124 | AZ25: 0.65 | BA25: 須田 | BB25: 200 | BC25: 10 | BD25: =ROUND((BB25-BC25)*BE25,0) -> 124 | BE25: 0.65 | BF25: 須田 | BG25: 200 | BH25: 10 | BI25: =ROUND((BG25-BH25)*BJ25,0) -> 124 | BJ25: 0.65 | BK25: 須田 | BL25: 200 | BM25: 10 | BN25: =ROUND((BL25-BM25)*BO25,0) -> 124 | BO25: 0.65
C26: 池添 | D26: 165 | E26: 20 | F26: =ROUND((D26-E26)*G26,0) -> 73 | G26: 0.5 | H26: 池添 | I26: 165 | J26: 20 | K26: =ROUND((I26-J26)*L26,0) -> 73 | L26: 0.5 | M26: 池添 | N26: 165 | O26: 20 | P26: =ROUND((N26-O26)*Q26,0) -> 73 | Q26: 0.5 | R26: 池添 | S26: 165 | T26: 20 | U26: =ROUND((S26-T26)*V26,0) -> 73 | V26: 0.5 | W26: 池添 | X26: 165 | Y26: 20 | Z26: =ROUND((X26-Y26)*AA26,0) -> 87 | AA26: 0.6 | AB26: 池添 | AC26: 165 | AD26: 20 | AE26: =ROUND((AC26-AD26)*AF26,0) -> 94 | AF26: 0.65 | AG26: 池添 | AH26: 165 | AI26: 20 | AJ26: =ROUND((AH26-AI26)*AK26,0) -> 102 | AK26: 0.7 | AL26: 池添 | AM26: 165 | AN26: 20 | AO26: =ROUND((AM26-AN26)*AP26,0) -> 102 | AP26: 0.7 | AQ26: 池添 | AR26: 165 | AS26: 20 | AT26: =ROUND((AR26-AS26)*AU26,0) -> 109 | AU26: 0.75 | AV26: 池添 | AW26: 165 | AX26: 20 | AY26: =ROUND((AW26-AX26)*AZ26,0) -> 109 | AZ26: 0.75 | BA26: 池添 | BB26: 165 | BC26: 20 | BD26: =ROUND((BB26-BC26)*BE26,0) -> 109 | BE26: 0.75 | BF26: 池添 | BG26: 165 | BH26: 20 | BI26: =ROUND((BG26-BH26)*BJ26,0) -> 116 | BJ26: 0.8 | BK26: 池添 | BL26: 165 | BM26: 20 | BN26: =ROUND((BL26-BM26)*BO26,0) -> 116 | BO26: 0.8
C27: 望月 | D27: 165 | E27: 20 | F27: =ROUND((D27-E27)*G27,0) -> 15 | G27: 0.1 | H27: 望月 | I27: 165 | J27: 20 | K27: =ROUND((I27-J27)*L27,0) -> 29 | L27: 0.2 | M27: 望月 | N27: 165 | O27: 20 | P27: =ROUND((N27-O27)*Q27,0) -> 29 | Q27: 0.2 | R27: 望月 | S27: 165 | T27: 20 | U27: =ROUND((S27-T27)*V27,0) -> 44 | V27: 0.3 | W27: 望月 | X27: 165 | Y27: 20 | Z27: =ROUND((X27-Y27)*AA27,0) -> 58 | AA27: 0.4 | AB27: 望月 | AC27: 165 | AD27: 20 | AE27: =ROUND((AC27-AD27)*AF27,0) -> 58 | AF27: 0.4 | AG27: 望月 | AH27: 165 | AI27: 20 | AJ27: =ROUND((AH27-AI27)*AK27,0) -> 73 | AK27: 0.5 | AL27: 望月 | AM27: 165 | AN27: 20 | AO27: =ROUND((AM27-AN27)*AP27,0) -> 73 | AP27: 0.5 | AQ27: 望月 | AR27: 165 | AS27: 20 | AT27: 60 | AU27: 0.55 | AV27: 望月 | AW27: 165 | AX27: 20 | AY27: 15 | AZ27: 0.55 | BA27: 望月 | BB27: 165 | BC27: 20 | BD27: =ROUND((BB27-BC27)*BE27,0) -> 87 | BE27: 0.6 | BF27: 望月 | BG27: 165 | BH27: 20 | BI27: =ROUND((BG27-BH27)*BJ27,0) -> 87 | BJ27: 0.6 | BK27: 望月 | BL27: 165 | BM27: 20 | BN27: =ROUND((BL27-BM27)*BO27,0) -> 94 | BO27: 0.65
F28: =ROUND((D28-E28)*G28,0) -> 0 | H28: 提箸 | I28: 200 | J28: 0 | K28: =ROUND((I28-J28)*L28,0) -> 0 | M28: 提箸 | N28: 200 | O28: 0 | P28: =ROUND((N28-O28)*Q28,0) -> 20 | Q28: 0.1 | R28: 提箸 | S28: 200 | T28: 0 | U28: =ROUND((S28-T28)*V28,0) -> 40 | V28: 0.2 | W28: 提箸 | X28: 200 | Y28: 10 | Z28: =ROUND((X28-Y28)*AA28,0) -> 57 | AA28: 0.3 | AB28: 提箸 | AC28: 200 | AD28: 10 | AE28: =ROUND((AC28-AD28)*AF28,0) -> 76 | AF28: 0.4 | AG28: 提箸 | AH28: 200 | AI28: 10 | AJ28: =ROUND((AH28-AI28)*AK28,0) -> 95 | AK28: 0.5 | AL28: 提箸 | AM28: 200 | AN28: 10 | AO28: =ROUND((AM28-AN28)*AP28,0) -> 95 | AP28: 0.5 | AQ28: 提箸 | AR28: 200 | AS28: 10 | AT28: =ROUND((AR28-AS28)*AU28,0) -> 105 | AU28: 0.55 | AV28: 提箸 | AW28: 200 | AX28: 10 | AY28: =ROUND((AW28-AX28)*AZ28,0) -> 114 | AZ28: 0.6 | BA28: 提箸 | BB28: 200 | BC28: 10 | BD28: =ROUND((BB28-BC28)*BE28,0) -> 124 | BE28: 0.65 | BF28: 提箸 | BG28: 200 | BH28: 10 | BI28: =ROUND((BG28-BH28)*BJ28,0) -> 124 | BJ28: 0.65 | BK28: 提箸 | BL28: 200 | BM28: 10 | BN28: =ROUND((BL28-BM28)*BO28,0) -> 133 | BO28: 0.7
F29: =ROUND((D29-E29)*G29,0) -> 0 | K29: =ROUND((I29-J29)*L29,0) -> 0 | P29: =ROUND((N29-O29)*Q29,0) -> 0 | U29: =ROUND((S29-T29)*V29,0) -> 0 | W29: 宮内 | X29: 100 | Y29: 0 | Z29: =ROUND((X29-Y29)*AA29,0) -> 0 | AA29: 0 | AB29: 中田 | AC29: 130 | AD29: 0 | AE29: =ROUND((AC29-AD29)*AF29,0) -> 124 | AF29: 0.95 | AG29: 中田 | AH29: 130 | AI29: 4 | AJ29: =ROUND((AH29-AI29)*AK29,0) -> 120 | AK29: 0.95 | AL29: 中田 | AM29: 130 | AN29: 4 | AO29: =ROUND((AM29-AN29)*AP29,0) -> 120 | AP29: 0.95 | AQ29: 中田 | AR29: 130 | AS29: 4 | AT29: =ROUND((AR29-AS29)*AU29,0) -> 120 | AU29: 0.95 | AV29: 中田 | AW29: 130 | AX29: 4 | AY29: =ROUND((AW29-AX29)*AZ29,0) -> 120 | AZ29: 0.95 | BA29: 中田 | BB29: 130 | BC29: 4 | BD29: =ROUND((BB29-BC29)*BE29,0) -> 120 | BE29: 0.95 | BF29: 中田 | BG29: 130 | BH29: 4 | BI29: =ROUND((BG29-BH29)*BJ29,0) -> 120 | BJ29: 0.95 | BK29: 中田 | BL29: 130 | BM29: 4 | BN29: =ROUND((BL29-BM29)*BO29,0) -> 120 | BO29: 0.95
F30: =ROUND((D30-E30)*G30,0) -> 0 | K30: =ROUND((I30-J30)*L30,0) -> 0 | P30: =ROUND((N30-O30)*Q30,0) -> 0 | U30: =ROUND((S30-T30)*V30,0) -> 0 | W30: 森山 | X30: 100 | Y30: 0 | Z30: =ROUND((X30-Y30)*AA30,0) -> 0 | AA30: 0 | AB30: 宮内 | AC30: 100 | AD30: 0 | AE30: =ROUND((AC30-AD30)*AF30,0) -> 10 | AF30: 0.1 | AG30: 宮内 | AH30: 100 | AI30: 0 | AJ30: =ROUND((AH30-AI30)*AK30,0) -> 10 | AK30: 0.1 | AL30: 宮内 | AM30: 100 | AN30: 0 | AO30: 20 | AP30: 0.2 | AQ30: 宮内 | AR30: 100 | AS30: 10 | AT30: =ROUND((AR30-AS30)*AU30,0) -> 27 | AU30: 0.3 | AV30: 宮内 | AW30: 100 | AX30: 10 | AY30: =ROUND((AW30-AX30)*AZ30,0) -> 36 | AZ30: 0.4 | BA30: 宮内 | BB30: 100 | BC30: 10 | BD30: =ROUND((BB30-BC30)*BE30,0) -> 45 | BE30: 0.5 | BF30: 宮内 | BG30: 100 | BH30: 10 | BI30: =ROUND((BG30-BH30)*BJ30,0) -> 54 | BJ30: 0.6 | BK30: 宮内 | BL30: 100 | BM30: 10 | BN30: =ROUND((BL30-BM30)*BO30,0) -> 54 | BO30: 0.6
F31: =ROUND((D31-E31)*G31,0) -> 0 | K31: =ROUND((I31-J31)*L31,0) -> 0 | P31: =ROUND((N31-O31)*Q31,0) -> 0 | U31: =ROUND((S31-T31)*V31,0) -> 0 | Z31: =ROUND((X31-Y31)*AA31,0) -> 0 | AB31: 森山 | AC31: 100 | AD31: 0 | AE31: =ROUND((AC31-AD31)*AF31,0) -> 10 | AF31: 0.1 | AG31: 森山 | AH31: 100 | AI31: 0 | AJ31: =ROUND((AH31-AI31)*AK31,0) -> 10 | AK31: 0.1 | AL31: 森山 | AM31: 100 | AN31: 0 | AO31: 20 | AP31: 0.2 | AQ31: 森山 | AR31: 100 | AS31: 10 | AT31: =ROUND((AR31-AS31)*AU31,0) -> 27 | AU31: 0.3 | AV31: 森山 | AW31: 100 | AX31: 10 | AY31: =ROUND((AW31-AX31)*AZ31,0) -> 36 | AZ31: 0.4 | BA31: 森山 | BB31: 100 | BC31: 10 | BD31: =ROUND((BB31-BC31)*BE31,0) -> 45 | BE31: 0.5 | BF31: 森山 | BG31: 100 | BH31: 10 | BI31: =ROUND((BG31-BH31)*BJ31,0) -> 54 | BJ31: 0.6 | BK31: 森山 | BL31: 100 | BM31: 10 | BN31: =ROUND((BL31-BM31)*BO31,0) -> 54 | BO31: 0.6
W33: 4月 | AB33: 5月 | AG33: 6月 | AL33: 7月 | AQ33: 8月 | AV33: 9月 | BA33: 10月 | BF33: 11月 | BK33: 12月
W34: 合計人数 | X34: 実働時間 | Y34: 相続対応 | Z34: 実働×熟 | AA34: 熟練度平均 | AB34: 合計人数 | AC34: 実働時間 | AD34: 相続対応 | AE34: 実働×熟 | AF34: 熟練度平均 | AG34: 合計人数 | AH34: 実働時間 | AI34: 相続対応 | AJ34: 実働×熟 | AK34: 熟練度平均 | AL34: 合計人数 | AM34: 実働時間 | AN34: 相続対応 | AO34: 実働×熟 | AP34: 熟練度平均 | AQ34: 合計人数 | AR34: 実働時間 | AS34: 相続対応 | AT34: 実働×熟 | AU34: 熟練度平均 | AV34: 合計人数 | AW34: 実働時間 | AX34: 相続対応 | AY34: 実働×熟 | AZ34: 熟練度平均 | BA34: 合計人数 | BB34: 実働時間 | BC34: 相続対応 | BD34: 実働×熟 | BE34: 熟練度平均 | BF34: 合計人数 | BG34: 実働時間 | BH34: 相続対応 | BI34: 実働×熟 | BJ34: 熟練度平均 | BK34: 合計人数 | BL34: 実働時間 | BM34: 相続対応 | BN34: 実働×熟 | BO34: 熟練度平均
C35: =COUNTA(C16:C31) -> 11 | D35: =SUM(D16:D31) -> 1885 | E35: =SUM(E16:E31) -> 198 | F35: =SUM(F16:F31) -> 1186 | G35: =AVERAGE(G16:G31) -> 0.7 | H35: =COUNTA(H16:H31) -> 12 | I35: =SUM(I16:I31) -> 2085 | J35: =SUM(J16:J31) -> 198 | K35: =SUM(K16:K31) -> 1200 | L35: =AVERAGE(L16:L31) -> 0.70909091 | M35: =COUNTA(M16:M31) -> 12 | N35: =SUM(N16:N31) -> 2085 | O35: =SUM(O16:O31) -> 198 | P35: =SUM(P16:P31) -> 1220 | Q35: =AVERAGE(Q16:Q31) -> 0.65833333 | R35: =COUNTA(R16:R31) -> 12 | S35: =SUM(S16:S31) -> 2085 | T35: =SUM(T16:T31) -> 198 | U35: =SUM(U16:U31) -> 1255 | V35: =AVERAGE(V16:V31) -> 0.675 | W35: =COUNTA(W16:W31) -> 15 | X35: =SUM(X16:X31) -> 2485 | Y35: =SUM(Y16:Y31) -> 258 | Z35: =SUM(Z16:Z31) -> 1444 | AA35: =AVERAGE(AA16:AA31) -> 0.62333333 | AB35: =COUNTA(AB16:AB31) -> 16 | AC35: =SUM(AC16:AC31) -> 2615 | AD35: =SUM(AD16:AD31) -> 258 | AE35: =SUM(AE16:AE31) -> 1614 | AF35: =AVERAGE(AF16:AF31) -> 0.665625 | AG35: =COUNTA(AG16:AG31) -> 16 | AH35: =SUM(AH16:AH31) -> 2615 | AI35: =SUM(AI16:AI31) -> 262 | AJ35: =SUM(AJ16:AJ31) -> 1662 | AK35: =AVERAGE(AK16:AK31) -> 0.684375 | AL35: =COUNTA(AL16:AL31) -> 16 | AM35: =SUM(AM16:AM31) -> 2615 | AN35: =SUM(AN16:AN31) -> 262 | AO35: =SUM(AO16:AO31) -> 1682 | AP35: =AVERAGE(AP16:AP31) -> 0.696875 | AQ35: =COUNTA(AQ16:AQ31) -> 16 | AR35: =SUM(AR16:AR31) -> 2615 | AS35: =SUM(AS16:AS31) -> 282 | AT35: =SUM(AT16:AT31) -> 1700 | AU35: =AVERAGE(AU16:AU31) -> 0.71875 | AV35: =COUNTA(AV16:AV31) -> 15 | AW35: =SUM(AW16:AW31) -> 2450 | AX35: =SUM(AX16:AX31) -> 278 | AY35: =SUM(AY16:AY31) -> 1510 | AZ35: =AVERAGE(AZ16:AZ31) -> 0.71333333 | BA35: =COUNTA(BA16:BA31) -> 15 | BB35: =SUM(BB16:BB31) -> 2450 | BC35: =SUM(BC16:BC31) -> 278 | BD35: =SUM(BD16:BD31) -> 1610 | BE35: =AVERAGE(BE16:BE31) -> 0.73333333 | BF35: =COUNTA(BF16:BF31) -> 15 | BG35: =SUM(BG16:BG31) -> 2450 | BH35: =SUM(BH16:BH31) -> 278 | BI35: =SUM(BI16:BI31) -> 1635 | BJ35: =AVERAGE(BJ16:BJ31) -> 0.75 | BK35: =COUNTA(BK16:BK31) -> 15 | BL35: =SUM(BL16:BL31) -> 2450 | BM35: =SUM(BM16:BM31) -> 278 | BN35: =SUM(BN16:BN31) -> 1651 | BO35: =AVERAGE(BO16:BO31) -> 0.75666667

Sheet 受注推移2
A1: 受注マンパワー推移2026
C2: 12月 | E2: 1月 | G2: 2月 | I2: 3月 | K2: 4月 | M2: 5月 | O2: 6月 | Q2: 7月 | S2: 8月 | U2: 9月 | W2: 10月 | Y2: 11月 | AA2: 12月
A3: 適正人数 | C3: 16 | E3: 16 | G3: 16 | I3: 16 | K3: 18 | M3: 18 | O3: 18 | Q3: 20 | S3: 20 | U3: 20 | W3: 20 | Y3: 20 | AA3: 20
A4: 受注担当 | C4: =C38 -> 14 | E4: =E38 -> 14 | G4: =G38 -> 15 | I4: =I38 -> 15 | K4: =K38 -> 14 | M4: =M38 -> 15 | O4: =O38 -> 15 | Q4: =Q38 -> 17 | S4: =S38 -> 18 | U4: =U38 -> 18 | W4: =W38 -> 18 | Y4: =Y38 -> 20 | AA4: =AA38 -> 20
A5: 差異 | C5: =C3-C4 -> 2 | E5: =E4-E3 -> -2 | G5: =G4-G3 -> -1 | I5: =I4-I3 -> -1 | K5: =K4-K3 -> -4 | M5: =M4-M3 -> -3 | O5: =O4-O3 -> -3 | Q5: =Q4-Q3 -> -3 | S5: =S4-S3 -> -2 | U5: =U4-U3 -> -2 | W5: =W4-W3 -> -2 | Y5: =Y4-Y3 -> 0 | AA5: =AA4-AA3 -> 0
J6: 受注人数不足
A7: 売上目標（士業C） | E7: 65014400 | G7: 62865000 | I7: 63864900 | K7: 62180800 | M7: 64158600 | O7: 63621800 | Q7: 64871400 | S7: 60713000 | U7: 61365000 | W7: 61691000 | Y7: 63647000 | AA7: 61677000
A8: 売上目標（士業必達） | E8: 59104000 | G8: 57150000 | I8: 58059000 | K8: 56528000 | M8: 58326000 | O8: 57838000 | Q8: 58974000 | S8: 55193636 | U8: 55786364 | W8: 56082727 | Y8: 57860909 | AA8: 56070000
A9: 面談総数 | E9: =F38 -> 221 | G9: =H38 -> 235 | I9: =J38 -> 233 | K9: =L38 -> 233 | M9: =N38 -> 245 | O9: =P38 -> 257 | Q9: =R38 -> 271 | S9: =T38 -> 269 | U9: =V38 -> 281 | W9: =X38 -> 282 | Y9: =Z38 -> 295 | AA9: =AB38 -> 280
A10: 平均面談総数 | K10: =ROUND(AVERAGE(L16:L29),0) -> 16 | M10: =ROUND(AVERAGE(N16:N30),0) -> 16 | O10: =ROUND(AVERAGE(P16:P31),0) -> 15 | Q10: =ROUND(AVERAGE(R16:R33),0) -> 15 | S10: =ROUND(AVERAGE(T16:T33),0) -> 14 | U10: =ROUND(AVERAGE(V16:V34),0) -> 15 | W10: =ROUND(AVERAGE(X16:X34),0) -> 15 | Y10: =ROUND(AVERAGE(Z16:Z34),0) -> 15 | AA10: =ROUND(AVERAGE(AB22:AB36),0) -> 12
A11: 最多面談数 | E11: =MAX(F16:F37) -> 22 | G11: =MAX(H16:H37) -> 23 | I11: =MAX(J16:J37) -> 23 | K11: =MAX(L16:L37) -> 21 | M11: =MAX(N16:N37) -> 21 | O11: =MAX(P16:P37) -> 20 | Q11: =MAX(R16:R37) -> 22 | S11: =MAX(T16:T37) -> 20 | U11: =MAX(V16:V37) -> 20 | W11: =MAX(X16:X37) -> 20 | Y11: =MAX(Z16:Z37) -> 20 | AA11: =MAX(AB16:AB37) -> 20
A13: 受注候補 | C13: =C49 -> 0 | E13: =E49 -> 5 | G13: =G49 -> 4 | I13: =I49 -> 4 | K13: =K49 -> 6 | M13: =M49 -> 5 | O13: =O49 -> 4 | Q13: =Q49 -> 4 | S13: =S49 -> 3 | U13: =U49 -> 4 | W13: =W49 -> 4 | Y13: =Y49 -> 2 | AA13: =AA49 -> 2
A15: 個別面談件数 | C15: 12月 | E15: 1月 | G15: 2月 | I15: 3月 | K15: 4月 | M15: 5月 | O15: 6月 | Q15: 7月 | S15: 8月 | U15: 9月 | W15: 10月 | Y15: 11月 | AA15: 12月
C16: 山田 | D16: 200 | E16: 山田 | F16: 22 | G16: 山田 | H16: 22 | I16: 山田 | J16: 17 | K16: 山田 | L16: 20 | M16: 山田 | N16: 21 | O16: 山田 | P16: 20 | Q16: 山田 | R16: 19 | S16: 山田 | T16: 18 | U16: 山田 | V16: 19 | W16: 山田 | X16: 19 | Y16: 山田 | Z16: 19 | AA16: 山田 | AB16: 17
C17: 嶋津 | D17: 200 | E17: 嶋津 | F17: 17 | G17: 嶋津 | H17: 19 | I17: 嶋津 | J17: 17 | K17: 嶋津 | L17: 15 | M17: 嶋津 | N17: 15 | O17: 嶋津 | P17: 15 | Q17: 嶋津 | R17: 15 | S17: 嶋津 | T17: 14 | U17: 嶋津 | V17: 15 | W17: 嶋津 | X17: 15 | Y17: 嶋津 | Z17: 15 | AA17: 嶋津 | AB17: 13
C18: 五十嵐 | D18: 200 | E18: 五十嵐 | F18: 5 | G18: 五十嵐 | H18: 8 | I18: 五十嵐 | J18: 7 | K18: 五十嵐 | L18: 12 | M18: 五十嵐 | N18: 12 | O18: 五十嵐 | P18: 12 | Q18: 五十嵐 | R18: 10 | S18: 五十嵐 | T18: 10 | U18: 五十嵐 | V18: 10 | W18: 五十嵐 | X18: 10 | Y18: 五十嵐 | Z18: 10 | AA18: 五十嵐 | AB18: 10
C19: 渡邉 | D19: 200 | E19: 渡邉 | F19: 22 | G19: 渡邉 | H19: 22 | I19: 渡邉 | J19: 23 | K19: 渡邉 | L19: 21 | M19: 渡邉 | N19: 21 | O19: 渡邉 | P19: 20 | Q19: 渡邉 | R19: 19 | S19: 渡邉 | T19: 18 | U19: 渡邉 | V19: 19 | W19: 渡邉 | X19: 19 | Y19: 渡邉 | Z19: 19 | AA19: 渡邉 | AB19: 17
C20: 梅澤 | D20: 200 | E20: 梅澤 | F20: 22 | G20: 梅澤 | H20: 23 | I20: 梅澤 | J20: 23 | K20: 梅澤 | L20: 21 | M20: 梅澤 | N20: 21 | O20: 梅澤 | P20: 20 | Q20: 梅澤 | R20: 19 | S20: 梅澤 | T20: 18 | U20: 梅澤 | V20: 19 | W20: 梅澤 | X20: 19 | Y20: 梅澤 | Z20: 19 | AA20: 梅澤 | AB20: 17
C21: 齋藤 | D21: 200 | E21: 齋藤 | F21: 22 | G21: 齋藤 | H21: 23 | I21: 齋藤 | J21: 23 | K21: 齋藤 | L21: 21 | M21: 齋藤 | N21: 21
C22: 藤田 | D22: 130 | E22: 藤田 | F22: 7 | G22: 藤田 | H22: 8 | I22: 藤田 | J22: 8 | K22: 藤田 | L22: 8 | M22: 藤田 | N22: 7 | O22: 藤田 | P22: 7 | Q22: 藤田 | R22: 7 | S22: 藤田 | T22: 7 | U22: 藤田 | V22: 6 | W22: 藤田 | X22: 7 | Y22: 藤田 | Z22: 7 | AA22: 藤田 | AB22: 6
C23: 馬場 | D23: 200 | E23: 馬場 | F23: 22 | G23: 馬場 | H23: 22 | I23: 馬場 | J23: 23 | K23: 馬場 | L23: 21 | M23: 馬場 | N23: 21 | O23: 馬場 | P23: 20 | Q23: 馬場 | R23: 19 | S23: 馬場 | T23: 18 | U23: 馬場 | V23: 19 | W23: 馬場 | X23: 19 | Y23: 馬場 | Z23: 19 | AA23: 馬場 | AB23: 17
C24: 角田 | D24: 200 | E24: 角田 | F24: 22 | G24: 角田 | H24: 23 | I24: 角田 | J24: 23 | K24: 角田 | L24: 21 | M24: 角田 | N24: 21 | O24: 角田 | P24: 20 | Q24: 角田 | R24: 19 | S24: 角田 | T24: 18 | U24: 角田 | V24: 19 | W24: 角田 | X24: 19 | Y24: 角田 | Z24: 19 | AA24: 角田 | AB24: 17
C25: 山崎 | D25: 200 | E25: 山崎 | F25: 18 | G25: 山崎 | H25: 22 | I25: 山崎 | J25: 23 | K25: 山崎 | L25: 21 | M25: 山崎 | N25: 21 | O25: 山崎 | P25: 20 | Q25: 山崎 | R25: 15 | S25: 山崎 | T25: 12 | U25: 山崎 | V25: 12 | W25: 山崎 | X25: 12 | Y25: 山崎 | Z25: 12 | AA25: 山崎 | AB25: 10
C26: 森谷 | D26: 200 | E26: 森谷 | F26: 8 | G26: 森谷 | H26: 10 | I26: 森谷 | J26: 10 | K26: 森谷 | L26: 10 | M26: 森谷 | N26: 10 | O26: 森谷 | P26: 10 | Q26: 森谷 | R26: 10 | S26: 森谷 | T26: 10 | U26: 森谷 | V26: 10 | W26: 森谷 | X26: 10 | Y26: 森谷 | Z26: 10 | AA26: 森谷 | AB26: 10
C27: 新井 | D27: 100 | E27: 新井 | F27: 8 | G27: 新井 | H27: 6 | I27: 新井 | J27: 6 | K27: 新井 | L27: 10 | M27: 新井 | N27: 10 | O27: 新井 | P27: 4 | Q27: 新井 | R27: 6 | S27: 新井 | T27: 6 | U27: 新井 | V27: 6 | W27: 新井 | X27: 6 | Y27: 新井 | Z27: 6 | AA27: 新井 | AB27: 6
C28: 花井 | D28: 200 | E28: 花井 | F28: 22 | G28: 花井 | H28: 23 | I28: 花井 | J28: 23 | K28: 花井 | L28: 21 | M28: 花井 | N28: 21 | O28: 花井 | P28: 20 | Q28: 花井 | R28: 19 | S28: 花井 | T28: 18 | U28: 花井 | V28: 19 | W28: 花井 | X28: 19 | Y28: 花井 | Z28: 19 | AA28: 花井 | AB28: 18
A29: 受注同席あり→青字 | C29: 杉原 | D29: 110 | E29: 杉原 | F29: 4 | G29: 杉原 | H29: 4 | I29: 杉原 | J29: 4 | K29: 杉原 | L29: 6 | M29: 杉原 | N29: 7 | O29: 杉原 | P29: 6 | Q29: 杉原 | R29: 6 | S29: 杉原 | T29: 6 | U29: 杉原 | V29: 6 | W29: 杉原 | X29: 6 | Y29: 杉原 | Z29: 6 | AA29: 杉原 | AB29: 5
A30: ※受注としてのカウント無 | G30: 加藤 | H30: 0 | I30: 加藤 | J30: 3 | K30: 加藤 | L30: 5 | M30: 加藤 | N30: 10 | O30: 加藤 | P30: 16 | Q30: 加藤 | R30: 16 | S30: 加藤 | T30: 15 | U30: 加藤 | V30: 15 | W30: 加藤 | X30: 15 | Y30: 加藤 | Z30: 15 | AA30: 加藤 | AB30: 13
A31: 単独デビュー後→黒字 | M31: 上村 | N31: 6 | O31: 上村 | P31: 15 | Q31: 上村 | R31: 22 | S31: 上村 | T31: 20 | U31: 上村 | V31: 19 | W31: 上村 | X31: 19 | Y31: 上村 | Z31: 19 | AA31: 上村 | AB31: 17
O32: 鎌田 | P32: 6 | Q32: 鎌田 | R32: 15 | S32: 鎌田 | T32: 15 | U32: 鎌田 | V32: 15 | W32: 鎌田 | X32: 15 | Y32: 鎌田 | Z32: 15 | AA32: 鎌田 | AB32: 13
O33: 登坂 | P33: 6 | Q33: 登坂 | R33: 15 | S33: 登坂 | T33: 20 | U33: 登坂 | V33: 18 | W33: 登坂 | X33: 18 | Y33: 登坂 | Z33: 19 | AA33: 登坂 | AB33: 17
O34: 齋藤さん分 | P34: 20 | Q34: 齋藤さん分 | R34: 20 | S34: 市川 | T34: 6 | U34: 市川 | V34: 15 | W34: 市川 | X34: 15 | Y34: 市川 | Z34: 15 | AA34: 市川 | AB34: 13
S35: 齋藤さん分 | T35: 20 | U35: 齋藤さん分 | V35: 20 | W35: 齋藤さん分 | X35: 20 | Y35: 太田 | Z35: 6 | AA35: 太田 | AB35: 12
Y36: 西原 | Z36: 6 | AA36: 西原 | AB36: 12
Y37: 齋藤さん分 | Z37: 20 | AA37: 齋藤さん分 | AB37: 20
C38: =COUNTA(C16:C37) -> 14 | D38: =SUM(D16:D37) -> 2540 | E38: =COUNTA(E16:E37) -> 14 | F38: =SUM(F16:F37) -> 221 | G38: =COUNTA(G16:G37) -> 15 | H38: =SUM(H16:H37) -> 235 | I38: =COUNTA(I16:I37) -> 15 | J38: =SUM(J16:J37) -> 233 | K38: =COUNTA(K16:K29) -> 14 | L38: =SUM(L16:L37) -> 233 | M38: =COUNTA(M16:M30) -> 15 | N38: =SUM(N16:N37) -> 245 | O38: =COUNTA(O16:O31) -> 15 | P38: =SUM(P16:P37) -> 257 | Q38: =COUNTA(Q16:Q33) -> 17 | R38: =SUM(R16:R37) -> 271 | S38: =COUNTA(S16:S34) -> 18 | T38: =SUM(T16:T37) -> 269 | U38: =COUNTA(U16:U34) -> 18 | V38: =SUM(V16:V37) -> 281 | W38: =COUNTA(W16:W34) -> 18 | X38: =SUM(X16:X37) -> 282 | Y38: =COUNTA(Y16:Y36) -> 20 | Z38: =SUM(Z16:Z37) -> 295 | AA38: =COUNTA(AA16:AA36) -> 20 | AB38: =SUM(AB16:AB37) -> 280
O39: 齋藤さん分 +20件要調整
A40: 受注候補 | C40: 12月 | E40: 1月 | G40: 2月 | I40: 3月 | K40: 4月 | M40: 5月 | O40: 6月 | Q40: 7月 | S40: 8月 | U40: 9月 | W40: 10月 | Y40: 11月 | AA40: 12月
E41: 森下
C42: 上村 | D42: 200 | E42: 加藤 | G42: 鎌田 | I42: 鎌田 | K42: 鎌田 | M42: 鎌田 | O42: 市川 | Q42: 市川 | S42: 太田 | U42: 太田 | W42: 太田 | Y42: 酒井 | AA42: 酒井
...

Sheet 顧客管理
A1: 顧客管理マンパワー推移2026
C2: 12月 | G2: 1月 | K2: 2月 | Q2: 3月 | S2: 4月 | X2: 5月 | AC2: 6月 | AH2: 7月 | AM2: 8月 | AR2: 9月 | AW2: 10月 | BB2: 11月 | BG2: 12月
A3: 適正人数 | C3: 25 | S3: =ROUND((受注推移2!E4*1.3),0) -> 18 | X3: =ROUND((受注推移2!M4*1.3),0) -> 20 | AC3: =ROUND((受注推移2!O4*1.3),0) -> 20 | AH3: =ROUND((受注推移2!Q4*1.3),0) -> 22 | AM3: =ROUND((受注推移2!S4*1.3),0) -> 23 | AR3: =ROUND((受注推移2!U4*1.3),0) -> 23 | AW3: =ROUND((受注推移2!W4*1.3),0) -> 23 | BB3: =ROUND((受注推移2!W4*1.3),0) -> 23 | BG3: =ROUND((受注推移2!AA4*1.3),0) -> 26
A4: 担当者数 | C4: =#REF! -> #REF! | G4: =#REF! -> #REF! | K4: =#REF! -> #REF! | Q4: =#REF! -> #REF! | S4: =S81 -> 28 | X4: =X81 -> 29 | AC4: =AC81 -> 30 | AH4: =ROUND(AH81,0) -> 29 | AM4: =ROUND(AM81,0) -> 28 | AR4: =ROUND(AR81,0) -> 28 | AW4: =ROUND(AW81,0) -> 28 | BB4: =ROUND(BB81,0) -> 28 | BG4: =ROUND(BG81,0) -> 28
A5: 差異 | C5: =C4-C3 -> #REF! | G5: =G4-G3 -> #REF! | K5: =K4-K3 -> #REF! | Q5: =Q4-Q3 -> #REF! | S5: =S4-S3 -> 10 | X5: =X4-X3 -> 9 | AC5: =AC4-AC3 -> 10 | AH5: =AH4-AH3 -> 7 | AM5: =AM4-AM3 -> 5 | AR5: =AR4-AR3 -> 5 | AW5: =AW4-AW3 -> 5 | BB5: =BB4-BB3 -> 5 | BG5: =BG4-BG3 -> 2
A6: 実働×熟練度 | C6: =#REF! -> #REF! | G6: =#REF! -> #REF! | K6: =#REF! -> #REF! | Q6: =#REF! -> #REF! | S6: =ROUND(U81,0) -> 2490 | X6: =ROUND(Z81,0) -> 2633 | AC6: =ROUND(AE81,0) -> 2876 | AH6: =ROUND(AJ81,0) -> 2973 | AM6: =ROUND(AO81,0) -> 3028 | AR6: =ROUND(AT81,0) -> 3148 | AW6: =ROUND(AY81,0) -> 3436 | BB6: =ROUND(BD81,0) -> 3591 | BG6: =ROUND(BI81,0) -> 3567
C7: 管理人数不足 | S7: 熟練度低
C8: 受注担当内訳
A9: 相続事業部 | C9: 12月 | G9: 1月 | K9: 2月 | Q9: 3月 | S9: 4月 | X9: 5月 | AC9: 6月 | AH9: 7月 | AM9: 8月 | AR9: 9月 | AW9: 10月 | BB9: 11月 | BG9: 12月
C10: 担当者名 | D10: 稼働時間 | E10: 管理件数 | F10: 熟練度 | G10: 担当者名 | H10: 稼働時間 | I10: 管理件数 | J10: 熟練度 | K10: 担当者名 | L10: 稼働時間 | M10: 管理件数 | N10: 熟練度 | O10: 担当者名 | P10: 稼働時間 | Q10: 管理件数 | R10: 熟練度 | S10: 担当者名 | T10: 実働 | U10: ×熟練度 | V10: 管理件数 | W10: 熟練度 | X10: 担当者名 | Y10: 稼働時間 | Z10: ×熟練度 | AA10: 管理件数 | AB10: 熟練度 | AC10: 担当者名 | AD10: 稼働時間 | AE10: ×熟練度 | AF10: 管理件数 | AG10: 熟練度 | AH10: 担当者名 | AI10: 稼働時間 | AJ10: ×熟練度 | AK10: 管理件数 | AL10: 熟練度 | AM10: 担当者名 | AN10: 稼働時間 | AO10: ×熟練度 | AP10: 管理件数 | AQ10: 熟練度 | AR10: 担当者名 | AS10: 稼働時間 | AT10: ×熟練度 | AU10: 管理件数 | AV10: 熟練度 | AW10: 担当者名 | AX10: 稼働時間 | AY10: ×熟練度 | AZ10: 管理件数 | BA10: 熟練度 | BB10: 担当者名 | BC10: 稼働時間 | BD10: ×熟練度 | BE10: 管理件数 | BF10: 熟練度 | BG10: 担当者名 | BH10: 稼働時間 | BI10: ×熟練度 | BJ10: 管理件数 | BK10: 熟練度
B11: 馬場T | C11: 渡部 | D11: 200h | F11: 0.95 | G11: 渡部 | H11: 200h | J11: 0.95 | K11: 渡部 | L11: 200h | N11: 0.95 | O11: 渡部 | P11: 200h | R11: 0.95 | S11: 渡部 | T11: 200 | U11: =ROUND(T11*W11,0) -> 190 | V11: 53 | W11: 0.95 | X11: 渡部 | Y11: 200 | Z11: =Y11*AB11 -> 190 | AA11: 53 | AB11: 0.95 | AC11: 渡部 | AD11: 200 | AE11: =ROUND(AD11*AG11,0) -> 190 | AF11: 40 | AG11: 0.95 | AH11: 渡部 | AI11: 200 | AJ11: =ROUND(AI11*AL11,0) -> 190 | AK11: 40 | AL11: 0.95 | AM11: 渡部 | AN11: 200 | AO11: =ROUND(AN11*AQ11,0) -> 190 | AP11: 40 | AQ11: 0.95 | AR11: 渡部 | AS11: 200 | AT11: =ROUND(AS11*AV11,0) -> 190 | AU11: 40 | AV11: 0.95 | AW11: 渡部 | AX11: 200 | AY11: =AX11*BA11 -> 190 | AZ11: 40 | BA11: 0.95 | BB11: 渡部 | BC11: 200 | BD11: =BC11*BF11 -> 190 | BE11: 40 | BF11: 0.95 | BG11: 渡部 | BH11: 200 | BI11: =BH11*BK11 -> 190 | BJ11: 40 | BK11: 0.95
C12: 宮川 | D12: 165h | F12: 0.75 | G12: 宮川 | H12: 165h | J12: 0.75 | K12: 宮川 | L12: 165h | N12: 0.75 | O12: 宮川 | P12: 165h | R12: 0.75 | S12: 宮川 | T12: 165 | U12: =ROUND(T12*W12,0) -> 124 | V12: 45 | W12: 0.75 | X12: 宮川 | Y12: 165 | Z12: =Y12*AB12 -> 123.75 | AA12: 45 | AB12: 0.75 | AC12: 宮川 | AD12: 165 | AE12: =ROUND(AD12*AG12,0) -> 124 | AF12: 45 | AG12: 0.75 | AH12: 宮川 | AI12: 165 | AJ12: =ROUND(AI12*AL12,0) -> 132 | AK12: 45 | AL12: 0.8 | AM12: 宮川 | AN12: 165 | AO12: =ROUND(AN12*AQ12,0) -> 132 | AP12: 45 | AQ12: 0.8 | AR12: 宮川 | AS12: 165 | AT12: =ROUND(AS12*AV12,0) -> 132 | AU12: 45 | AV12: 0.8 | AW12: 宮川 | AX12: 165 | AY12: =AX12*BA12 -> 140.25 | AZ12: 45 | BA12: 0.85 | BB12: 宮川 | BC12: 165 | BD12: =BC12*BF12 -> 140.25 | BE12: 45 | BF12: 0.85 | BG12: 宮川 | BH12: 165 | BI12: =BH12*BK12 -> 140.25 | BJ12: 45 | BK12: 0.85
