Workbook
Name 一般社団法人いきいき: 抽出元!$A$3
Name 株式会社オーシャン: 抽出元!$A$4
Name 徽章1: INDIRECT('[1]請求書（前受金）司'!$R$9:$V$9)
Name 徽章1: INDIRECT(#REF!)
Name 徽章1: INDIRECT('[2]請求書（前受金）司'!$R$9:$V$9)
Name 徽章1: INDIRECT(#REF!)
Name 徽章2: INDIRECT(#REF!)
Name 徽章2: INDIRECT('[1]請求書（前受金）行'!$R$9:$V$9)
Name 徽章2: INDIRECT('請求書（前受金）行'!$R$10:$V$10)
Name 徽章2: INDIRECT('[2]請求書（前受金）行'!$R$9:$V$9)
Name 徽章2: INDIRECT('領収書（前受金）行'!$R$10:$V$10)
Name 徽章2: INDIRECT('領収書（前受金）司'!$R$10:$V$10)
Name 徽章2: INDIRECT('請求書（前受金）行'!$R$10:$V$10)
Name 徽章3: INDIRECT('[1]請求書 (確定) 司'!$R$9:$V$9)
Name 徽章3: INDIRECT(#REF!)
Name 徽章3: INDIRECT('[2]請求書 (確定) 司'!$R$9:$V$9)
Name 徽章3: INDIRECT(#REF!)
Name 徽章4: INDIRECT(#REF!)
Name 徽章4: INDIRECT('請求書 (確定)行'!$R$10:$V$10)
Name 徽章4: INDIRECT('請求書 (確定)司'!$R$10:$V$10)
Name 徽章4: INDIRECT(#REF!)
Name 徽章4: INDIRECT('[2]請求書 (確定)行'!$R$9:$V$9)
Name 徽章4: INDIRECT('領収書 (確定)行'!$R$10:$V$10)
Name 徽章4: INDIRECT('領収書 (確定)司'!$R$10:$V$10)
Name 徽章4: INDIRECT(#REF!)
Name 行政書士法人: 抽出元!$A$1
Name 司法書士法人: 抽出元!$A$2

Sheet 入力元
C4: 管理番号 | L4: R | N4: 8 | P4: - | R4: Y
C5: 郵便番号
C6: 依頼者住所
C7: マンション名以下
C8: 依頼者氏名 | AC8: 外字
C9: 生年月日 | L9: 昭和 | R9: 年 | V9: 月 | Z9: 日 | AC9: 無 | AJ9: =IF($AC$9="有","依頼者氏名","")
C13: 被相続人氏名 | AC13: 外字
C14: 死亡日 | L14: 令和 | R14: 年 | V14: 月 | Z14: 日 | AC14: 無 | AJ14: =IF($AC$14="有","・被相続人氏名","")

Sheet 簡易契約書 
A1: =TODAY() -> 46225 | C1: 行政書士法人 | H1: ←どっちか選ぶ
B2: =入力元!L4 -> R | C2: =入力元!N4 -> 8 | D2: - | E2: =入力元!R4 -> Y | F2: =入力元!T4 -> 0
B3: 委 任 契 約 書 【 契 約 事 項 】
AB4: 行政書士法人 | AF4: 黒田 美菜子 | AI4: 神奈川県横浜市西区高島２丁目１４番１７号クレアトール横浜５階 | AJ4: みずほ | AL4: 横浜東口支店 | AO4: 2167817 | AR4: 行政書士法人オーシャン | AW4: （ギョウセイショシホウジンオーシャン） | AX4: 行政書士会
AB5: 司法書士法人 | AF5: 山田 哲 | AI5: 神奈川県横浜市西区高島２丁目５番１２号横浜ＤＫビル３階 | AJ5: みずほ | AL5: 横浜東口支店 | AO5: 2169216 | AR5: 司法書士法人オーシャン 代表社員 山田 哲 | AW5: （シホウショシホウジンオーシャンダイヒョウシャインヤマダサトシ） | AX5: 司法書士会
B6: １. 委任業務の範囲
B7: ２. 期 間 | I7: ご契約日より、原則として本契約締結の日より６ヶ月後の応当日までとする。 | AB7: 外字
AB8: =入力元!$AJ$9&入力元!$AJ$14&IF(OR(入力元!$AC$9="有",入力元!$AC$14="有"),"に外字あり","")
B9: ３. 報 酬 | J9: 金 | O9: 円（税込） | Q9: ※報酬額基準表に基づく
B11: ４. 支 払 条 件 | I11: 1. | J11: 報酬の支払いは、別紙請求書記載の銀行口座に振込とする。
I12: 2. | J12: 業務着手は、報酬の入金を確認した時から開始するものとする。
I13: 3. | J13: 甲又は乙の都合により委任業務の着手前にこの契約を解除した時は
J14: 既に支払った報酬金は返還するものとする。 但し、着手後に解除した
J15: 時は業務の進捗に応じ、乙の計算に基づき算出した報酬額を支払うも
J16: のとする。
B17: ５. 資 料 の 提 示 | J17: 委任業務の処理に必要となる情報や資料等の提供を乙に求められた
J18: 場合、甲は速やかに資料等の提示（提供）を行うものとする。
B19: ６. そ の 他 事 項 | I19: 1. | J19: 甲は委任業務の処理に必要な実費（戸籍収集の際の手数料や郵送
J20: 代・登録免許税等）を乙の請求に基づき支払う。
I21: 2. | J21: 本契約について、甲又は乙から契約解除・変更する場合は、予め７
J22: 日前に相手方にその申出をするものとする。
B23: 7. 特 記 事 項
J24: 特になし
C29: 上記のとおり委任契約を致します。
C30: 令和 年 月 日 | K30: （ご契約日）
C32: （甲：委任者） | G32: 住 所 | J32: =入力元!L6 -> 0
J33: =入力元!L7 -> 0
G34: 氏 名
G35: （署名）
C38: （乙：受任者） | G38: =VLOOKUP(C1,AB4:AR5,8,FALSE) -> 神奈川県横浜市西区高島２丁目１４番１７号クレアトール横浜５階
G39: =VLOOKUP(C1,AB4:AR5,1,FALSE) -> 行政書士法人 | K39: オーシャン | O39: 代表社員 | R39: =VLOOKUP(C1,AB4:AR5,5,FALSE) -> 黒田 美菜子
G40: 神奈川県 | J40: =VLOOKUP(C1,AB4:AX5,23,FALSE) -> 行政書士会 | N40: 所属

Sheet 簡易契約書 (行・司)
A1: =TODAY() -> 46225
B2: =入力元!L4 -> R | C2: =入力元!N4 -> 8 | D2: - | E2: =入力元!R4 -> Y | F2: =入力元!T4 -> 0
B3: 委 任 契 約 書 【 契 約 事 項 】
AB4: 行政書士法人 | AF4: 黒田 美菜子 | AJ4: みずほ | AL4: 横浜東口 | AO4: 2167817 | AR4: 行政書士法人オーシャン | AX4: 行政書士会
AB5: 司法書士法人 | AF5: 山田 哲 | AJ5: 横浜 | AL5: 藤沢中央 | AO5: 6114123 | AR5: 司法書士法人オーシャン 代表社員 山田 哲 | AX5: 司法書士会
B6: １. 委任業務の範囲 | I6: 相続登記手続きサポートプラン
B7: ２. 期 間 | I7: ご契約日より、原則として本契約締結の日より６ヶ月後の応当日までとする。 | AB7: 外字
AB8: =入力元!$AJ$9&入力元!$AJ$14&IF(OR(入力元!$AC$9="有",入力元!$AC$14="有"),"に外字あり","")
B9: ３. 報 酬 | J9: 金 | K9: 148500 | O9: 円（税込） | Q9: ※報酬額基準表に基づく
B11: ４. 支 払 条 件 | I11: 1. | J11: 報酬の支払いは、別紙請求書記載の銀行口座に振込とする。
I12: 2. | J12: 業務着手は、報酬の入金を確認した時から開始するものとする。
I13: 3. | J13: 甲又は乙、丙の都合により委任業務の着手前にこの契約を解除した
J14: 時は、既に支払った報酬金は返還するものとする。 但し、着手後に解
J15: 除した時は、業務の進捗に応じ、乙、丙の計算に基づき算出した報酬
J16: 額を支払うものとする。
B17: ５. 資 料 の 提 示 | J17: 委任業務の処理に必要となる情報や資料等の提供を乙及び丙に
J18: 求められた場合、甲は速やかに資料等の提示（提供）を行うものとする。
B19: ６. そ の 他 事 項 | I19: 1. | J19: 甲は委任業務の処理に必要な実費（戸籍収集の際の手数料や郵送
J20: 代・登録免許税等）を乙及び丙の請求に基づき支払う。
I21: 2. | J21: 本契約について、甲又は乙、丙から契約解除・変更する場合は予め
J22: ７日前に相手方にその申出をするものとする。
B23: 7. 特 記 事 項
J24: 特になし
C29: 上記のとおり委任契約を致します。
C30: 令和 年 月 日 | K30: （ご契約日）
C32: （甲：委任者） | G32: 住 所 | J32: =入力元!L6 -> 0
J33: =入力元!L7 -> 0
G34: 氏 名
G35: （署名）
C39: （乙：受任者） | G39: 神奈川県横浜市西区高島２丁目１４番１７号クレアトール横浜５階
G40: 行政書士法人 | K40: オーシャン | O40: 代表社員 | R40: 黒田 美菜子
G41: 神奈川県 | J41: 行政書士会 | N41: 所属
C45: （丙：受任者） | G45: 神奈川県横浜市西区高島２丁目１３－２横浜駅前共同ビル
G46: 司法書士法人オーシャン | O46: 代表社員 | R46: 山田 哲
G47: 神奈川県 | J47: 司法書士会 | N47: 所属

Sheet 契約書★財産調査あり（連名）
A1: 委 任 契 約 書 | BC1: =TODAY() -> 46225
AB2: 第１０条 （報酬） | BC2: 外字
AC3: 甲 が 乙 及び 丙 に対して支払う報酬は、 | AM3: 別紙報酬額基準表 | AR3: =IF(AM3="別紙報酬額基準表","の通りとする。","円（税込）とする。") -> の通りとする。 | BC3: =入力元!$AJ$9&入力元!$AJ$14&IF(OR(入力元!$AC$9="有",入力元!$AC$14="有"),"に外字あり","")
AC4: なお， 乙 及び 丙 は，報酬とは別に，印紙代，切手代，交付手数料，予納金，交通費，通信費等の実費等
AC5: （以下「実費」という）について実額を受け取ることができる。また，実費について乙及び丙が立て替えることの
A6: 後記依頼者を 甲 とし，後記行政書士を 乙 ，後記司法書士を 丙 として，次のとおり契約する。 | AC6: できる金額の総額は 金５万円 を上限とする。 | BC6: 別紙報酬額基準表
A7: 第１条 （行政書士 委任業務の表示） | BC7: 2000 | BD7: ←入力してください
B8: 甲 は 乙 に下記業務（以下「本件業務」という）を委任し， 乙 はこれを受任する。 | AC8: ２ | AD8: 報酬基準に記載のない業務は， 甲 及び 乙 及び 丙 協議の上，報酬額を決定するものとする。
B9: （１） | D9: 故 | E9: =入力元!L13 -> 0 | I9: 様の | K9: 相続 | P9: に関する手続き | BC9: 行政書士業務
C10: （書類の作成・交付申請受領及び申請書等の提出を含む）の一切 | AB10: 第１１条 （委任業務の終了） | BC10: 相続
B11: （２） | C11: 前号の手続きの前提となる手続き | AC11: 乙 及び 丙 は，前条に定める実費及び未払いの報酬があるときは，その支払いを確認したときに，本件業務 | BC11: 遺言書の作成
B12: （３） | C12: 前号の手続きに必要となる付属手続き | AC12: に関する書類を 甲 に引き渡すものとする。 | BC12: ※その他業務はこちらに上書き
A14: 第２条 （司法書士 委任業務の表示） | AB14: 第1２条 （契約期間）
B15: 甲 は 丙 に本件業務に関する | I15: 不動産登記業務 | O15: を委任し， 丙 はこれを受任する。 | AC15: 本契約の契約期間は、原則として契約締結の日より | AO15: 8ヶ月 | AQ15: 後の応当日までとする。
A17: 第３条 （協議の義務） | AB17: 第１３条 （解除事由）
B18: 本件業務の処理に関連して，前項各号以外の手続きが必要となったときは，別途， 甲 ・ 乙 ・ 丙 の協議 | AC18: 乙 及び 丙 は，以下のいずれかの事由が生じたときは，本契約を解除することができる。 | BC18: 司法書士業務
B19: で決定するものとする。 | AC19: （１） | AD19: 甲 が 乙 及び 丙 に対し，虚偽の事実を申告し，または，事実を正当な理由なく告げなかったため， 乙 | BC19: 不動産登記業務
AD20: 及び 丙 の事件処理に著しい不都合が生じたとき | BC20: 相続放棄
A21: 第４条 （法令の遵守） | AC21: （２） | AD21: 甲 と 乙 及び 丙 との信頼関係が破綻したとき | BC21: ※その他業務はこちらに上書き
B22: 乙 及び 丙 は，各自行政書士法・司法書士法及び所属行政書士会・司法書士会の会則に従い，誠実に | AC22: （３） | AD22: 契約期間が応当日を超過したとき
B23: 委任事務の処理にあたるものとする。
AB24: 第１４条 （甲の事由による業務の終了）
A25: 第５条 （復代理人の選任） | AC25: 乙 及び 丙 は，以下のいずれかの事由が生じたときであっても， 甲 に対し，報酬を請求することができる。
B26: 乙 及び 丙 は，他の行政書士及び司法書士と共同して本件業務を処理し，あるいは弁護士，弁理士， | AC26: （１） | AD26: 甲 が 乙 及び 丙 の責任でない事情により 乙 または 丙 を解任したとき
B27: 公認会計士，税理士，土地家屋調査士，社会保険労務士，不動産鑑定士等に関連する業務を処理又は | AC27: （２） | AD27: 甲 が 乙 及び 丙 の同意なく依頼事件を終わらせたとき
B28: 補助させることができる。 | AC28: （３） | AD28: 甲 が故意又は重大な過失により 乙 及び 丙 の事件処理を不能にしたとき
A30: ２ | B30: 本件業務の処理に関連して，復代理人の選任が必要となったときは， 甲 はあらかじめ承諾するものとす | AB30: 第１５条 （秘密保持）
B31: る。 | AC31: 乙 及び 丙 は，業務上知り得た秘密を正当な理由なく他に漏らし，又は利用してはならないこととする。
AC32: 業務が終了した後も，同様とする。
A33: 第６条 （報告の義務）
B34: 乙 及び 丙 は，本件業務に関し， 甲 に報告義務を負うものとする。 | AB34: 第１６条 （反社会的勢力の排除）
AC35: 裏面に記載のとおりとする。
A36: 第７条 （手続きの決定）
B37: 甲 と 乙 及び 丙 は本件業務について十分協議のうえ，具体的手続を決定するものとする。 | AB37: 上記契約の成立を証するため，本書２通を作成し， 甲 及び 乙 及び 丙 が署名・捺印のうえ，甲と乙丙が各１通
AB38: を保有する。
A39: 第８条 （財産調査及び遺言書の確認）
B40: 甲 及び 乙 及び 丙 は，本件業務に関する財産調査において， 甲 から委任をうけた範囲内で行うもの
B41: とし，その財産調査の開始によって，金融・証券その他各種口座が凍結されることに 甲 はあらかじめ承諾 | AB41: 令和 年 月 日
B42: するものとする。また，委任の範囲を超えた財産が発見されたとしても， 乙 及び 丙 は，その責に任じない
B43: ものとする。 | AB43: 甲 | AD43: 住所 | AF43: =入力元!L6 -> 0
...

Sheet 契約書★財産調査なし（連名）
A1: 委 任 契 約 書 | BC1: =TODAY() -> 46225
BC2: 外字
BC3: =入力元!$AJ$9&入力元!$AJ$14&IF(OR(入力元!$AC$9="有",入力元!$AC$14="有"),"に外字あり","")
AB4: 第１０条 （委任業務の終了）
AC5: 乙 及び 丙 は，前条に定める実費及び未払いの報酬があるときは、その支払いを確認したときに，本件業務
A6: 後記依頼者を 甲 とし，後記行政書士を 乙 ,後記司法書士を 丙 として，次のとおり契約する。 | AC6: に関する書類を 甲 に引き渡すものとする。 | BC6: 別紙報酬額基準表
A8: 第１条 （行政書士 委任業務の表示） | AB8: 第11条 （契約期間）
B9: 甲 は 乙 に下記業務（以下「本件業務」という）を委任し， 乙 はこれを受任する。 | AC9: 本契約の契約期間は、原則として契約締結の日より | AO9: 6ヶ月 | AQ9: 後の応当日までとする。
B10: （１） | D10: 故 | E10: =入力元!L13 -> 0 | I10: 様の | K10: 相続 | P10: に関する手続き | BC10: 2000 | BD10: ←入力してください
C11: （書類の作成・交付申請受領及び申請書等の提出を含む）の一切 | AB11: 第１2条 （解除事由）
B12: （２） | C12: 前号の手続きの前提となる手続き | AC12: 乙 及び 丙 は，以下のいずれかの事由が生じたときは，本契約を解除することができる。 | BC12: 行政書士業務
B13: （３） | C13: 前号の手続きに必要となる付属手続き | AC13: （１） | AD13: 甲 が 乙 及び 丙 に対し，虚偽の事実を申告し，または，事実を正当な理由なく告げなかったため， 乙 | BC13: 相続
AD14: 及び 丙 の事件処理に著しい不都合が生じたとき | BC14: 遺言書の作成
A15: 第２条 （司法書士 委任業務の表示） | AC15: （２） | AD15: 甲 と 乙 及び 丙 との信頼関係が破綻したとき | BC15: ※その他業務はこちらに上書き
B16: 甲 は 丙 に本件業務に関する | I16: 不動産登記業務 | O16: を委任し、 丙 はこれを受任する。 | AC16: （３） | AD16: 契約期間が応当日を超過したとき
A18: 第３条 （協議の義務） | AB18: 第１3条 （甲の事由による業務の終了） | BC18: 司法書士業務
B19: 本件業務の処理に関連して，前項各号以外の手続きが必要となったときは，別途， 甲 ・ 乙 ・ 丙 の協議 | AC19: 乙 及び 丙 は，以下のいずれかの事由が生じたときであっても， 甲 に対し，報酬を請求することができる。 | BC19: 不動産登記業務
B20: で決定するものとする。 | AC20: （１） | AD20: 甲 が 乙 及び 丙 の責任でない事情により 乙 または 丙 を解任したとき | BC20: 相続放棄
AC21: （２） | AD21: 甲 が 乙 及び 丙 の同意なく依頼事件を終わらせたとき | BC21: ※その他業務はこちらに上書き
A22: 第４条 （法令の遵守） | AC22: （３） | AD22: 甲 が故意又は重大な過失により 乙 及び 丙 の事件処理を不能にしたとき
B23: 乙 及び 丙 は，各自行政書士法・司法書士法及び所属行政書士会・司法書士会の会則に従い，誠実に
B24: 委任事務の処理にあたるものとする。 | AB24: 第１4条 （秘密保持）
AC25: 乙 及び 丙 は，業務上知り得た秘密を正当な理由なく他に漏らし，又は利用してはならないこととする。
A26: 第５条 （復代理人の選任） | AC26: 業務が終了した後も，同様とする。
B27: 乙 及び 丙 は，他の行政書士及び司法書士と共同して本件業務を処理し，あるいは弁護士，弁理士，
B28: 公認会計士，税理士，土地家屋調査士，社会保険労務士，不動産鑑定士等に関連する業務を処理又は | AB28: 第１5条 （反社会的勢力の排除）
B29: 補助させることができる。 | AC29: 裏面に記載のとおりとする。
A31: ２ | B31: 本件業務の処理に関連して，復代理人の選任が必要となったときは， 甲 はあらかじめ承諾するものとす | AB31: 上記契約の成立を証するため，本書２通を作成し， 甲 及び 乙 及び 丙 が署名・捺印のうえ， 甲 と 乙丙 が各１通
B32: る。 | AB32: を保有する。
A34: 第６条 （報告の義務）
B35: 乙 及び 丙 は，本件業務に関し， 甲 に報告義務を負うものとする。 | AB35: 令和 年 月 日
AB36: 甲 | AD36: 住所 | AF36: =入力元!L6 -> 0
A37: 第７条 （手続きの決定） | AF37: =入力元!L7 -> 0
B38: 甲 と 乙 及び 丙 は本件業務について十分協議のうえ，具体的手続を決定するものとする。
AD39: 氏名
A40: 第８条 （資料の提示）
B41: 甲 は 乙 及び 丙 に対して，本件業務の処理に必要となる情報や資料（以下「資料等」 という）の提供を | AR41: お認印
B42: 求められた場合，速やかに資料等を提示し，本件業務の処理に関し積極的かつ全面的に 乙 及び 丙 に
B43: 協力し， 乙 及び 丙 は誠実に本件業務を処理するものとする。 | AB43: 乙 | AD43: 神奈川県横浜市西区高島２丁目１４－１７ クレアトール横浜ビル５階
AD44: 行政書士法人オーシャン 代表社員 黒田 美菜子
...

Sheet 契約書★財産調査あり（行単独）
A1: 委 任 契 約 書 | BC1: =TODAY() -> 46225
AB2: 第９条 （報酬） | BC2: 外字
AC3: 甲 が 乙 に対して支払う報酬は、 | AJ3: 別紙報酬額基準表 | AO3: の通りとする。なお,乙は,報酬とは別に,印紙代, | BC3: =入力元!$AJ$9&入力元!$AJ$14&IF(OR(入力元!$AC$9="有",入力元!$AC$14="有"),"に外字あり","")
AC4: 切手代，交付手数料，予納金，交通費，通信費等の実費等（以下「実費」という）について実額を受け取ることが
AC5: できる。また，実費について乙が立て替えることのできる金額の総額は 金５万円 を上限とする。
A6: 後記依頼者を 甲 とし，後記行政書士を 乙として，次のとおり契約する。 | BC6: 別紙報酬額基準表
A7: 第１条 （行政書士 委任業務の表示） | AC7: ２ | AD7: 報酬基準に記載のない業務は， 甲 及び 乙 協議の上，報酬額を決定するものとする。 | BC7: 2000 | BD7: ←入力してください
B8: 甲 は 乙 に下記業務（以下「本件業務」という）を委任し， 乙 はこれを受任する。
B9: （１） | D9: 故 | E9: =入力元!L13 -> 0 | I9: 様の | K9: 相続 | P9: に関する手続き | AB9: 第１０条 （委任業務の終了） | BC9: 行政書士業務
C10: （書類の作成・交付申請受領及び申請書等の提出を含む）の一切 | AC10: 乙 は，前条に定める実費及び未払いの報酬があるときは，その支払いを確認したときに，本件業務に関する | BC10: 相続
B11: （２） | C11: 前号の手続きの前提となる手続き | AC11: 書類を 甲 に引き渡すものとする。 | BC11: 遺言書の作成
B12: （３） | C12: 前号の手続きに必要となる付属手続き | BC12: ※その他業務はこちらに上書き
AB13: 第1１条 （契約期間）
A14: 第２条 （協議の義務） | AC14: 本契約の契約期間は、原則として契約締結の日より | AO14: 8ヶ月 | AQ14: 後の応当日までとする。
B15: 本件業務の処理に関連して，前項各号以外の手続きが必要となったときは，別途， 甲 ・ 乙 の協議で決
B16: 定するものとする。 | AB16: 第１２条 （解除事由）
AC17: 乙 は，以下のいずれかの事由が生じたときは，本契約を解除することができる。
A18: 第３条 （法令の遵守） | AC18: （１） | AD18: 甲 が 乙 に対し，虚偽の事実を申告し，または，事実を正当な理由なく告げなかったため， 乙の事件処理 | BC18: 司法書士業務
B19: 乙 は，行政書士法及び所属行政書士会の会則に従い，誠実に委任事務の処理にあたるものとする。 | AD19: に著しい不都合が生じたとき | BC19: 不動産登記業務
AC20: （２） | AD20: 甲 と 乙 との信頼関係が破綻したとき | BC20: 相続放棄
AC21: （３） | AD21: 契約期間が応当日を超過したとき | BC21: ※その他業務はこちらに上書き
A22: 第４条 （復代理人の選任）
B23: 乙 は，他の行政書士及び司法書士と共同して本件業務を処理し，あるいは弁護士，弁理士，公認会計 | AB23: 第１３条 （甲の事由による業務の終了）
B24: 士，税理士，土地家屋調査士，社会保険労務士，不動産鑑定士等に関連する業務を処理又は補助させ | AC24: 乙 は，以下のいずれかの事由が生じたときであっても， 甲 に対し，報酬を請求することができる。
B25: ることができる。 | AC25: （１） | AD25: 甲 が 乙 の責任でない事情により 乙 を解任したとき
AC26: （２） | AD26: 甲 が 乙 の同意なく依頼事件を終わらせたとき
A27: ２ | B27: 本件業務の処理に関連して，復代理人の選任が必要となったときは， 甲 はあらかじめ承諾するものとす | AC27: （３） | AD27: 甲 が故意又は重大な過失により 乙 の事件処理を不能にしたとき
B28: る。
AB29: 第１４条 （秘密保持）
A30: 第５条 （報告の義務） | AC30: 乙 は，業務上知り得た秘密を正当な理由なく他に漏らし，又は利用してはならないこととする。業務が終了
B31: 乙 は，本件業務に関し， 甲 に報告義務を負うものとする。 | AC31: した後も，同様とする。
A33: 第６条 （手続きの決定） | AB33: 第１５条 （反社会的勢力の排除）
B34: 甲 と 乙 は本件業務について十分協議のうえ，具体的手続を決定するものとする。 | AC34: 裏面に記載のとおりとする。
A36: 第７条 （財産調査及び遺言書の確認） | AB36: 上記契約の成立を証するため，本書２通を作成し， 甲 及び 乙 が署名・捺印のうえ，甲と乙が各１通を保有する。
B37: 甲 及び 乙 は，本件業務に関する財産調査において， 甲 から委任をうけた範囲内で行うものとし，その
B38: 財産調査の開始によって，金融・証券その他各種口座が凍結されることに 甲 はあらかじめ承諾するものと
B39: する。また，委任の範囲を超えた財産が発見されたとしても， 乙 は，その責に任じないものとする。 | AB39: 令和 年 月 日
A41: 2 | B41: 甲 及び 乙 は，本件業務に関する遺言書の有無の調査につき，甲から委任をうけた場合のみ行うものと
B42: する。乙が遺言書の調査の委任を受けなかったとき，或いは，通常なすべき調査によって遺言書の
B43: 確認ができなかったときにおいて，遺産分割協議後に遺言書が発見された場合,また,甲以外の第 | AB43: 甲 | AD43: 住所 | AF43: =入力元!L6 -> 0
...

Sheet 契約書(遺言など単独)★財産調査なし 
A1: 委 任 契 約 書 | BC1: =TODAY() -> 46225
AB3: 第８条 （契約期間）
AC4: 本契約の契約期間は、原則として本契約締結の日より6ヶ月後の応当日までとする。
A6: 後記依頼者を 甲 とし，後記行政書士を 乙 として，次の通り契約する。 | AB6: 第９条 （解除事由） | BC6: 外字
A7: 第１条 （委任業務の表示） | AC7: 乙 は，以下のいずれかの事由が生じたときは，本契約を解除することができる。 | BC7: =入力元!$AJ$9&入力元!$AJ$14&IF(OR(入力元!$AC$9="有",入力元!$AC$14="有"),"に外字あり","")
B8: 甲 は 乙 に下記業務（以下「本件業務」という）を委任し， 乙 はこれを受任する。 | AC8: （１） | AD8: 甲 が 乙 に対し，虚偽の事実を申告し，または，事実を正当な理由なく告げなかったため， 乙 の事件処
B9: （１） | D9: =入力元!L8 -> 0 | H9: 様の | J9: 遺言書の作成 | O9: に関する手続き | AD9: 理に著しい不都合が生じたとき
C10: （書類の作成・交付申請受領及び申請書等の提出を含む）の一切 | AC10: （２） | AD10: 甲 と 乙 との信頼関係が破綻したとき | BC10: 行政書士 | BD10: ←どっちか選ぶ
B11: （２） | C11: 前号の手続きの前提となる手続き | AC11: （３） | AD11: 契約期間が応当日を超過したとき
B12: （３） | C12: 前号の手続きに必要となる付属手続き
AB13: 第１０条 （甲の事由による業務の終了）
A14: 第２条 （法令の遵守） | AC14: 乙は，以下のいずれかの事由が生じたときであっても， 甲 に対し，報酬を請求することができる。
B15: 乙 は，各自行政書士法及び所属行政書士会の会則に従い，誠実に委任事務の処理にあたるものとする。 | AC15: （１） | AD15: 甲 が 乙 の責任でない事情により 乙 を解任したとき | BC15: 別紙報酬額基準表
AC16: （２） | AD16: 甲 が 乙 の同意なく依頼業務を終わらせたとき | BC16: 4000 | BD16: ←入力してください
A17: 第３条 （協議・報告義務） | AC17: （３） | AD17: 甲 が故意又は重大な過失により 乙 の業務処理を不能にしたとき
B18: 甲 と 乙 は本件業務について十分協議のうえ，具体的手続を決定する。 | BC18: ↓編集不可
AB19: 第１１条 （秘密保持） | BC19: 乙 は，行政書士法及び所属行政書士会の会則に従い，誠実に委任事務の処理にあたるものとする。
A20: ２ | B20: 乙 は，本件業務に関し， 甲 に報告義務を負うものとする。 | AC20: 乙 は，業務上知り得た秘密を正当な理由なく他に漏らし，又は利用してはならないこととする。業務が終了し | BC20: 乙 は，司法書士法及び所属司法書士会の会則に従い，誠実に委任事務の処理にあたるものとする。
AC21: た後も，同様とする。
A22: 第４条 （資料の提示） | BC22: 乙は他の行政書士と共同して本件業務を処理し，あるいは司法書士、弁護士，弁理士，公認会計士，税
B23: 甲 は 乙 に対して，本件業務の処理に必要となる情報や資料（以下「資料等」 という）の提供を求められ | AB23: 第１２条 （反社会勢力の排除） | BC23: 理士，土地家屋調査士，社会保険労務士，不動産鑑定士等に関連する業務を処理又は補助させることが
B24: た場合，速やかに資料等を提示し，本件業務の処理に関し積極的かつ全面的に 乙 に協力し， 乙 は誠実 | AC24: 裏面に記載のとおりとする。 | BC24: できる。
B25: に本件業務を処理するものとする。
AB26: 上記契約の成立を証するため，本書２通を作成し，甲及び乙が署名・捺印の上，各１通を保有する。
A27: 第５条 （復代理人の選任） | BC27: 乙は他の司法書士と共同して本件業務を処理し，あるいは行政書士、弁護士，弁理士，公認会計士，税
B28: 乙 及び 丙 は，他の行政書士及び司法書士と共同して本件業務を処理し，あるいは弁護士，弁理士， | BC28: 理士，土地家屋調査士，社会保険労務士，不動産鑑定士等に関連する業務を処理又は補助させることが
B29: 公認会計士，税理士，土地家屋調査士，社会保険労務士，不動産鑑定士等に関連する業務を処理又は | AB29: 令和 年 月 日 | BC29: できる。
B30: 補助させることができる。
AB31: 甲 | AD31: 住所 | AF31: =入力元!$L$6 -> 0 | BC31: 神奈川県横浜市西区高島２丁目１４－１７ クレアトール横浜ビル５階
A32: ２ | B32: 本件業務の処理に関連して，復代理人の選任が必要となったときは， 甲 はあらかじめ承諾するものとす | AF32: =入力元!$L$7 -> 0 | BC32: 行政書士法人オーシャン 代表社員 黒田 美菜子 | BO32: 神奈川県行政書士会所属
B33: る。 | BC33: 司法書士法人オーシャン 代表社員 山田 哲 | BO33: 神奈川県司法書士会所属
AD34: 氏名
A35: 第６条 （報酬）
B36: 甲 が 乙 に対して支払う報酬は、 | J36: 別紙報酬額基準表 | O36: =IF(J36="別紙報酬額基準表","の通りとする。","円（税込）とする。") -> の通りとする。
B37: なお， 乙 は，報酬とは別に，印紙代，切手代，交付手数料，予納金，交通費， 通信費等の実費等（以下 | AR37: お認印
B38: 「実費」という）について実額を受け取ることができる。また，実費について乙が立て替えることのできる金額
B39: の総額は 金５万円 を上限とする。 | AB39: 乙 | AD39: 神奈川県横浜市西区高島２丁目１４－１７ クレアトール横浜ビル５階
AD40: =IF($BC$10="行政書士",BC32,BC33) -> 行政書士法人オーシャン 代表社員 黒田 美菜子
A41: ２ | B41: 報酬額基準表に記載のない業務は， 甲 及び 乙 協議の上，報酬額を決定するものとする。 | AD41: =IF($BC$10="行政書士",BO32,BO33) -> 神奈川県行政書士会所属
A43: 第７条 （委任業務の終了）
...

Sheet 委任状  (法定相続情報証明）
AA2: 外字
AA3: =入力元!$AJ$9&入力元!$AJ$14&IF(OR(入力元!$AC$9="有",入力元!$AC$14="有"),"に外字あり","")
B4: 委 任 状
AA6: 行政書士法人オーシャン 代表社員 黒田 美菜子 | AF6: 神奈川県横浜市西区高島２丁目１４番１７号 クレアトール横浜ビル５階
AA7: 司法書士法人オーシャン 代表社員 山田 哲 | AF7: 神奈川県横浜市西区高島２丁目１３－２ 横浜駅前共同ビル
B10: （代理人） | E10: 住 所 | G10: =VLOOKUP(G11,AA6:AM8,6,FALSE) -> 神奈川県横浜市西区高島２丁目１４番１７号 クレアトール横浜ビル５階
E11: 氏 名 | G11: 行政書士法人オーシャン 代表社員 黒田 美菜子
B13: 私は，上記の者に対し，以下の被相続人の相続に係る次の権限を委任する。 １ 法定相続情報一覧図を作成すること ２ 法定相続情報一覧図の保管及び一覧図の写しの交付の申出をすること （希望する法定相続情報一覧図の写しの交付通数 通） ３ 法定相続情報一覧図の写し及び返却される添付書面を受領すること ４ 上記１から３までのほか，法定相続情報一覧図の保管及び一覧図の写しの交付の 申出に関して必要な一切の権限
C15: 被相続人の最後の住所（又は本籍）
C17: 被相続人の氏名
D18: =入力元!L13 -> 0
C19: 死亡年月日
C24: 令和 | E24: 年 月 日
E26: （委任者）
E27: 住 所 | G27: =入力元!L6 -> 0
G28: =入力元!L7 -> 0
E30: 氏 名

Sheet 委任状（行・司連名）
A1: =入力元!L4 -> R | B1: =入力元!N4 -> 8 | C1: - | D1: =入力元!R4 -> Y | E1: =入力元!T4 -> 0
A2: 委 任 状
Z3: 外字
Z4: =入力元!$AJ$9&入力元!$AJ$14&IF(OR(入力元!$AC$9="有",入力元!$AC$14="有"),"に外字あり","")
Q5: 令和 | S5: 年 月 日
L7: 委任者 | N7: （相続人） | V7: =IF(N7="（相続人","法定代理人)","") | Z7: 行政書士法人オーシャン 代表社員 黒田 美菜子
L8: 住所 | N8: =入力元!L6 -> 0 | Z8: 司法書士法人オーシャン 代表社員 山田 哲
N9: =入力元!L7 -> 0 | Z9: 行政書士法人オーシャン 代表社員 黒田 美菜子 司法書士法人オーシャン 代表社員 山田 哲
L10: 氏名
X11: 印
M12: 生年月日 | N12: =入力元!L9 -> 昭和 | P12: =入力元!P9 -> 0 | Q12: 年 | R12: =入力元!T9 -> 0 | S12: 月 | T12: =入力元!X9 -> 0 | U12: 日
B14: 私は、被相続人 | F14: =入力元!L13 -> 0 | J14: （ | K14: =入力元!L14 -> 令和 | L14: =入力元!P14 -> 0 | M14: 年 | N14: =入力元!T14 -> 0 | O14: 月 | P14: =入力元!X14 -> 0 | Q14: 日死亡）の相続手続きに関し、
B15: 次の者を代理人と定め，下記の事項に関する権限を委任します。
C17: 代 理 人
C18: 本店住所 | G18: 横浜市西区高島二丁目１４番１７号 クレアトール横浜ビル５階
C19: 従たる事務所 | G19: 横浜市西区高島２丁目１３－２ 横浜駅前共同ビル
G20: 藤沢市鵠沼石上一丁目1番１号 江ノ電第２ビル4階
E22: 氏名 | G22: 行政書士法人オーシャン 代表社員 黒田 美菜子
C25: 本店住所 | G25: 横浜市西区高島２丁目１３－２ 横浜駅前共同ビル
C26: 従たる事務所 | G26: 横浜市西区高島二丁目１４番１７号 クレアトール横浜ビル５階
E28: 氏名 | G28: 司法書士法人オーシャン 代表社員 山田 哲
A31: 記
B33: １ | C33: 相続人、及び相続財産、負債の確定に必要な書類を取得する一切の権限
C34: （１） | D34: 戸籍、除籍、改製原戸籍、住民票、住民票除票、戸籍の附票、不在籍証明、不在住証明書の取
D35: 得に関する権限（但し，世帯主・続柄・本籍・筆頭者等の省略がないもの）
C36: （２） | D36: 固定資産名寄帳の取得に関する権限
C37: （３） | D37: 固定資産評価証明、固定資産公課証明書の取得に関する権限
C38: （４） | D38: 貯金及び国債の残高証明書の請求と受領・現存調査・貯金入出金照会・証拠書写しの請求と受
D39: 領（別紙 有/無）
C40: （５） | D40: 預金、投資信託取引、出資金及び保有株式の現存調査及び残高証明書、取引明細書、評価証明書の
D41: 取得に関する権限
C42: （６） | D42: 生命保険契約等の現存調査及びそれに関する書類の取得に関する権限
C43: （７） | D43: 被相続人の公正証書遺言の存否を確認する権限
C44: （８） | D44: その他，財産確定に必要な書類の取得に関する権限
C45: （９） | D45: 登録済加入者情報に関する開示請求及びその情報を記載した「登録済加入者情報通知書」の
D46: 受領等に係る一切の事務に関する権限
B48: 2 | C48: 本委任状に掲げる行為の復代理人選定に関する権限
B50: 3 | C50: 本委任状に掲げる行為に付帯する一切の権限
B52: 4 | C52: 本委任状の原本還付を請求する権限

Sheet 委任状（行・司連連名）預金解約あり
A1: =入力元!L4 -> R | B1: =入力元!N4 -> 8 | C1: - | D1: =入力元!R4 -> Y | E1: =入力元!T4 -> 0
A2: 委 任 状
Z3: 外字
Z4: =入力元!$AJ$9&入力元!$AJ$14&IF(OR(入力元!$AC$9="有",入力元!$AC$14="有"),"に外字あり","")
Q5: 令和 | S5: 年 月 日
L7: 委任者 | N7: （相続人） | V7: =IF(N7="（相続人","法定代理人)","") | Z7: 行政書士法人オーシャン 代表社員 黒田 美菜子
L8: 住所 | N8: =入力元!L6 -> 0 | Z8: 司法書士法人オーシャン 代表社員 山田 哲
N9: =入力元!L7 -> 0 | Z9: 行政書士法人オーシャン 代表社員 黒田 美菜子 司法書士法人オーシャン 代表社員 山田 哲
L10: 氏名
X11: 印
M12: 生年月日 | N12: =入力元!L9 -> 昭和 | P12: =入力元!P9 -> 0 | Q12: 年 | R12: =入力元!T9 -> 0 | S12: 月 | T12: =入力元!X9 -> 0 | U12: 日
B14: 私は、被相続人 | F14: =入力元!L13 -> 0 | J14: （ | K14: =入力元!L14 -> 令和 | L14: =入力元!P14 -> 0 | M14: 年 | N14: =入力元!T14 -> 0 | O14: 月 | P14: =入力元!X14 -> 0 | Q14: 日死亡）の相続手続きに関し、
B15: 次の者を代理人と定め，下記の事項に関する権限を委任します。
C17: 代 理 人
C18: 本店住所 | G18: 横浜市西区高島二丁目１４番１７号 クレアトール横浜ビル５階
C19: 従たる事務所 | G19: 横浜市西区高島２丁目１３－２ 横浜駅前共同ビル
G20: 藤沢市鵠沼石上一丁目1番１号 江ノ電第２ビル4階
E22: 氏名 | G22: 行政書士法人オーシャン 代表社員 黒田 美菜子
C25: 本店住所 | G25: 横浜市西区高島２丁目１３－２ 横浜駅前共同ビル
C26: 従たる事務所 | G26: 横浜市西区高島二丁目１４番１７号 クレアトール横浜ビル５階
E28: 氏名 | G28: 司法書士法人オーシャン 代表社員 山田 哲
A31: 記
B33: １ | C33: 相続人、及び相続財産、負債の確定に必要な書類を取得する一切の権限
C34: （１） | D34: 戸籍、除籍、改製原戸籍、住民票、住民票除票、戸籍の附票、不在籍証明、不在住証明書の取
D35: 得に関する権限（但し，世帯主・続柄・本籍・筆頭者等の省略がないもの）
C36: （２） | D36: 固定資産名寄帳の取得に関する権限
C37: （３） | D37: 固定資産評価証明、固定資産公課証明書の取得に関する権限
C38: （４） | D38: 貯金及び国債の残高証明書の請求と受領・現存調査・貯金入出金照会・証拠書写しの請求と受
D39: 領（別紙 有/無）
C40: （５） | D40: 預金、投資信託取引、出資金及び保有株式の現存調査及び残高証明書、取引明細書、評価証明書の
D41: 取得に関する権限
C42: （６） | D42: 生命保険契約等の現存調査及びそれに関する書類の取得に関する権限
C43: （７） | D43: 被相続人の公正証書遺言の存否を確認する権限
C44: （８） | D44: その他，財産確定に必要な書類の取得に関する権限
C45: （９） | D45: 登録済加入者情報に関する開示請求及びその情報を記載した「登録済加入者情報通知書」の
D46: 受領等に係る一切の事務に関する権限
B48: ２ | C48: 相続財産（預貯金、投資信託、出資金、公共債等の債権、株式、生命保険契約等、上記被相続人名義の
C49: 一切の財産を含む）の名義変更及び解約と解約金の受領に関する一切の権限
B51: ３ | C51: 貯金等の相続手続きに関する書類の提出、証書等の受領、返送書類の受領、連絡
B53: ４ | C53: 前記各号に掲げる行為の復代理人選定に関する権限
...

Sheet 委任状（行遺産承継解約）
B2: =[3]入力元!L4 -> R | C2: =入力元!N4 -> 8 | D2: - | E2: =[3]入力元!R4 -> Y | F2: =入力元!T4 -> 0
B3: 委 任 状
AB4: 外字
AB5: =[3]入力元!$AJ$9&[3]入力元!$AJ$14&IF(OR([3]入力元!$AC$9="有",[3]入力元!$AC$14="有"),"に外字あり","")
R6: 令和 | T6: 年 月 日
M8: 委任者 | O8: （相続人） | W8: =IF(O8="（相続人","法定代理人)","") | AB8: 行政書士法人オーシャン 代表社員 黒田 美菜子
M9: 住所 | O9: =入力元!L6 -> 0 | AB9: 司法書士法人オーシャン 代表社員 山田 哲
O10: =入力元!L7 -> 0 | AB10: 行政書士法人オーシャン 代表社員 黒田 美菜子 司法書士法人オーシャン 代表社員 山田 哲
M11: 氏名
Y12: 印
N13: 生年月日 | O13: 昭和 | Q13: =入力元!P9 -> 0 | R13: 年 | S13: =入力元!T9 -> 0 | T13: 月 | U13: =入力元!X9 -> 0 | V13: 日
C15: 私は、被相続人 | G15: =入力元!L13 -> 0 | K15: （ | L15: =[3]入力元!L14 -> 令和 | M15: =入力元!P14 -> 0 | N15: 年 | O15: =入力元!T14 -> 0 | P15: 月 | Q15: =入力元!X14 -> 0 | R15: 日死亡）の相続手続きに関し、
C16: 次の者を代理人と定め，行政書士法第1条の2、同法第1条の3第1項、同法第13条の6第1号及び同法施
C17: 行規則第12条の2第4号に基づき下記の事項に関する権限を委任します。
D19: 代 理 人
D20: 本店住所 | H20: 横浜市西区高島二丁目１４番１７号 クレアトール横浜ビル５階
D21: 従たる事務所 | H21: 横浜市西区高島２丁目１３－２ 横浜駅前共同ビル
H22: 藤沢市鵠沼石上一丁目1番１号 江ノ電第２ビル4階
F24: 氏名 | H24: 行政書士法人オーシャン 代表社員 黒田 美菜子
B28: 記
C30: １ | D30: 金融機関、証券会社、保険会社等に対する、現存照会または残高証明・取引明細書の請求及び受領、
D31: 各種書類または証書類の提出および受領、預貯金の解約および解約金の受領、
D32: 貸金庫取引の解約並びに保管物の回収、株式・有価証券等寄託物件の返還および
D33: 売却または相続移管並びに受渡、払戻金・満期金・保険金・給付金・売却代金等の請求並びに受領、
D34: 連絡、照会、その他預貯金・生命保険・株式・有価証券類の相続手続
C36: ２ | D36: 登録済加入者情報に関する開示請求及びその情報を記載した「登録済加入者情報通知書」の
D37: 受領等に係る一切の事務に関する権限
C39: ３ | D39: 預貯金、有価証券等金融資産について下記信託口口座に解約の手続きにより直接入金、
D40: 又は他の財産管理口座より入金し信託すること、
D41: 又は行政書士法人オーシャンの財産管理口座に直接入金し管理すること。
B43: 記
D44: 東京都千代田区大手町2-2-1
D45: ミトラ信託株式会社 代表取締役 今中 弘明
D46: 信託口座）楽天銀行 第三営業支店（253）普通 7591563
D47: ミトラ信託株式会社 行政書士法人オーシャン信託口
C49: ４ | D49: 貯金等の相続手続きに関する書類の提出、証書等の受領、返送書類の受領、連絡
C51: ５ | D51: 前記各号に掲げる行為の復代理人選定に関する権限
C53: ６ | D53: 前各項に付帯する一切の権限
C55: ７ | D55: 本委任状の原本還付を請求する権限

Sheet 委任状（行・司連名）登記のみ
A1: =入力元!L4 -> R | B1: =入力元!N4 -> 8 | C1: - | D1: =入力元!R4 -> Y | E1: =入力元!T4 -> 0
A2: 委 任 状
Z3: 外字
Z4: =入力元!$AJ$9&入力元!$AJ$14&IF(OR(入力元!$AC$9="有",入力元!$AC$14="有"),"に外字あり","")
Q5: 令和 | S5: 年 月 日
L7: 委任者 | N7: （相続人） | V7: =IF(N7="（相続人","法定代理人)","") | Z7: 行政書士法人オーシャン 代表社員 黒田 美菜子
L8: 住所 | N8: =入力元!L6 -> 0 | Z8: 司法書士法人オーシャン 代表社員 山田 哲
N9: =入力元!L7 -> 0 | Z9: 行政書士法人オーシャン 代表社員 黒田 美菜子 司法書士法人オーシャン 代表社員 山田 哲
L10: 氏名
X11: 印
M12: 生年月日 | N12: =入力元!L9 -> 昭和 | P12: =入力元!P9 -> 0 | Q12: 年 | R12: =入力元!T9 -> 0 | S12: 月 | T12: =入力元!X9 -> 0 | U12: 日
B14: 私は、被相続人 | F14: =入力元!L13 -> 0 | J14: （ | K14: =入力元!L14 -> 令和 | L14: =入力元!P14 -> 0 | M14: 年 | N14: =入力元!T14 -> 0 | O14: 月 | P14: =入力元!X14 -> 0 | Q14: 日死亡）の相続手続きに関し、
B15: 次の者を代理人と定め，下記の事項に関する権限を委任します。
C17: 代 理 人
C18: 本店住所 | G18: 横浜市西区高島二丁目１４番１７号 クレアトール横浜ビル５階
C19: 従たる事務所 | G19: 横浜市西区高島２丁目１３－２ 横浜駅前共同ビル
E21: 氏名 | G21: 行政書士法人オーシャン 代表社員 黒田 美菜子
C24: 本店住所 | G24: 横浜市西区高島２丁目１３－２ 横浜駅前共同ビル
C25: 従たる事務所 | G25: 横浜市西区高島二丁目１４番１７号 クレアトール横浜ビル５階
E27: 氏名 | G27: 司法書士法人オーシャン 代表社員 山田 哲
A30: 記
B32: １ | C32: 相続人、及び相続財産、負債の確定に必要な書類を取得する一切の権限
C33: （１） | D33: 戸籍、除籍、改製原戸籍、住民票、住民票除票、戸籍の附票、不在籍証明、不在住証明書の取
D34: 得に関する権限（但し，世帯主・続柄・本籍・筆頭者等の省略がないもの）
C35: （２） | D35: 固定資産名寄帳の取得に関する権限
C36: （３） | D36: 固定資産評価証明、固定資産公課証明書の取得に関する権限
C37: （4） | D37: その他，財産確定に必要な書類の取得に関する権限
B39: 2 | C39: 本委任状に掲げる行為の復代理人選定に関する権限
B41: 3 | C41: 本委任状に掲げる行為に付帯する一切の権限
B43: 4 | C43: 本委任状の原本還付を請求する権限

Sheet 委任状（行のみ）相続
A1: =入力元!L4 -> R | B1: =入力元!N4 -> 8 | C1: - | D1: =入力元!R4 -> Y | E1: =入力元!T4 -> 0
A2: 委 任 状
Z3: 外字
Z4: =入力元!$AJ$9&入力元!$AJ$14&IF(OR(入力元!$AC$9="有",入力元!$AC$14="有"),"に外字あり","")
Q5: 令和 | S5: 年 月 日
L7: 委任者 | N7: （相続人） | V7: =IF(N7="（相続人","法定代理人)","") | Z7: 行政書士法人オーシャン 代表社員 黒田 美菜子
L8: 住所 | N8: =入力元!L6 -> 0 | Z8: 司法書士法人オーシャン 代表社員 山田 哲
N9: =入力元!L7 -> 0 | Z9: 行政書士法人オーシャン 代表社員 黒田 美菜子 司法書士法人オーシャン 代表社員 山田 哲
L10: 氏名
X11: 印
M12: 生年月日 | N12: =入力元!L9 -> 昭和 | P12: =入力元!P9 -> 0 | Q12: 年 | R12: =入力元!T9 -> 0 | S12: 月 | T12: =入力元!X9 -> 0 | U12: 日
B14: 私は、被相続人 | F14: =入力元!L13 -> 0 | J14: （ | K14: =入力元!L14 -> 令和 | L14: =入力元!P14 -> 0 | M14: 年 | N14: =入力元!T14 -> 0 | O14: 月 | P14: =入力元!X14 -> 0 | Q14: 日死亡）の相続手続きに関し、
B15: 次の者を代理人と定め，下記の事項に関する権限を委任します。
C17: 代 理 人
C18: 本店住所 | G18: 横浜市西区高島二丁目１４番１７号 クレアトール横浜ビル５階
C19: 従たる事務所 | G19: 横浜市西区高島２丁目１３－２ 横浜駅前共同ビル
E21: 氏名 | G21: 行政書士法人オーシャン 代表社員 黒田 美菜子
A24: 記
B26: １ | C26: 相続人、及び相続財産、負債の確定に必要な書類を取得する一切の権限
C27: （１） | D27: 戸籍、除籍、改製原戸籍、住民票、住民票除票、戸籍の附票、不在籍証明、不在住証明書の取
D28: 得に関する権限（但し，世帯主・続柄・本籍・筆頭者等の省略がないもの）
B30: 2 | C30: 本委任状に掲げる行為の復代理人選定に関する権限
B32: 3 | C32: 本委任状に掲げる行為に付帯する一切の権限
B34: 4 | C34: 本委任状の原本還付を請求する権限

Sheet 委任状 (司のみ)相続登記 
A1: =入力元!L4 -> R | B1: =入力元!N4 -> 8 | C1: - | D1: =入力元!R4 -> Y | E1: =入力元!T4 -> 0
A2: 委 任 状 | Z2: 外字
Z3: =入力元!$AJ$9&入力元!$AJ$14&IF(OR(入力元!$AC$9="有",入力元!$AC$14="有"),"に外字あり","")
Q5: 令和 | S5: 年 月 日
Z6: 行政書士法人オーシャン 代表社員 黒田 美菜子
L7: 委任者 | N7: （相続人） | V7: =IF(N7="（相続人","法定代理人)","") | Z7: 司法書士法人オーシャン 代表社員 山田 哲
L8: 住所 | N8: =入力元!L6 -> 0 | Z8: 行政書士法人オーシャン 代表社員 黒田 美菜子 司法書士法人オーシャン 代表社員 山田 哲
N9: =入力元!L7 -> 0
L10: 氏名
X11: 印
M12: 生年月日 | N12: =入力元!L9 -> 昭和 | P12: =入力元!P9 -> 0 | Q12: 年 | R12: =入力元!T9 -> 0 | S12: 月 | T12: =入力元!X9 -> 0 | U12: 日
B14: 私は、被相続人 | F14: =入力元!L13 -> 0 | J14: （ | K14: =入力元!L14 -> 令和 | L14: =入力元!P14 -> 0 | M14: 年 | N14: =入力元!T14 -> 0 | O14: 月 | P14: =入力元!X14 -> 0 | Q14: 日死亡）の相続手続きに関し、
B15: 次の者を代理人と定め，下記の事項に関する権限を委任します。
C17: 代 理 人
C18: 本店住所 | G18: 横浜市西区高島２丁目１３－２ 横浜駅前共同ビル
C19: 従たる事務所 | G19: 横浜市西区高島二丁目１４番１７号 クレアトール横浜ビル５階
E21: 氏名 | G21: 司法書士法人オーシャン 代表社員 山田 哲
A24: 記
B26: 1 | C26: 相続人、及び相続財産の確定に必要な書類を取得する一切の権限
C27: （１） | D27: 戸籍、除籍、改製原戸籍、住民票、住民票除票、戸籍の附票、不在籍証明、不在住証明書の取
D28: 得に関する権限（但し，世帯主・続柄・本籍・筆頭者等の省略がないもの）
C29: （２） | D29: 所得証明書，課税証明書の取得に関する権限
C30: （３） | D30: 固定資産名寄帳の取得に関する権限
C31: （４） | D31: 固定資産評価証明、固定資産公課証明書の取得に関する権限
B34: ２ | C34: 前記各号に掲げる行為の復代理人選定に関する権限
B37: ３ | C37: 前各項に付帯する一切の権限
B40: ４ | C40: 本委任状の原本還付を請求する権限

Sheet 委任状 (行)遺言
A1: =入力元!L4 -> R | B1: =入力元!N4 -> 8 | C1: - | D1: =入力元!R4 -> Y | E1: =入力元!T4 -> 0
A2: 委 任 状 | Z2: 外字
Z3: =入力元!$AJ$9&入力元!$AJ$14&IF(OR(入力元!$AC$9="有",入力元!$AC$14="有"),"に外字あり","")
Q5: 令和 | S5: 年 月 日
L7: 委任者 | V7: =IF(N7="（相続人","法定代理人)","")
L8: 住所 | N8: =入力元!L6 -> 0
N9: =入力元!L7 -> 0
L10: 氏名
X11: 印
M12: 生年月日 | P12: =入力元!P9 -> 0 | Q12: 年 | R12: =入力元!T9 -> 0 | S12: 月 | T12: =入力元!X9 -> 0 | U12: 日
B14: 私は、次の者を代理人と定め、下記の事項に関する権限を委任します。
C16: 代 理 人
C17: 本店住所 | G17: 横浜市西区高島２丁目１４－１７ クレアトール横浜ビル５階
C18: 従たる事務所 | G18: 横浜市西区高島２丁目１３－２ 横浜駅前共同ビル
E20: 氏名 | H20: 行政書士法人オーシャン | N20: 代表社員 | R20: 黒田 美菜子
A23: 記
B25: １ | C25: 私の遺言作成に関する一切の権限
B26: 0
B27: ２ | C27: 私の推定相続人及び推定相続財産確定に必要な書類を取得する一切の権限
B28: 0 | C28: （１） | D28: 戸籍、除籍、改製原戸籍、住民票、住民票除票、戸籍の附票、不在籍証明、不在住証明書
C29: 0 | D29: の取得に関する権限（但し，世帯主・続柄・本籍・筆頭者等の省略がないもの）
C30: （２） | D30: 固定資産名寄帳の取得に関する権限
B31: 0 | C31: （３） | D31: 固定資産評価証明、固定資産公課証明書の取得に関する権限
B32: 0 | C32: （４） | D32: 貯金及び国債の残高証明書の請求と受領・現存調査・貯金入出金照会・証拠書写しの請求
B33: 0 | C33: 0 | D33: と受領（別紙 有/無）
B34: 0 | C34: （５） | D34: 預金、投資信託取引及び保有株式の現存調査及び残高証明書、取引明細書、評価証明書
B35: 0 | C35: 0 | D35: の取得に関する権限
B36: 0 | C36: （６） | D36: 生命保険契約等の現存調査及びそれに関する書類の取得に関する権限
C37: （７） | D37: その他，財産確定に必要な書類の取得に関する権限
C38: （８） | D38: 登録済加入者情報に関する開示請求及びその情報を記載した
D39: 「登録済加入者情報通知書」の受領等に係る一切の事務に関する権限
B41: ３ | C41: 前記各号に掲げる行為の復代理人選定に関する権限
B42: 0
B43: ４ | C43: 前各項に付帯する一切の権限
B45: ５ | C45: 本委任状の原本還付を請求する権限
D46: =IFERROR(VLOOKUP($Z$4&#REF!,$Z$25:$AV$48,#REF!,0),"")
B47: =IFERROR(VLOOKUP($Z$4&#REF!,$Z$25:$AV$48,#REF!,0),"") | D47: =IFERROR(VLOOKUP($Z$4&#REF!,$Z$25:$AV$48,#REF!,0),"")
B48: =IFERROR(VLOOKUP($Z$4&#REF!,$Z$25:$AV$48,#REF!,0),"") | D48: =IFERROR(VLOOKUP($Z$4&#REF!,$Z$25:$AV$48,#REF!,0),"")

Sheet 委任状 (行司)贈与・信託
A1: =入力元!L4 -> R | B1: =入力元!N4 -> 8 | C1: - | D1: =入力元!R4 -> Y | E1: =入力元!T4 -> 0
A2: 委 任 状 | Z2: 外字
Z3: =入力元!$AJ$9&入力元!$AJ$14&IF(OR(入力元!$AC$9="有",入力元!$AC$14="有"),"に外字あり","")
Q5: 令和 | S5: 年 月 日
Z6: 行政書士法人オーシャン 代表社員 黒田 美菜子
L7: 委任者 | V7: =IF(N7="（相続人","法定代理人)","") | Z7: 司法書士法人オーシャン 代表社員 山田 哲
L8: 住所 | N8: =入力元!L6 -> 0 | Z8: 行政書士法人オーシャン 代表社員 黒田 美菜子 司法書士法人オーシャン 代表社員 山田 哲
N9: =入力元!L7 -> 0
L10: 氏名
X11: 印
M12: 生年月日 | N12: =入力元!L9 -> 昭和 | P12: =入力元!P9 -> 0 | Q12: 年 | R12: =入力元!T9 -> 0 | S12: 月 | T12: =入力元!X9 -> 0 | U12: 日
B14: 私は、次の者を代理人と定め、下記の事項に関する権限を委任します。
C16: 代 理 人
C17: 本店住所 | G17: 横浜市西区高島二丁目１４番１７号 クレアトール横浜ビル５階
C18: 従たる事務所 | G18: 横浜市西区高島２丁目１３－２ 横浜駅前共同ビル
E20: 氏名 | G20: 行政書士法人オーシャン 代表社員 黒田 美菜子
C22: 代 理 人
C23: 本店住所 | G23: 横浜市西区高島２丁目１３－２ 横浜駅前共同ビル
C24: 従たる事務所 | G24: 横浜市西区高島二丁目１４番１７号 クレアトール横浜ビル５階
E26: 氏名 | G26: 司法書士法人オーシャン 代表社員 山田 哲
A29: 記
B31: １ | C31: 私に関する下記書類を取得する一切の権限
B32: 0 | C32: （１） | D32: 戸籍、除籍、改製原戸籍、住民票、住民票除票、戸籍の附票、不在籍証明、不在住証明書の取
B33: 0 | C33: 0 | D33: 得に関する権限（但し，世帯主・続柄・本籍・筆頭者等の省略がないもの）
B34: 0 | C34: （２） | D34: 固定資産名寄帳の取得に関する権限
B35: 0 | C35: （３） | D35: 固定資産評価証明、固定資産公課証明書の取得に関する権限
B36: 0 | C36: （４） | D36: 貯金及び国債の残高証明書の請求と受領・現存調査・貯金入出金照会・証拠書写しの請求と受
B37: 0 | C37: 0 | D37: 領（別紙 有/無）
B38: 0 | C38: （５） | D38: 預金、投資信託取引及び保有株式の現存調査及び残高証明書、取引明細書、評価証明書の
B39: 0 | C39: 0 | D39: 取得に関する権限
B40: 0 | C40: （６） | D40: 生命保険契約等の現存調査及びそれに関する書類の取得に関する権限
B41: 0 | C41: （７） | D41: その他，財産確定に必要な書類の取得に関する権限
C42: （８） | D42: 登録済加入者情報に関する開示請求及びその情報を記載した
D43: 「登録済加入者情報通知書」の受領等に係る一切の事務に関する権限
B44: 0 | C44: 0 | D44: 0
B45: ２ | C45: 前記各号に掲げる行為の復代理人選定に関する権限
B46: 0 | C46: 0 | D46: 0
B47: ３ | C47: 前各項に付帯する一切の権限
B48: 0 | C48: 0 | D48: 0
B49: ４ | C49: 本委任状の原本還付を請求する権限

Sheet 委任状 (司)贈与・信託 
A1: =入力元!L4 -> R | B1: =入力元!N4 -> 8 | C1: - | D1: =入力元!R4 -> Y | E1: =入力元!T4 -> 0
A2: 委 任 状 | Z2: 外字
Z3: =入力元!$AJ$9&入力元!$AJ$14&IF(OR(入力元!$AC$9="有",入力元!$AC$14="有"),"に外字あり","")
Q5: 令和 | S5: 年 月 日
Z6: 行政書士法人オーシャン 代表社員 黒田 美菜子
L7: 委任者 | V7: =IF(N7="（相続人","法定代理人)","") | Z7: 司法書士法人オーシャン 代表社員 山田 哲
L8: 住所 | N8: =入力元!L6 -> 0 | Z8: 行政書士法人オーシャン 代表社員 黒田 美菜子 司法書士法人オーシャン 代表社員 山田 哲
N9: =入力元!L7 -> 0
L10: 氏名
X11: 印
M12: 生年月日 | N12: =入力元!L9 -> 昭和 | P12: =入力元!P9 -> 0 | Q12: 年 | R12: =入力元!T9 -> 0 | S12: 月 | T12: =入力元!X9 -> 0 | U12: 日
B14: 私は、次の者を代理人と定め、下記の事項に関する権限を委任します。
C16: 代 理 人
C17: 本店住所 | G17: 横浜市西区高島２丁目１３－２ 横浜駅前共同ビル
C18: 従たる事務所 | G18: 横浜市西区高島二丁目１４番１７号 クレアトール横浜ビル５階
E20: 氏名 | G20: 司法書士法人オーシャン 代表社員 山田 哲
A23: 記
B25: １ | C25: 私に関する下記書類を取得する一切の権限
B26: 0 | C26: （１） | D26: 戸籍、除籍、改製原戸籍、住民票、住民票除票、戸籍の附票、不在籍証明、不在住証明書の取
B27: 0 | C27: 0 | D27: 得に関する権限（但し，世帯主・続柄・本籍・筆頭者等の省略がないもの）
B28: 0 | C28: （２） | D28: 固定資産名寄帳の取得に関する権限
B29: 0 | C29: （３） | D29: 固定資産評価証明、固定資産公課証明書の取得に関する権限
B30: 0 | C30: （４） | D30: 貯金及び国債の残高証明書の請求と受領・現存調査・貯金入出金照会・証拠書写しの請求と受
B31: 0 | C31: 0 | D31: 領（別紙 有/無）
B32: 0 | C32: （５） | D32: 預金、投資信託取引及び保有株式の現存調査及び残高証明書、取引明細書、評価証明書の
B33: 0 | C33: 0 | D33: 取得に関する権限
B34: 0 | C34: （６） | D34: 生命保険契約等の現存調査及びそれに関する書類の取得に関する権限
B35: 0 | C35: （７） | D35: その他，財産確定に必要な書類の取得に関する権限
C36: （８） | D36: 登録済加入者情報に関する開示請求及びその情報を記載した
D37: 「登録済加入者情報通知書」の受領等に係る一切の事務に関する権限
B38: 0 | C38: 0 | D38: 0
B39: ２ | C39: 前記各号に掲げる行為の復代理人選定に関する権限
B40: 0 | C40: 0 | D40: 0
B41: ３ | C41: 前各項に付帯する一切の権限
B42: 0 | C42: 0 | D42: 0
B43: ４ | C43: 本委任状の原本還付を請求する権限

Sheet 委任状 (遺言検索のみ)
A1: =入力元!L4 -> R | B1: =入力元!N4 -> 8 | C1: - | D1: =入力元!R4 -> Y | E1: =入力元!T4 -> 0
A2: 委 任 状 | Z2: 外字
Z3: =入力元!$AJ$9&入力元!$AJ$14&IF(OR(入力元!$AC$9="有",入力元!$AC$14="有"),"に外字あり","")
Q5: 令和 | S5: 年 月 日
L7: 委任者 | N7: （相続人） | V7: =IF(N7="（相続人","法定代理人)","")
L8: 住所 | N8: =入力元!L6 -> 0
N9: =入力元!L7 -> 0
L10: 氏名
X11: 印
M12: 生年月日 | N12: =入力元!L9 -> 昭和 | P12: =入力元!P9 -> 0 | Q12: 年 | R12: =入力元!T9 -> 0 | S12: 月 | T12: =入力元!X9 -> 0 | U12: 日
B14: 私は、被相続人 | F14: =入力元!L13 -> 0 | J14: （ | K14: =入力元!L14 -> 令和 | L14: =入力元!P14 -> 0 | M14: 年 | N14: =入力元!T14 -> 0 | O14: 月 | P14: =入力元!X14 -> 0 | Q14: 日死亡）の相続手続きに関し、
B15: 次の者を代理人と定め，下記の事項に関する権限を委任します。
C17: 代 理 人
C18: 本店住所 | G18: 横浜市西区高島２丁目１４－１７ クレアトール横浜ビル５階
C19: 従たる事務所 | G19: 横浜市西区高島２丁目１３－２ 横浜駅前共同ビル
E21: 氏名 | H21: 行政書士法人オーシャン | N21: 代表社員 | R21: 黒田 美菜子
N22: 行政書士補助者
A24: 記
B26: １ | C26: 被相続人が公正証書遺言を作成されているか否かを確認する権限
B27: 0
B28: ２ | C28: 被相続人の公正証書遺言謄本を取得する権限
B29: 0
B30: ３ | C30: 前項に掲げる行為の復代理人選定に関する権限
B31: 0
B32: ４ | C32: 前項に付帯する一切の権限
B34: ５ | C34: 本委任状の原本還付を請求する権限

Sheet 特定事務指示書（包括）
A2: 特定事務指示書
B4: 私は、下記の者を、下記の事務手続き代行者として指定します。
A6: 記
C8: 【手続き代行者】
C9: 住所
C10: 氏名
B13: １, | C13: 被相続人 | E13: の相続手続における相続人及び相続財産の確定に必要な書類を
C14: 取得する一切の権限
B15: （１） | C15: 戸籍、除籍、改正原戸籍、住民票、住民票除票、戸籍の附票、不在籍証明、不在住
C16: 明書の取得に関する権限（但し、世帯主・続柄・本籍・筆頭者等の省略がないもの）
B17: （２） | C17: 固定資産名寄帳の取得に関する権限
B18: （３） | C18: 固定資産評価証明書及び非課税証明書ならびに固定資産公課証明書の取得に関する権限
B19: （４） | C19: 預金、貯金等の停止依頼書及び相続手続き書類の提出、証書等の受領、返送書類の受領、
C20: 払戻し金員の受領、連絡
B21: （５） | C21: 貯金及び国債の残高証明書の請求と原本受領・現存調査・貯金入出金照会・証拠書写しの
C22: 請求と回答の受領に関する権限（別紙 有/無）
B23: （６） | C23: 預金、投資信託取引及び保有株式の現存調査及び残高証明書、取引明細書、評価証明書
C24: の請求と取得に関する権限
B25: （７） | C25: 生命保険契約等の現存調査及びそれに関する書類の請求と取得に関する権限
B26: （８） | C26: その他，財産確定に必要な書類の請求と取得に関する一切の権限
B27: （９） | C27: 預貯金、投資信託等の全金融資産の名義変更・解約・換価（遺言者名義の預貯金の払戻し
C28: 手続及び払戻し金員の受領、株式等の有価証券の売却手続及び売却代金の受領の権限
C29: など）、その他の財産の名義変更、貸金庫がある場合はその開扉・蔵置品の引取り・解約
C30: などに必要な一切の権限
B31: （10） | C31: 登録済加入者情報に関する開示請求及びその情報を記載した
C32: 「登録済加入者情報通知書」の受領等に係る一切の事務に関する権限
B33: （11） | C33: 上記手続きに関する役所、金融機関との打合せ
B34: （１2） | C34: 前記に掲げる行為に付帯する一切の権限
C36: 【被相続人】
C37: 住所 | L37: 👈住所のみ手入力
C38: 氏名 | D38: =入力元!L13 -> 0
C40: 【相続人】
C41: 住所 | D41: =入力元!L6 -> 0
D42: =入力元!L7 -> 0
C43: 氏名 | D43: =入力元!L8 -> 0
J45: 以上
J47: =TODAY() -> 46225
C49: 【受任者】
C50: 事務所住所 | D50: 神奈川県横浜市西区高島二丁目14番17号クレアトール横浜ビル５階
C51: 従たる事務所住所 | D51: 神奈川県横浜市西区高島２丁目１３－２ 横浜駅前共同ビル
...

Sheet 原本預かり証
A1: =TODAY() -> 46225
Z2: 外字
Z3: =入力元!$AJ$9&入力元!$AJ$14&IF(OR(入力元!$AC$9="有",入力元!$AC$14="有"),"に外字あり","")
F8: 原本預かり証
Z9: 行政書士法人オーシャン 代表社員 黒田 美菜子 | AE9: 神奈川県横浜市西区高島２丁目１４－１７ クレアトール横浜ビル５階
Z10: 司法書士法人オーシャン 代表社員 山田 哲 | AE10: 神奈川県横浜市西区高島２丁目１３－２ 横浜駅前共同ビル
Z11: 行政書士法人オーシャン 代表社員 黒田 美菜子 司法書士法人オーシャン 代表社員 山田 哲 | AE11: 神奈川県横浜市西区高島２丁目１４－１７ クレアトール横浜ビル５階 神奈川県横浜市西区高島２丁目１３－２ 横浜駅前共同ビル
C12: 本日下記の原本書類をお預かり致しました。 | Z12: 一般社団法人いきいきライフ協会 代表理事 黒田 美菜子 | AE12: 神奈川県横浜市西区高島２丁目１４－１７ クレアトール横浜ビル５階
C13: これらの資料は委任事務の範囲内においてのみ使用し、他一切に用いないことと致します。
O15: 令和 年 月 日
J18: =VLOOKUP(I21,Z9:AH12,6,FALSE) -> 神奈川県横浜市西区高島２丁目１４－１７ クレアトール横浜ビル５階 神奈川県横浜市西区高島２丁目１３－２ 横浜駅前共同ビル
I21: 行政書士法人オーシャン 代表社員 黒田 美菜子 司法書士法人オーシャン 代表社員 山田 哲
A24: 記
E27: 1 | U27: 通
E28: 2 | U28: 通
E29: 3 | U29: 通
E30: 4 | U30: 通
E31: 5 | U31: 通
E32: 6 | U32: 通
E33: 7 | U33: 通
U35: 以上

Sheet 原本受領証 
A1: R | B1: =入力元!N4 -> 8 | C1: - | D1: =[1]入力元!R4 -> Y
Z2: 外字
A4: 行政書士法人オーシャン 代表社員 黒田 美菜子 殿 司法書士法人オーシャン 代表社員 山田 哲 殿
F7: 原本受領証
Z8: 行政書士法人オーシャン 代表社員 黒田 美菜子 殿
Z9: 司法書士法人オーシャン 代表社員 山田 哲 殿
C10: 下記書類について、すべて返還を受け、正に受領致しました。 | Z10: 行政書士法人オーシャン 代表社員 黒田 美菜子 殿 司法書士法人オーシャン 代表社員 山田 哲 殿
Z11: 一般社団法人 いきいきライフ協会 代表理事 黒田 美菜子 殿
O12: 令和 | Q12: 年 | S12: 月 | U12: 日
I15: 住所： | K15: =入力元!L6 -> 0
K16: =入力元!L7 -> 0
I18: 氏名：
V20: 印
A22: 記
D24: 1 | E24: 不動産登記権利証 | U24: 通
D27: 2 | U27: 通
D28: 3 | U28: 通
D29: 4 | U29: 通
D30: 5 | U30: 通
D31: 6 | U31: 通
D32: 7 | U32: 通
D33: 8 | U33: 通
D34: 9 | U34: 通
D35: 10 | U35: 通
D36: 11 | U36: 通
D37: 12 | U37: 通
D38: 13 | U38: 通
V40: 以上
A43: お仏壇のはせがわご利用のお客様へアンケートご協力のお願い
A45: 平素はお仏壇のはせがわを御利用いただき、心より御礼申し上げます。 協力企業及び法人（行政書士、司法書士等）連携して、ご葬儀後のさまざまな手続きのお手伝いをさせていただいております。 サービスの品質向上のため、当社の相続手続き支援サービスをご利用いただいたお客様にアンケートのご協力をお願いしております。 お手数ですが、下記のQRコードからアンケートに進みご回答ください。
A48: ▼回答はこちらから▼
A62: ※所要時間は5分程度です
A64: なお、回答は統計的に処理され、当アンケート以外の目的で使用することはありません。 いただいた個人情報を第三者に提供することはなく、当社のプライバシーポリシーに従って厳重に保管いたします。 アンケートについてご不明点等がありましたら、下記までお問い合わせください。
A69: 株式会社 はせがわ アンケート窓口 ﾋﾟｰｽﾌﾙ･ﾗｲﾌｻﾎﾟｰﾄ企画推進部 電話：0120-558-594

Sheet 郵送書類確認票
N1: 管理番号 | O1: =[2]入力元!R4 -> Y
C2: 郵送書類確認票
C4: 送付書類をご確認いただき、ご返送書類一覧のチェック欄へ☑ご記入、署名欄へご署名・ご捺印の上、 お手数ではございますがご返送の程よろしくお願い致します。 ご不明点等ございましたら、お気軽にお問合せくださいませ。 | N4: 外字
N5: =[2]入力元!$AJ$9&[2]入力元!$AJ$14&IF(OR([2]入力元!$AC$9="有",[2]入力元!$AC$14="有"),"に外字あり","")
D7: ■送付書類一覧 | I7: ■ご返送書類一覧
C8: ＮＯ | D8: 書類内容 | F8: 通数 | H8: チェック | I8: 書類内容 | K8: 通数
C9: 1 | D9: 委任契約書 | F9: 2 | H9: □ | I9: 委任契約書 | K9: 1
C10: 2 | D10: 委任状 | F10: 2 | H10: □ | I10: 委任状 | K10: 1
C11: 3 | D11: 御請求書 | F11: 1 | H11: □ | I11: 法定相続情報一覧図 | K11: 1
C12: 4 | D12: 郵送書類確認票（本状） | F12: 1 | H12: □ | I12: 幸田賢一様の写真付身分証明書写し | K12: 1
C13: 5 | D13: 返信用レターパック | F13: 1 | H13: □ | I13: 郵送書類確認票（本状） | K13: 1
C14: 6 | H14: □
C15: 7 | H15: □
C16: 8 | H16: □
C17: 9 | H17: □
C18: 10 | H18: □ | N18: 行政書士法人オーシャン 代表社員 黒田 美菜子
N19: 司法書士法人オーシャン 代表社員 山田 哲
H20: ※追加でご返送書類がありましたら、 お手数ですがご記入の上ご返送ください。 | N20: 行政書士法人オーシャン 代表社員 黒田 美菜子 司法書士法人オーシャン 代表社員 山田 哲
C21: 発送日： | N21: 一般社団法人いきいきライフ協会 代表理事 黒田 美菜子
C22: 令和 年 月 日 | I22: 令和 年 月 日
I23: 上記書類を確かに受領致しました。
C24: お客様 ご署名欄 | I24: 行政書士法人オーシャン 代表社員 黒田 美菜子 司法書士法人オーシャン 代表社員 山田 哲 | N24: TEL：045-548-3041 FAX:045-548-3081
N25: TEL：045-548-9172 FAX:045-548-9173
I26: お客様担当： | J26: 嶋津／比護 | N26: TEL:0466-53-7992 FAX:0466-53-7993
J27: TEL：045-548-9172 FAX:045-548-9173

Sheet 契約書（1％）
A1: 委 任 契 約 書
AD2: みずほ銀行 | AH2: 横浜東口支店
AD3: 普通口座 | AH3: 2135338
AD4: 口座名義 | AH4: 横浜相続遺言相談センター 横浜本店 黒田美菜子
AG5: （ヨコハマソウゾクイゴンソウダンセンター ヨコハマホンテン クロダミナコ）
AY7: 行政書士業務
AY8: 相続
A9: （ 1 ）■故 | B9: ■ | C9: 故 | J9: 相続 | O9: に関する手続き | AY9: 遺言の作成
AY10: ※その他業務はこちらに上書き
AY13: 司法書士業務
I15: 不動産登記業務 | AY15: 不動産登記業務
AY16: 相続放棄
AY17: ※その他業務はこちらに上書き
AB33: =TODAY() -> 46225
AB35: 甲 | AD35: 住所
AD38: 氏名
AB41: 乙 | AD41: 神奈川県横浜市西区高島２丁目１４－１７ クレアトール横浜ビル５階
AD42: 行政書士法人オーシャン 代表社員 黒田 美菜子
AD43: 神奈川県行政書士会所属
AY44: 別紙報酬額基準表
AB45: 丙 | AD45: 神奈川県横浜市西区高島２丁目１４－１７ クレアトール横浜ビル５階
AD46: 司法書士法人オーシャン 代表社員 山田 哲
AD47: 神奈川県司法書士会所属

Sheet 契約書（執行）
A1: 委任契約書
A4: （ 1 ）■故 | B4: ■ | C4: おーい お茶 | J4: 相続 | M4: に関する手続き
AW12: =TODAY() -> 46225
AW14: 甲 | AY14: 住所
AY16: 氏名
AB18: みずほ銀行 | AF18: 横浜東口支店 | AW18: 乙 | AY18: 神奈川県横浜市西区高島２丁目１４－１７ クレアトール横浜ビル５階
AB19: 普通口座 | AF19: 2162742 | AY19: 行政書士法人オーシャン 代表社員 黒田 美菜子
AB20: 口座名義 | AF20: 横浜相続遺言相談センター横浜本店 | AY20: 神奈川県行政書士会所属
AE21: （ヨコハマソウゾクユイゴンソウダンセンターヨコハマホンテン）
AW22: 丙 | AY22: 神奈川県横浜市西区高島２丁目１４－１７ クレアトール横浜ビル５階
AY23: 司法書士法人オーシャン 代表社員 山田 哲
AY24: 神奈川県司法書士会所属

Sheet 請求書（前受金）行
V1: 作成 | X1: 確認
B2: 案件管理№
B3: =入力元!L4 -> R | C3: =入力元!N4 -> 8 | D3: - | E3: =入力元!R4 -> Y | F3: =入力元!T4 -> 0 | AA3: 外字
A4: 御 請 求 書 | AA4: =入力元!$AJ$9&入力元!$AJ$14&IF(OR(入力元!$AC$9="有",入力元!$AC$14="有"),"に外字あり","")
Q6: 登録番号：T5-0200-0501-0814
B8: =入力元!L8 -> 0 | J8: 様 | N8: 発行年月日 | R8: 令和 | T8: 8 | U8: 年 | V8: 5 | W8: 月 | X8: 23 | Y8: 日
B10: 件名： | D10: 相続手続きサポートプラン | R10: 行政書士法人 | W10: オーシャン
N11: 住所 | P11: ： | Q11: 横浜市西区高島２-１４-１７
B12: 下記の通りご請求申し上げます。 | Q12: クレアトール横浜５階
N13: 担当者 | P13: ： | Q13: 代表社員 黒田 美菜子
B14: 金額 | D14: =V31 -> 93500 | J14: 也 | N14: 電話 | P14: ： | Q14: 045-548-3041
N15: ＦＡＸ | P15: ： | Q15: 045-548-3081
B17: 件 名 | R17: 請求区分 | U17: 請求額
B18: =D10 -> 相続手続きサポートプラン | R18: 前受金 | V18: 93500
AC22: 経理用
B23: 小 計 | U23: ① | V23: =SUM(V18:Y22) -> 93500 | AC23: 税抜価格確認用
B24: そ の 他 費 用 | R24: 金額（税込） | V24: 内消費税（10％） | AC24: ↓触らない
V25: =AC25*0.1 -> 0 | AC25: =S25/1.1 -> 0
V26: =AC26*0.1 -> 0 | AC26: =S26/1.1 -> 0
V27: =AC27*0.1 -> 0 | AC27: =S27/1.1 -> 0
B28: 小 計 | U28: ② | V28: =SUM(S25:U27) -> 0
B29: 内 消 費 税 計 （10％） | U29: ③ | V29: =SUM(V25:Y27) -> 0
B30: 合 計 ①＋② | U30: ④ | V30: =V23+V28 -> 93500
B31: 請 求 額 | U31: ⑤ | V31: =V30 -> 93500
B32: ※前受金は消費税対象外となります。
B33: 備考：お振込手数料はお客様ご負担にてお願い申し上げます。
C34: 前受金の領収書につきましては、特段のお申出がない限りは発行致しませんので、
C35: 振込票の控えを大切に保管ください。
B37: お支払口座 【振込先】 | G37: みずほ銀行 横浜東口支店
G38: 普通口座 | J38: 口座番号 | M38: 2167817
G39: 口座名義 | J39: 行政書士法人オーシャン
L40: （ギョウセイショシホウジンオーシャン）
B41: お支払条件 | F41: ご請求日より5営業日以内にお支払下さい。

Sheet 請求書（前受金）司
V1: 作成 | X1: 確認
B2: 案件管理№
B3: =入力元!L4 -> R | C3: =入力元!N4 -> 8 | D3: - | E3: =入力元!R4 -> Y | F3: =入力元!T4 -> 0 | AA3: 外字
A4: 御 請 求 書 | AA4: =入力元!$AJ$9&入力元!$AJ$14&IF(OR(入力元!$AC$9="有",入力元!$AC$14="有"),"に外字あり","")
Q6: 登録番号：T8-0200-0501-1099
B8: =入力元!L8 -> 0 | J8: 様 | N8: 発行年月日 | R8: 令和 | U8: 年 | W8: 月 | Y8: 日
B10: 件名： | R10: 司法書士法人 | W10: オーシャン
N11: 住所 | P11: ： | Q11: 横浜市西区高島２丁目１３－２
B12: 下記の通りご請求申し上げます。 | Q12: 横浜駅前共同ビル
N13: 担当者 | P13: ： | Q13: 司法書士 山田 哲
B14: 金額 | D14: =V31 -> 0 | J14: 也 | N14: 電話 | P14: ： | Q14: 045-548-9172
N15: ＦＡＸ | P15: ： | Q15: 045-548-9173
B17: 件 名 | R17: 請求区分 | U17: 請求額
B18: =D10 -> 0 | R18: 前受金
AC22: 経理用
B23: 小 計 | U23: ① | V23: =SUM(V18:Y22) -> 0 | AC23: 税抜価格確認用
B24: そ の 他 費 用 | R24: 金額（税込） | V24: 内消費税（10％） | AC24: ↓触らない
V25: =AC25*0.1 -> 0 | AC25: =S25/1.1 -> 0
V26: =AC26*0.1 -> 0 | AC26: =S26/1.1 -> 0
V27: =AC27*0.1 -> 0 | AC27: =S27/1.1 -> 0
B28: 小 計 | U28: ② | V28: =SUM(S25:U27) -> 0
B29: 内 消 費 税 計 （10％） | U29: ③ | V29: =SUM(V25:Y27) -> 0
B30: 合 計 ①＋② | U30: ④ | V30: =V23+V28 -> 0
B31: 請 求 額 | U31: ⑤ | V31: =V30 -> 0
B32: ※前受金は消費税対象外となります。
B33: 備考：お振込手数料はお客様ご負担にてお願い申し上げます。
C34: 前受金の領収書につきましては、特段のお申出がない限りは発行致しませんので、
C35: 振込票の控えを大切に保管ください。
B37: お支払口座 【振込先】 | G37: みずほ銀行 横浜東口支店
G38: 普通口座 | J38: 口座番号 | M38: 2169216
G39: 口座名義 | J39: 司法書士法人オーシャン 代表社員 山田 哲
I40: （シホウショシホウジンオーシャンダイヒョウシャインヤマダサトシ）
B41: お支払条件 | F41: ご請求日より5営業日以内にお支払下さい。

Sheet 立替実費 行 
A1: 案件管理№ | H1: 発行日：
A2: =入力元!L4&入力元!N4&入力元!P4&入力元!R4&入力元!T4 -> R8-Y | H2: 担 当 | M2: 外字
M3: =入力元!$AJ$9&入力元!$AJ$14&IF(OR(入力元!$AC$9="有",入力元!$AC$14="有"),"に外字あり","")
A4: 立替実費明細書
A7: =入力元!L8 -> 0
D8: 様
G9: 行政書士法人オーシャン 代表社員 黒田 美菜子
G11: 〒 220-0011
A12: =I65 -> 0 | G12: 横浜市西区高島2-14-17クレアトール横浜5階
D13: 也
A16: 下記の通りご請求申し上げます。
A18: 立替実費名目 （非課税） | E18: 数量 | F18: 単価 | G18: 金額 | H18: 備考
G19: =E19*F19 -> 0
G21: =E21*F21 -> 0
G23: =E23*F23 -> 0
G25: =E25*F25 -> 0
G27: =E27*F27 -> 0
G29: =E29*F29 -> 0
G31: =E31*F31 -> 0
G33: =E33*F33 -> 0
G35: =E35*F35 -> 0
G37: =E37*F37 -> 0
F39: 小計 | G39: =SUM(G19:G38) -> 0
A42: 立替実費名目 （課税） | E42: 数量 | F42: 単価 | G42: 金額（税込） | H42: 備考
G43: =E43*F43 -> 0
G45: =E45*F45 -> 0
G47: =E47*F47 -> 0
G49: =E49*F49 -> 0
G51: =E51*F51 -> 0
G53: =E53*F53 -> 0
G55: =E55*F55 -> 0
G57: =E57*F57 -> 0
G59: =E59*F59 -> 0
G61: =E61*F61 -> 0
F63: 小計 | G63: =SUM(G43:G62) -> 0
A65: 上段の 国、地方公共団体等の手数料については消費税非課税となります。 | H65: 合計 | I65: =SUM(G39,G63) -> 0

Sheet 立替実費 司
A1: 案件管理№ | H1: 発行日：
A2: =入力元!L4&入力元!N4&入力元!P4&入力元!R4&入力元!T4 -> R8-Y | H2: 担 当 | M2: 外字
M3: =入力元!$AJ$9&入力元!$AJ$14&IF(OR(入力元!$AC$9="有",入力元!$AC$14="有"),"に外字あり","")
A4: 立替実費明細書
A7: =入力元!L8 -> 0
D8: 様
G9: 司法書士法人オーシャン 代表社員 山田 哲
G11: 〒 220-0011
A12: =I65 -> 0 | G12: 横浜市西区高島２丁目１３－２ 横浜駅前共同ビル
D13: 也
A16: 下記の通りご請求申し上げます。
A18: 立替実費名目 （非課税） | E18: 数量 | F18: 単価 | G18: 金額 | H18: 備考
G19: =E19*F19 -> 0
G21: =E21*F21 -> 0
G23: =E23*F23 -> 0
G25: =E25*F25 -> 0
G27: =E27*F27 -> 0
G29: =E29*F29 -> 0
G31: =E31*F31 -> 0
G33: =E33*F33 -> 0
G35: =E35*F35 -> 0
G37: =E37*F37 -> 0
F39: 小計 | G39: =SUM(G19:G38) -> 0
A42: 立替実費名目 （課税） | E42: 数量 | F42: 単価 | G42: 金額（税込） | H42: 備考
G43: =E43*F43 -> 0
G45: =E45*F45 -> 0
G47: =E47*F47 -> 0
G49: =E49*F49 -> 0
G51: =E51*F51 -> 0
G53: =E53*F53 -> 0
G55: =E55*F55 -> 0
G57: =E57*F57 -> 0
G59: =E59*F59 -> 0
G61: =E61*F61 -> 0
F63: 小計 | G63: =SUM(G43:G62) -> 0
A65: 上段の 国、地方公共団体等の手数料については消費税非課税となります。 | H65: 合計 | I65: =SUM(G39,G63) -> 0

Sheet 請求書 (確定)行
V1: 作成 | X1: 確認
B2: 案件管理№
B3: =入力元!L4 -> R | C3: =入力元!N4 -> 8 | D3: - | E3: =入力元!R4 -> Y | F3: =入力元!T4 -> 0 | AA3: 外字
A4: 御 請 求 書 | AA4: =入力元!$AJ$9&入力元!$AJ$14&IF(OR(入力元!$AC$9="有",入力元!$AC$14="有"),"に外字あり","")
Q6: 登録番号：T5-0200-0501-0814
B8: =入力元!L8 -> 0 | J8: 様 | N8: 発行年月日 | R8: 令和 | U8: 年 | W8: 月 | Y8: 日
B10: 件名： | D10: ='請求書（前受金）行'!D10:K10 -> 相続手続きサポートプラン | R10: 行政書士法人 | W10: オーシャン
N11: 住所 | P11: ： | Q11: 横浜市西区高島２-１４-１７
B12: 下記の通りご請求申し上げます。 | Q12: クレアトール横浜５階
N13: 担当者 | P13: ： | Q13: 代表社員 黒田 美菜子
B14: 金額 | D14: =R29 -> -93500 | J14: 也 | N14: 電話 | P14: ： | Q14: 045-548-3041
N15: ＦＡＸ | P15: ： | Q15: 045-548-3081 | AG15: 経理用
AG16: 税抜価格確認用
B17: 件 名 | O17: 請求区分 | R17: 金額（税込） | V17: 内消費税（10％） | AG17: ↓触らない
B18: ='請求書（前受金）行'!B18:Q18 -> 相続手続きサポートプラン | O18: 報酬 | V18: =AG18*0.1 -> 0 | AG18: =R18/1.1 -> 0
V19: =AG19*0.1 -> 0 | AG19: =R19/1.1 -> 0
V20: =AG20*0.1 -> 0 | AG20: =R20/1.1 -> 0
B21: 前受金(令和8年●月●日受領) | V21: =-'請求書（前受金）行'!V18:Y18 -> -93500
B22: そ の 他 費 用 | R22: 金額（税込） | V22: 内消費税（10％）
B23: 立替実費代（課税分） | R23: ='立替実費 行 '!G63 -> 0 | V23: =AG23*0.1 -> 0 | AG23: =R23/1.1 -> 0
B24: 立替実費代（非課税分） | R24: ='立替実費 行 '!G39 -> 0 | AG24: =R24/1.1 -> 0
V25: =AG25*0.1 -> 0 | AG25: =R25/1.1 -> 0
B26: 小 計 （ 税 込 ） | R26: =SUM(R18:U20,R23:U25) -> 0
B27: 10 ％ 対 象 額 （ 合 計 ） | R27: =SUM(R18:U20,R23,R25) -> 0
B28: 内 消 費 税 計 （10％） | R28: =SUM(V18:Y20,V23,V25) -> 0
B29: 請 求 額 | R29: =R26+V21 -> -93500
B31: 備考：お振込手数料はお客様ご負担にてお願い申し上げます。
B34: お支払口座 【振込先】 | G34: みずほ銀行 横浜東口支店
G35: 普通口座 | J35: 口座番号 | M35: 2167817
G36: 口座名義 | J36: 行政書士法人オーシャン
L37: （ギョウセイショシホウジンオーシャン）
B38: お支払条件 | F38: ご請求日より5営業日以内にお支払下さい。

Sheet 請求書 (確定)司
V1: 作成 | X1: 確認
B2: 案件管理№
B3: =入力元!L4 -> R | C3: =入力元!N4 -> 8 | D3: - | E3: =入力元!R4 -> Y | F3: =入力元!T4 -> 0 | AA3: 外字
A4: 御 請 求 書 | AA4: =入力元!$AJ$9&入力元!$AJ$14&IF(OR(入力元!$AC$9="有",入力元!$AC$14="有"),"に外字あり","")
Q6: 登録番号：T8-0200-0501-1099
B8: =入力元!L8 -> 0 | J8: 様 | N8: 発行年月日 | R8: 令和 | U8: 年 | W8: 月 | Y8: 日
B10: 件名： | D10: ='請求書（前受金）司'!D10:K10 -> 0 | R10: 司法書士法人 | W10: オーシャン
N11: 住所 | P11: ： | Q11: 横浜市西区高島２丁目１３－２
B12: 下記の通りご請求申し上げます。 | Q12: 横浜駅前共同ビル
N13: 担当者 | P13: ： | Q13: 司法書士 山田 哲
B14: 金額 | D14: =R29 -> 0 | J14: 也 | N14: 電話 | P14: ： | Q14: 045-548-9172
N15: ＦＡＸ | P15: ： | Q15: 045-548-9173 | AG15: 経理用
AG16: 税抜価格確認用
B17: 件 名 | O17: 請求区分 | R17: 金額（税込） | V17: 内消費税（10％） | AG17: ↓触らない
B18: ='請求書（前受金）司'!B18:Q18 -> 0 | O18: 報酬 | V18: =AG18*0.1 -> 0 | AG18: =R18/1.1 -> 0
V19: =AG19*0.1 -> 0 | AG19: =R19/1.1 -> 0
V20: =AG20*0.1 -> 0 | AG20: =R20/1.1 -> 0
B21: 前受金(令和8年●月●日受領) | V21: =-'請求書（前受金）司'!V18:Y18 -> 0
B22: そ の 他 費 用 | R22: 金額（税込） | V22: 内消費税（10％）
B23: 立替実費代（課税分） | R23: ='立替実費 司'!G63 -> 0 | V23: =AG23*0.1 -> 0 | AG23: =R23/1.1 -> 0
B24: 立替実費代（非課税分） | R24: ='立替実費 司'!G39 -> 0 | AG24: =R24/1.1 -> 0
V25: =AG25*0.1 -> 0 | AG25: =R25/1.1 -> 0
B26: 小 計 （ 税 込 ） | R26: =SUM(R18:U20,R23:U25) -> 0
B27: 10 ％ 対 象 額 （ 合 計 ） | R27: =SUM(R18:U20,R23,R25) -> 0
B28: 内 消 費 税 計 （10％） | R28: =SUM(V18:Y20,V23,V25) -> 0
B29: 請 求 額 | R29: =R26+V21 -> 0
B31: 備考：お振込手数料はお客様ご負担にてお願い申し上げます。
B34: お支払口座 【振込先】 | G34: みずほ銀行 横浜東口支店
G35: 普通口座 | J35: 口座番号 | M35: 2169216
G36: 口座名義 | J36: 司法書士法人オーシャン 代表社員 山田 哲
I37: （シホウショシホウジンオーシャンダイヒョウシャインヤマダサトシ）
B38: お支払条件 | F38: ご請求日より5営業日以内にお支払下さい。

Sheet 領収書（前受金）行
B2: 案件管理№
B3: =入力元!L4 -> R | C3: =入力元!N4 -> 8 | D3: - | E3: =入力元!R4 -> Y | F3: =入力元!T4 -> 0 | AA3: 外字
A4: 領 収 書 | AA4: =入力元!$AJ$9&入力元!$AJ$14&IF(OR(入力元!$AC$9="有",入力元!$AC$14="有"),"に外字あり","")
Q6: 登録番号：T5-0200-0501-0814
B8: =入力元!L8 -> 0 | J8: 様 | N8: 領 収 日 | R8: 令和 | U8: 年 | W8: 月 | Y8: 日
B10: 件名： | D10: ='請求書（前受金）行'!D10:K10 -> 相続手続きサポートプラン | R10: 行政書士法人 | W10: オーシャン
N11: 住所 | P11: ： | Q11: 横浜市西区高島２-１４-１７
B12: 下記のとおり領収致しました。 | Q12: クレアトール横浜５階
N13: 担当者 | P13: ： | Q13: 代表社員 黒田 美菜子
B14: 金額 | D14: =V31 -> 93500 | J14: 也 | N14: 電話 | P14: ： | Q14: 045-548-3041
N15: ＦＡＸ | P15: ： | Q15: 045-548-3081
B17: 件 名 | R17: 区分 | U17: 請求額
B18: ='請求書（前受金）行'!B18:Q18 -> 相続手続きサポートプラン | R18: ='請求書（前受金）行'!R18:T18 -> 前受金 | V18: ='請求書（前受金）行'!V18:Y18 -> 93500
B23: 小 計 | U23: ① | V23: =SUM(V18:Y22) -> 93500
B24: そ の 他 費 用 | R24: 金額（税込） | V24: 内消費税（10％）
S25: ='請求書（前受金）行'!S25:U25 -> 0 | V25: ='請求書（前受金）行'!V25:Y25 -> 0
S26: ='請求書（前受金）行'!S26:U26 -> 0 | V26: ='請求書（前受金）行'!V26:Y26 -> 0
S27: ='請求書（前受金）行'!S27:U27 -> 0 | V27: ='請求書（前受金）行'!V27:Y27 -> 0
B28: 小 計 | U28: ② | V28: =SUM(S25:U27) -> 0
B29: 内 消 費 税 計 （10％） | U29: ③ | V29: =SUM(V25:Y27) -> 0
B30: 合 計 ①＋② | U30: ④ | V30: =V23+V28 -> 93500
B31: 領 収 額 | U31: ⑤ | V31: =V30 -> 93500
B34: 備 考

Sheet 領収書（前受金）司
B2: 案件管理№
B3: =入力元!L4 -> R | C3: =入力元!N4 -> 8 | D3: - | E3: =入力元!R4 -> Y | F3: =入力元!T4 -> 0 | AA3: 外字
A4: 領 収 書 | AA4: =入力元!$AJ$9&入力元!$AJ$14&IF(OR(入力元!$AC$9="有",入力元!$AC$14="有"),"に外字あり","")
Q6: 登録番号：T8-0200-0501-1099
B8: =入力元!L8 -> 0 | J8: 様 | N8: 領 収 日 | R8: 令和 | U8: 年 | W8: 月 | Y8: 日
B10: 件名： | D10: ='請求書（前受金）司'!D10:K10 -> 0 | R10: 司法書士法人 | W10: オーシャン
N11: 住所 | P11: ： | Q11: 横浜市西区高島２丁目１３－２
B12: 下記のとおり領収致しました。 | Q12: 横浜駅前共同ビル
N13: 担当者 | P13: ： | Q13: 司法書士 山田 哲
B14: 金額 | D14: =V31 -> 0 | J14: 也 | N14: 電話 | P14: ： | Q14: 045-548-9172
N15: ＦＡＸ | P15: ： | Q15: 045-548-9173
B17: 件 名 | R17: 区分 | U17: 請求額
B18: ='請求書（前受金）司'!B18:Q18 -> 0 | R18: ='請求書（前受金）司'!R18:T18 -> 前受金 | V18: ='請求書（前受金）司'!V18:Y18 -> 0
B23: 小 計 | U23: ① | V23: =SUM(V18:Y22) -> 0
B24: そ の 他 費 用 | R24: 金額（税込） | V24: 内消費税（10％）
S25: ='請求書（前受金）司'!S25:U25 -> 0 | V25: ='請求書（前受金）司'!V25:Y25 -> 0
S26: ='請求書（前受金）司'!S26:U26 -> 0 | V26: ='請求書（前受金）司'!V26:Y26 -> 0
S27: ='請求書（前受金）司'!S27:U27 -> 0 | V27: ='請求書（前受金）司'!V27:Y27 -> 0
B28: 小 計 | U28: ② | V28: =SUM(S25:U27) -> 0
B29: 内 消 費 税 計 （10％） | U29: ③ | V29: =SUM(V25:Y27) -> 0
B30: 合 計 ①＋② | U30: ④ | V30: =V23+V28 -> 0
B31: 領 収 額 | U31: ⑤ | V31: =V30 -> 0
B34: 備 考

Sheet 領収書 (確定)行
B2: 案件管理№
B3: =入力元!L4 -> R | C3: =入力元!N4 -> 8 | D3: - | E3: =入力元!R4 -> Y | F3: =入力元!T4 -> 0 | AA3: 外字
A4: 領 収 書 | AA4: =入力元!$AJ$9&入力元!$AJ$14&IF(OR(入力元!$AC$9="有",入力元!$AC$14="有"),"に外字あり","")
Q6: 登録番号：T5-0200-0501-0814
B8: =入力元!L8 -> 0 | J8: 様 | N8: 領 収 日 | R8: 令和 | U8: 年 | W8: 月 | Y8: 日
B10: 件名： | D10: ='請求書（前受金）行'!D10:K10 -> 相続手続きサポートプラン | R10: 行政書士法人 | W10: オーシャン
N11: 住所 | P11: ： | Q11: 横浜市西区高島２-１４-１７
B12: 下記のとおり領収致しました。 | Q12: クレアトール横浜５階
N13: 担当者 | P13: ： | Q13: 代表社員 黒田 美菜子
B14: 金額 | D14: =R29 -> -93500 | J14: 也 | N14: 電話 | P14: ： | Q14: 045-548-3041
N15: ＦＡＸ | P15: ： | Q15: 045-548-3081
B17: 件 名 | O17: 区分 | R17: 金額（税込） | V17: 内消費税（10％）
B18: ='請求書 (確定)行'!B18:N18 -> 相続手続きサポートプラン | O18: ='請求書 (確定)行'!O18:Q18 -> 報酬 | R18: ='請求書 (確定)行'!R18:U18 -> 0 | V18: ='請求書 (確定)行'!V18:Y18 -> 0
V19: ='請求書 (確定)行'!V19:Y19 -> 0
V20: ='請求書 (確定)行'!V20:Y20 -> 0
B21: ='請求書 (確定)行'!B21:U21 -> 前受金(令和8年●月●日受領) | V21: ='請求書 (確定)行'!V21:Y21 -> -93500
B22: その他費用 | R22: 金額（税込） | V22: 内消費税（10％）
B23: 立替実費代（課税分） | R23: ='請求書 (確定)行'!R23:U23 -> 0 | V23: ='請求書 (確定)行'!V23:Y23 -> 0
B24: 立替実費代（非課税分） | R24: ='請求書 (確定)行'!R24:U24 -> 0
V25: ='請求書 (確定)行'!V25:Y25 -> 0
B26: 小 計 （ 税 込 ） | R26: =SUM(R18:U20,R23:U25) -> 0
B27: 10 ％ 対 象 額 （ 合 計 ） | R27: =SUM(R18:U20,R23,R25) -> 0
B28: 内 消 費 税 計 （10％） | R28: =SUM(V18:Y20,V23,V25) -> 0
B29: 領 収 額 | R29: =R26+V21 -> -93500
B32: 備 考

Sheet 領収書 (確定)司
B2: 案件管理№
B3: =入力元!L4 -> R | C3: =入力元!N4 -> 8 | D3: - | E3: =入力元!R4 -> Y | F3: =入力元!T4 -> 0 | AA3: 外字
A4: 領 収 書 | AA4: =入力元!$AJ$9&入力元!$AJ$14&IF(OR(入力元!$AC$9="有",入力元!$AC$14="有"),"に外字あり","")
Q6: 登録番号：T8-0200-0501-1099
B8: =入力元!L8 -> 0 | J8: 様 | N8: 領 収 日 | R8: 令和 | U8: 年 | W8: 月 | Y8: 日
B10: 件名： | D10: ='請求書（前受金）司'!D10:K10 -> 0 | R10: 司法書士法人 | W10: オーシャン
N11: 住所 | P11: ： | Q11: 横浜市西区高島２丁目１３－２
B12: 下記のとおり領収致しました。 | Q12: 横浜駅前共同ビル
N13: 担当者 | P13: ： | Q13: 司法書士 山田 哲
B14: 金額 | D14: =R29 -> 0 | J14: 也 | N14: 電話 | P14: ： | Q14: 045-548-9172
N15: ＦＡＸ | P15: ： | Q15: 045-548-9173
B17: 件 名 | O17: 区分 | R17: 金額（税込） | V17: 内消費税（10％）
B18: ='請求書 (確定)司'!B18:N18 -> 0 | O18: ='請求書 (確定)司'!O18:Q18 -> 報酬 | R18: ='請求書 (確定)司'!R18:U18 -> 0 | V18: ='請求書 (確定)司'!V18:Y18 -> 0
V19: ='請求書 (確定)司'!V19:Y19 -> 0
V20: ='請求書 (確定)司'!V20:Y20 -> 0
B21: ='請求書 (確定)司'!B21:U21 -> 前受金(令和8年●月●日受領) | V21: ='請求書 (確定)司'!V21:Y21 -> 0
B22: その他費用 | R22: 金額（税込） | V22: 内消費税（10％）
B23: 立替実費代（課税分） | R23: ='請求書 (確定)司'!R23:U23 -> 0 | V23: ='請求書 (確定)司'!V23:Y23 -> 0
B24: 立替実費代（非課税分） | R24: ='請求書 (確定)司'!R24:U24 -> 0
V25: ='請求書 (確定)司'!V25:Y25 -> 0
B26: 小 計 （ 税 込 ） | R26: =SUM(R18:U20,R23:U25) -> 0
B27: 10 ％ 対 象 額 （ 合 計 ） | R27: =SUM(R18:U20,R23,R25) -> 0
B28: 内 消 費 税 計 （10％） | R28: =SUM(V18:Y20,V23,V25) -> 0
B29: 領 収 額 | R29: =R26+V21 -> 0
B32: 備 考

Sheet 角２封筒
V2: 〒 | X2: =MID(入力元!N5,1,1) | Z2: =MID(入力元!N5,2,1) | AB2: =MID(入力元!N5,3,1) | AD2: - | AE2: =MID(入力元!R5,1,1) | AG2: =MID(入力元!R5,2,1) | AI2: =MID(入力元!R5,3,1) | AK2: =MID(入力元!R5,4,1) | AN2: 外字
AN3: =入力元!$AJ$9&入力元!$AJ$14&IF(OR(入力元!$AC$9="有",入力元!$AC$14="有"),"に外字あり","")
G9: =入力元!L6 -> 0
G10: =入力元!L7 -> 0
K14: =入力元!L8 -> 0 | AB14: 様

Sheet 長形３号（白）
J2: 〒 | K2: =MID(入力元!N5,1,1) | L2: =MID(入力元!N5,2,1) | M2: =MID(入力元!N5,3,1) | N2: - | O2: =MID(入力元!R5,1,1) | P2: =MID(入力元!R5,2,1) | Q2: =MID(入力元!R5,3,1) | R2: =MID(入力元!R5,4,1) | T2: 外字
T3: =入力元!$AJ$9&入力元!$AJ$14&IF(OR(入力元!$AC$9="有",入力元!$AC$14="有"),"に外字あり","")
A9: =入力元!L6 -> 0
C10: =入力元!L7 -> 0
C14: =入力元!L8 -> 0 | O14: 様

Sheet 長形３号 (茶)
J2: 〒 | K2: =MID(入力元!N5,1,1) | L2: =MID(入力元!N5,2,1) | M2: =MID(入力元!N5,3,1) | N2: - | O2: =MID(入力元!R5,1,1) | P2: =MID(入力元!R5,2,1) | Q2: =MID(入力元!R5,3,1) | R2: =MID(入力元!R5,4,1) | T2: 外字
T3: =入力元!$AJ$9&入力元!$AJ$14&IF(OR(入力元!$AC$9="有",入力元!$AC$14="有"),"に外字あり","")
A9: =入力元!L6 -> 0
C10: =入力元!L7 -> 0
C14: =入力元!L8 -> 0 | O14: 様

Sheet Sheet7

Sheet 抽出元
