Workbook
Name gaiyou: 設定用!$D$6:$D$15
Name lank: 設定用!$H$6:$H$14
Name mendan: 設定用!$F$6:$F$13
Name shiten: 設定用!$B$6:$B$8

Sheet シート118

Sheet シート119

Sheet シート120

Sheet シート171

Sheet シート174

Sheet シート134

Sheet シート122

Sheet シート115

Sheet シート113

Sheet シート103

Sheet 拠点別年間集計
A1: -- | F1: 1月 | G1: 2月 | H1: 3月 | I1: 4月 | J1: 5月 | K1: 6月 | L1: 7月 | M1: 8月 | N1: 9月 | O1: 10月 | P1: 11月 | Q1: 12月
C2: アポ率集計 | F2: 1月 | G2: 2月 | H2: 3月 | I2: 4月 | J2: 5月 | K2: 6月 | L2: 7月 | M2: 8月 | N2: 9月 | O2: 10月 | P2: 11月 | Q2: 12月 | R2: 年間
B3: D4 | C3: 総計 | D3: 受信件数 | F3: =INDIRECT(F$1&"!"&$B3) -> 55 | G3: =INDIRECT(G$1&"!"&$B3) -> 52 | H3: =INDIRECT(H$1&"!"&$B3) -> 68 | I3: =INDIRECT(I$1&"!"&$B3) -> 73 | J3: =INDIRECT(J$1&"!"&$B3) -> 0 | K3: =INDIRECT(K$1&"!"&$B3) -> 0 | L3: =INDIRECT(L$1&"!"&$B3) -> 0 | M3: =INDIRECT(M$1&"!"&$B3) -> 0 | ... Q3: =INDIRECT(Q$1&"!"&$B3) -> 0 | R3: =SUM(F3:Q3) -> 248
B4: D5 | D4: 面談予約件数 | F4: =INDIRECT(F$1&"!"&$B4) -> 35 | G4: =INDIRECT(G$1&"!"&$B4) -> 25 | H4: =INDIRECT(H$1&"!"&$B4) -> 44 | I4: =INDIRECT(I$1&"!"&$B4) -> 39 | J4: =INDIRECT(J$1&"!"&$B4) -> 0 | K4: =INDIRECT(K$1&"!"&$B4) -> 0 | L4: =INDIRECT(L$1&"!"&$B4) -> 0 | M4: =INDIRECT(M$1&"!"&$B4) -> 0 | ... Q4: =INDIRECT(Q$1&"!"&$B4) -> 0 | R4: =SUM(F4:Q4) -> 143
B5: D6 | D5: 面談獲得率 | F5: =INDIRECT(F$1&"!"&$B5) -> 0.63636364 | G5: =INDIRECT(G$1&"!"&$B5) -> 0.48076923 | H5: =INDIRECT(H$1&"!"&$B5) -> 0.64705882 | I5: =INDIRECT(I$1&"!"&$B5) -> 0.53424658 | J5: =INDIRECT(J$1&"!"&$B5) | K5: =INDIRECT(K$1&"!"&$B5) | L5: =INDIRECT(L$1&"!"&$B5) | M5: =INDIRECT(M$1&"!"&$B5) | ... Q5: =INDIRECT(Q$1&"!"&$B5) | R5: =R4/R3 -> 0.5766129
B7: E4 | C7: =設定用!B6 -> 横浜本店 | D7: 受信件数 | F7: =INDIRECT(F$1&"!"&$B7) -> 55 | G7: =INDIRECT(G$1&"!"&$B7) -> 51 | H7: =INDIRECT(H$1&"!"&$B7) -> 67 | I7: =INDIRECT(I$1&"!"&$B7) -> 73 | J7: =INDIRECT(J$1&"!"&$B7) -> 0 | K7: =INDIRECT(K$1&"!"&$B7) -> 0 | L7: =INDIRECT(L$1&"!"&$B7) -> 0 | M7: =INDIRECT(M$1&"!"&$B7) -> 0 | ... Q7: =INDIRECT(Q$1&"!"&$B7) -> 0 | R7: =SUM(F7:Q7) -> 246
B8: E5 | D8: 面談予約件数 | F8: =INDIRECT(F$1&"!"&$B8) -> 35 | G8: =INDIRECT(G$1&"!"&$B8) -> 24 | H8: =INDIRECT(H$1&"!"&$B8) -> 43 | I8: =INDIRECT(I$1&"!"&$B8) -> 39 | J8: =INDIRECT(J$1&"!"&$B8) -> 0 | K8: =INDIRECT(K$1&"!"&$B8) -> 0 | L8: =INDIRECT(L$1&"!"&$B8) -> 0 | M8: =INDIRECT(M$1&"!"&$B8) -> 0 | ... Q8: =INDIRECT(Q$1&"!"&$B8) -> 0 | R8: =SUM(F8:Q8) -> 141
B9: E6 | D9: 面談獲得率 | F9: =INDIRECT(F$1&"!"&$B9) -> 0.63636364 | G9: =INDIRECT(G$1&"!"&$B9) -> 0.47058824 | H9: =INDIRECT(H$1&"!"&$B9) -> 0.64179104 | I9: =INDIRECT(I$1&"!"&$B9) -> 0.53424658 | J9: =INDIRECT(J$1&"!"&$B9) | K9: =INDIRECT(K$1&"!"&$B9) | L9: =INDIRECT(L$1&"!"&$B9) | M9: =INDIRECT(M$1&"!"&$B9) | ... Q9: =INDIRECT(Q$1&"!"&$B9) | R9: =R8/R7 -> 0.57317073
B11: F4 | C11: =設定用!B7 -> 藤沢支店 | D11: 受信件数 | F11: =INDIRECT(F$1&"!"&$B11) -> 0 | G11: =INDIRECT(G$1&"!"&$B11) -> 1 | H11: =INDIRECT(H$1&"!"&$B11) -> 1 | I11: =INDIRECT(I$1&"!"&$B11) -> 0 | J11: =INDIRECT(J$1&"!"&$B11) -> 0 | K11: =INDIRECT(K$1&"!"&$B11) -> 0 | L11: =INDIRECT(L$1&"!"&$B11) -> 0 | M11: =INDIRECT(M$1&"!"&$B11) -> 0 | ... Q11: =INDIRECT(Q$1&"!"&$B11) -> 0 | R11: =SUM(F11:Q11) -> 2 | S11: =AVERAGE(E11:N11) -> 0.22222222
B12: F5 | D12: 面談予約件数 | F12: =INDIRECT(F$1&"!"&$B12) -> 0 | G12: =INDIRECT(G$1&"!"&$B12) -> 1 | H12: =INDIRECT(H$1&"!"&$B12) -> 1 | I12: =INDIRECT(I$1&"!"&$B12) -> 0 | J12: =INDIRECT(J$1&"!"&$B12) -> 0 | K12: =INDIRECT(K$1&"!"&$B12) -> 0 | L12: =INDIRECT(L$1&"!"&$B12) -> 0 | M12: =INDIRECT(M$1&"!"&$B12) -> 0 | ... Q12: =INDIRECT(Q$1&"!"&$B12) -> 0 | R12: =SUM(F12:Q12) -> 2
B13: F6 | D13: 面談獲得率 | F13: =INDIRECT(F$1&"!"&$B13) | G13: =INDIRECT(G$1&"!"&$B13) -> 1 | H13: =INDIRECT(H$1&"!"&$B13) -> 1 | I13: =INDIRECT(I$1&"!"&$B13) | J13: =INDIRECT(J$1&"!"&$B13) | K13: =INDIRECT(K$1&"!"&$B13) | L13: =INDIRECT(L$1&"!"&$B13) | M13: =INDIRECT(M$1&"!"&$B13) | ... Q13: =INDIRECT(Q$1&"!"&$B13) | R13: =R12/R11 -> 1
B15: G4 | C15: =設定用!B8 -> 渋谷支店 | D15: 受信件数 | F15: =INDIRECT(F$1&"!"&$B15) -> 0 | G15: =INDIRECT(G$1&"!"&$B15) -> 0 | H15: =INDIRECT(H$1&"!"&$B15) -> 0 | I15: =INDIRECT(I$1&"!"&$B15) -> 0 | J15: =INDIRECT(J$1&"!"&$B15) -> 0 | K15: =INDIRECT(K$1&"!"&$B15) -> 0 | L15: =INDIRECT(L$1&"!"&$B15) -> 0 | M15: =INDIRECT(M$1&"!"&$B15) -> 0 | ... Q15: =INDIRECT(Q$1&"!"&$B15) -> 0 | R15: =SUM(F15:Q15) -> 0
B16: G5 | D16: 面談予約件数 | F16: =INDIRECT(F$1&"!"&$B16) -> 0 | G16: =INDIRECT(G$1&"!"&$B16) -> 0 | H16: =INDIRECT(H$1&"!"&$B16) -> 0 | I16: =INDIRECT(I$1&"!"&$B16) -> 0 | J16: =INDIRECT(J$1&"!"&$B16) -> 0 | K16: =INDIRECT(K$1&"!"&$B16) -> 0 | L16: =INDIRECT(L$1&"!"&$B16) -> 0 | M16: =INDIRECT(M$1&"!"&$B16) -> 0 | ... Q16: =INDIRECT(Q$1&"!"&$B16) -> 0 | R16: =SUM(F16:Q16) -> 0
B17: G6 | D17: 面談獲得率 | F17: =INDIRECT(F$1&"!"&$B17) | G17: =INDIRECT(G$1&"!"&$B17) | H17: =INDIRECT(H$1&"!"&$B17) | I17: =INDIRECT(I$1&"!"&$B17) | J17: =INDIRECT(J$1&"!"&$B17) | K17: =INDIRECT(K$1&"!"&$B17) | L17: =INDIRECT(L$1&"!"&$B17) | M17: =INDIRECT(M$1&"!"&$B17) | ... Q17: =INDIRECT(Q$1&"!"&$B17) | R17: =R16/R15 -> #DIV/0!
C20: 受注率 集計 | F20: 1月 | G20: 2月 | H20: 3月 | I20: 4月 | J20: 5月 | K20: 6月 | L20: 7月 | M20: 8月 | N20: 9月 | O20: 10月 | P20: 11月 | Q20: 12月 | R20: 年間
B21: D211 | C21: 総計 | D21: 面談対応件数 | F21: =INDIRECT(F$1&"!"&$B21) -> 0 | G21: =INDIRECT(G$1&"!"&$B21) -> 7 | H21: =INDIRECT(H$1&"!"&$B21) -> 0 | I21: =INDIRECT(I$1&"!"&$B21) -> 0 | J21: =INDIRECT(J$1&"!"&$B21) -> 0 | K21: =INDIRECT(K$1&"!"&$B21) -> 0 | L21: =INDIRECT(L$1&"!"&$B21) -> 0 | M21: =INDIRECT(M$1&"!"&$B21) -> 0 | ... Q21: =INDIRECT(Q$1&"!"&$B21) -> 0 | R21: =SUM(F21:Q21) -> 7
B22: D212 | D22: 即受注 件数 | F22: =INDIRECT(F$1&"!"&$B22) -> 0 | G22: =INDIRECT(G$1&"!"&$B22) -> 0 | H22: =INDIRECT(H$1&"!"&$B22) -> 0 | I22: =INDIRECT(I$1&"!"&$B22) -> 0 | J22: =INDIRECT(J$1&"!"&$B22) | K22: =INDIRECT(K$1&"!"&$B22) -> 0 | L22: =INDIRECT(L$1&"!"&$B22) | M22: =INDIRECT(M$1&"!"&$B22) -> 0 | ... O22: =INDIRECT(O$1&"!"&$B22) -> 0 | R22: =SUM(F22:Q22) -> 0
B23: D213 | D23: 戻り受注 件数 | F23: =INDIRECT(F$1&"!"&$B23) -> 代表 | G23: =INDIRECT(G$1&"!"&$B23) -> 0.26923077 | H23: =INDIRECT(H$1&"!"&$B23) -> 代表 | I23: =INDIRECT(I$1&"!"&$B23) -> 代表 | J23: =INDIRECT(J$1&"!"&$B23) -> 0 | K23: =INDIRECT(K$1&"!"&$B23) | L23: =INDIRECT(L$1&"!"&$B23) -> 0 | M23: =INDIRECT(M$1&"!"&$B23) | ... Q23: =INDIRECT(Q$1&"!"&$B23) | R23: =SUM(F23:Q23) -> 0.26923077
B24: D214 | D24: 受注率 | F24: =INDIRECT(F$1&"!"&$B24) -> 0 | G24: =INDIRECT(G$1&"!"&$B24) -> 0 | H24: =INDIRECT(H$1&"!"&$B24) -> 0 | I24: =INDIRECT(I$1&"!"&$B24) -> 0 | J24: =INDIRECT(J$1&"!"&$B24) -> 0 | K24: =INDIRECT(K$1&"!"&$B24) -> 0 | L24: =INDIRECT(L$1&"!"&$B24) -> 0 | M24: =INDIRECT(M$1&"!"&$B24) -> 0 | ... Q24: =INDIRECT(Q$1&"!"&$B24) -> 0 | R24: =SUM(R22:R23)/R21 -> 0.038461538
B26: E211 | C26: =設定用!F6 -> 横浜本店 | D26: 面談対応件数 | F26: =INDIRECT(F$1&"!"&$B26) -> 0 | G26: =INDIRECT(G$1&"!"&$B26) -> 4 | H26: =INDIRECT(H$1&"!"&$B26) -> 0 | I26: =INDIRECT(I$1&"!"&$B26) -> 0 | J26: =INDIRECT(J$1&"!"&$B26) -> 0 | K26: =INDIRECT(K$1&"!"&$B26) -> 0 | L26: =INDIRECT(L$1&"!"&$B26) -> 0 | M26: =INDIRECT(M$1&"!"&$B26) -> 0 | ... Q26: =INDIRECT(Q$1&"!"&$B26) -> 0 | R26: =SUM(F26:Q26) -> 4
B27: E212 | D27: 即受注 件数 | F27: =INDIRECT(F$1&"!"&$B27) -> 0 | G27: =INDIRECT(G$1&"!"&$B27) -> 0 | H27: =INDIRECT(H$1&"!"&$B27) -> 0 | I27: =INDIRECT(I$1&"!"&$B27) -> 0 | J27: =INDIRECT(J$1&"!"&$B27) | K27: =INDIRECT(K$1&"!"&$B27) -> 0 | L27: =INDIRECT(L$1&"!"&$B27) | M27: =INDIRECT(M$1&"!"&$B27) -> 0 | ... Q27: =INDIRECT(Q$1&"!"&$B27) -> 0 | R27: =SUM(F27:Q27) -> 0
B28: E213 | D28: 戻り受注 件数 | F28: =INDIRECT(F$1&"!"&$B28) -> 黒田み | G28: =INDIRECT(G$1&"!"&$B28) -> 0.25 | H28: =INDIRECT(H$1&"!"&$B28) -> 黒田み | I28: =INDIRECT(I$1&"!"&$B28) -> 黒田み | J28: =INDIRECT(J$1&"!"&$B28) -> 0 | K28: =INDIRECT(K$1&"!"&$B28) | L28: =INDIRECT(L$1&"!"&$B28) -> 0 | M28: =INDIRECT(M$1&"!"&$B28) | ... Q28: =INDIRECT(Q$1&"!"&$B28) | R28: =SUM(F28:Q28) -> 0.25
B29: E214 | D29: 受注率 | F29: =INDIRECT(F$1&"!"&$B29) -> 0 | G29: =INDIRECT(G$1&"!"&$B29) -> 0 | H29: =INDIRECT(H$1&"!"&$B29) -> 0 | I29: =INDIRECT(I$1&"!"&$B29) -> 0 | J29: =INDIRECT(J$1&"!"&$B29) -> 0 | K29: =INDIRECT(K$1&"!"&$B29) -> 0 | L29: =INDIRECT(L$1&"!"&$B29) -> 0 | M29: =INDIRECT(M$1&"!"&$B29) -> 0 | ... Q29: =INDIRECT(Q$1&"!"&$B29) -> 0 | R29: =SUM(R27:R28)/R26 -> 0.0625
B31: F211 | C31: =設定用!F7 -> 藤沢支店 | D31: 面談対応件数 | F31: =INDIRECT(F$1&"!"&$B31) -> 0 | G31: =INDIRECT(G$1&"!"&$B31) -> 2 | H31: =INDIRECT(H$1&"!"&$B31) -> 0 | I31: =INDIRECT(I$1&"!"&$B31) -> 0 | J31: =INDIRECT(J$1&"!"&$B31) -> 0 | K31: =INDIRECT(K$1&"!"&$B31) -> 0 | L31: =INDIRECT(L$1&"!"&$B31) -> 0 | M31: =INDIRECT(M$1&"!"&$B31) -> 0 | ... Q31: =INDIRECT(Q$1&"!"&$B31) -> 0 | R31: =SUM(F31:Q31) -> 2
B32: F212 | D32: 即受注 件数 | F32: =INDIRECT(F$1&"!"&$B32) -> 0 | G32: =INDIRECT(G$1&"!"&$B32) -> 0 | H32: =INDIRECT(H$1&"!"&$B32) -> 0 | I32: =INDIRECT(I$1&"!"&$B32) -> 0 | J32: =INDIRECT(J$1&"!"&$B32) | K32: =INDIRECT(K$1&"!"&$B32) -> 0 | L32: =INDIRECT(L$1&"!"&$B32) | M32: =INDIRECT(M$1&"!"&$B32) -> 0 | ... Q32: =INDIRECT(Q$1&"!"&$B32) -> 0 | R32: =SUM(F32:Q32) -> 0
B33: F213 | D33: 戻り受注 件数 | F33: =INDIRECT(F$1&"!"&$B33) -> 山田 | G33: =INDIRECT(G$1&"!"&$B33) -> 0.4 | H33: =INDIRECT(H$1&"!"&$B33) -> 山田 | I33: =INDIRECT(I$1&"!"&$B33) -> 山田 | J33: =INDIRECT(J$1&"!"&$B33) -> 0 | K33: =INDIRECT(K$1&"!"&$B33) | L33: =INDIRECT(L$1&"!"&$B33) -> 0 | M33: =INDIRECT(M$1&"!"&$B33) | ... Q33: =INDIRECT(Q$1&"!"&$B33) | R33: =SUM(F33:Q33) -> 0.4
B34: F214 | D34: 受注率 | F34: =INDIRECT(F$1&"!"&$B34) -> 3 | G34: =INDIRECT(G$1&"!"&$B34) -> 0 | H34: =INDIRECT(H$1&"!"&$B34) -> 1 | I34: =INDIRECT(I$1&"!"&$B34) -> 4 | J34: =INDIRECT(J$1&"!"&$B34) -> 0 | K34: =INDIRECT(K$1&"!"&$B34) -> 0 | L34: =INDIRECT(L$1&"!"&$B34) -> 0 | M34: =INDIRECT(M$1&"!"&$B34) -> 0 | ... Q34: =INDIRECT(Q$1&"!"&$B34) -> 0 | R34: =SUM(R32:R33)/R31 -> 0.2
B36: G211 | C36: =設定用!F8 -> 渋谷支店 | D36: 面談対応件数 | F36: =INDIRECT(F$1&"!"&$B36) -> 0 | G36: =INDIRECT(G$1&"!"&$B36) -> 0 | H36: =INDIRECT(H$1&"!"&$B36) -> 0 | I36: =INDIRECT(I$1&"!"&$B36) -> 0 | J36: =INDIRECT(J$1&"!"&$B36) -> 0 | K36: =INDIRECT(K$1&"!"&$B36) -> 0 | L36: =INDIRECT(L$1&"!"&$B36) -> 0 | M36: =INDIRECT(M$1&"!"&$B36) -> 0 | ... Q36: =INDIRECT(Q$1&"!"&$B36) -> 0 | R36: =SUM(F36:Q36) -> 0
B37: G212 | D37: 即受注 件数 | F37: =INDIRECT(F$1&"!"&$B37) -> 0 | G37: =INDIRECT(G$1&"!"&$B37) -> 0 | H37: =INDIRECT(H$1&"!"&$B37) -> 0 | I37: =INDIRECT(I$1&"!"&$B37) -> 0 | J37: =INDIRECT(J$1&"!"&$B37) | K37: =INDIRECT(K$1&"!"&$B37) -> 0 | L37: =INDIRECT(L$1&"!"&$B37) | M37: =INDIRECT(M$1&"!"&$B37) -> 0 | ... Q37: =INDIRECT(Q$1&"!"&$B37) -> 0 | R37: =SUM(F37:Q37) -> 0
B38: G213 | D38: 戻り受注 件数 | F38: =INDIRECT(F$1&"!"&$B38) -> 奥章 | G38: =INDIRECT(G$1&"!"&$B38) -> 0 | H38: =INDIRECT(H$1&"!"&$B38) -> 奥章 | I38: =INDIRECT(I$1&"!"&$B38) -> 奥章 | J38: =INDIRECT(J$1&"!"&$B38) -> 0 | K38: =INDIRECT(K$1&"!"&$B38) | L38: =INDIRECT(L$1&"!"&$B38) -> 0 | M38: =INDIRECT(M$1&"!"&$B38) | ... Q38: =INDIRECT(Q$1&"!"&$B38) | R38: =SUM(F38:Q38) -> 0
B39: G214 | D39: 受注率 | F39: =INDIRECT(F$1&"!"&$B39) -> 0 | G39: =INDIRECT(G$1&"!"&$B39) -> 0 | H39: =INDIRECT(H$1&"!"&$B39) -> 0 | I39: =INDIRECT(I$1&"!"&$B39) -> 0 | J39: =INDIRECT(J$1&"!"&$B39) -> 0 | K39: =INDIRECT(K$1&"!"&$B39) -> 0 | L39: =INDIRECT(L$1&"!"&$B39) -> 0 | M39: =INDIRECT(M$1&"!"&$B39) -> 0 | ... Q39: =INDIRECT(Q$1&"!"&$B39) -> 0 | R39: =SUM(R37:R38)/R36 -> #DIV/0!
B41: H211 | C41: =設定用!F9 -> お客様先 | D41: 面談対応件数 | F41: =INDIRECT(F$1&"!"&$B41) -> 0 | G41: =INDIRECT(G$1&"!"&$B41) -> 0 | H41: =INDIRECT(H$1&"!"&$B41) -> 0 | I41: =INDIRECT(I$1&"!"&$B41) -> 0 | J41: =INDIRECT(J$1&"!"&$B41) -> 0 | K41: =INDIRECT(K$1&"!"&$B41) -> 0 | L41: =INDIRECT(L$1&"!"&$B41) -> 0 | M41: =INDIRECT(M$1&"!"&$B41) -> 0 | ... Q41: =INDIRECT(Q$1&"!"&$B41) -> 0 | R41: =SUM(F41:Q41) -> 0
B42: H212 | D42: 即受注 件数 | F42: =INDIRECT(F$1&"!"&$B42) -> 0 | G42: =INDIRECT(G$1&"!"&$B42) -> 0 | H42: =INDIRECT(H$1&"!"&$B42) -> 0 | I42: =INDIRECT(I$1&"!"&$B42) -> 0 | J42: =INDIRECT(J$1&"!"&$B42) | K42: =INDIRECT(K$1&"!"&$B42) -> 0 | L42: =INDIRECT(L$1&"!"&$B42) | M42: =INDIRECT(M$1&"!"&$B42) -> 0 | ... Q42: =INDIRECT(Q$1&"!"&$B42) -> 0 | R42: =SUM(F42:Q42) -> 0
B43: H213 | D43: 戻り受注 件数 | F43: =INDIRECT(F$1&"!"&$B43) -> 山﨑 | G43: =INDIRECT(G$1&"!"&$B43) | H43: =INDIRECT(H$1&"!"&$B43) -> 山﨑 | I43: =INDIRECT(I$1&"!"&$B43) -> 山﨑 | J43: =INDIRECT(J$1&"!"&$B43) -> 0 | K43: =INDIRECT(K$1&"!"&$B43) | L43: =INDIRECT(L$1&"!"&$B43) -> 0 | M43: =INDIRECT(M$1&"!"&$B43) | ... Q43: =INDIRECT(Q$1&"!"&$B43) | R43: =SUM(F43:Q43) -> 0
B44: H214 | D44: 受注率 | F44: =INDIRECT(F$1&"!"&$B44) -> 0 | G44: =INDIRECT(G$1&"!"&$B44) -> 0 | H44: =INDIRECT(H$1&"!"&$B44) -> 0 | I44: =INDIRECT(I$1&"!"&$B44) -> 0 | J44: =INDIRECT(J$1&"!"&$B44) -> 0 | K44: =INDIRECT(K$1&"!"&$B44) -> 0 | L44: =INDIRECT(L$1&"!"&$B44) -> 0 | M44: =INDIRECT(M$1&"!"&$B44) -> 0 | ... Q44: =INDIRECT(Q$1&"!"&$B44) -> 0 | R44: =SUM(R42:R43)/R41 -> #DIV/0!
B46: I211 | C46: =設定用!F10 -> パートナー先 | D46: 面談対応件数 | F46: =INDIRECT(F$1&"!"&$B46) -> 0 | G46: =INDIRECT(G$1&"!"&$B46) -> 0 | H46: =INDIRECT(H$1&"!"&$B46) -> 0 | I46: =INDIRECT(I$1&"!"&$B46) -> 0 | J46: =INDIRECT(J$1&"!"&$B46) -> 0 | K46: =INDIRECT(K$1&"!"&$B46) -> 0 | L46: =INDIRECT(L$1&"!"&$B46) -> 0 | M46: =INDIRECT(M$1&"!"&$B46) -> 0 | ... Q46: =INDIRECT(Q$1&"!"&$B46) -> 0 | R46: =SUM(F46:Q46) -> 0
B47: I212 | D47: 即受注 件数 | F47: =INDIRECT(F$1&"!"&$B47) -> 0 | G47: =INDIRECT(G$1&"!"&$B47) -> 0 | H47: =INDIRECT(H$1&"!"&$B47) -> 0 | I47: =INDIRECT(I$1&"!"&$B47) -> 0 | J47: =INDIRECT(J$1&"!"&$B47) | K47: =INDIRECT(K$1&"!"&$B47) -> 0 | L47: =INDIRECT(L$1&"!"&$B47) | M47: =INDIRECT(M$1&"!"&$B47) -> 0 | ... Q47: =INDIRECT(Q$1&"!"&$B47) -> 0 | R47: =SUM(F47:Q47) -> 0
B48: I213 | D48: 戻り受注 件数 | F48: =INDIRECT(F$1&"!"&$B48) -> 0 | G48: =INDIRECT(G$1&"!"&$B48) | H48: =INDIRECT(H$1&"!"&$B48) -> 0 | I48: =INDIRECT(I$1&"!"&$B48) -> 0 | J48: =INDIRECT(J$1&"!"&$B48) -> 0 | K48: =INDIRECT(K$1&"!"&$B48) | L48: =INDIRECT(L$1&"!"&$B48) -> 0 | M48: =INDIRECT(M$1&"!"&$B48) | ... Q48: =INDIRECT(Q$1&"!"&$B48) | R48: =SUM(F48:Q48) -> 0
B49: I214 | D49: 受注率 | F49: =INDIRECT(F$1&"!"&$B49) -> 0 | G49: =INDIRECT(G$1&"!"&$B49) -> 0 | H49: =INDIRECT(H$1&"!"&$B49) -> 0 | I49: =INDIRECT(I$1&"!"&$B49) -> 0 | J49: =INDIRECT(J$1&"!"&$B49) -> 0 | K49: =INDIRECT(K$1&"!"&$B49) -> 0 | L49: =INDIRECT(L$1&"!"&$B49) -> 0 | M49: =INDIRECT(M$1&"!"&$B49) -> 0 | ... Q49: =INDIRECT(Q$1&"!"&$B49) -> 0 | R49: =SUM(R47:R48)/R46 -> #DIV/0!
B51: J211 | C51: =設定用!F11 -> その他 | D51: 面談対応件数 | F51: =INDIRECT(F$1&"!"&$B51) -> 0 | G51: =INDIRECT(G$1&"!"&$B51) -> 1 | H51: =INDIRECT(H$1&"!"&$B51) -> 0 | I51: =INDIRECT(I$1&"!"&$B51) -> 0 | J51: =INDIRECT(J$1&"!"&$B51) -> 0 | K51: =INDIRECT(K$1&"!"&$B51) -> 0 | L51: =INDIRECT(L$1&"!"&$B51) -> 0 | M51: =INDIRECT(M$1&"!"&$B51) -> 0 | ... Q51: =INDIRECT(Q$1&"!"&$B51) -> 0 | R51: =SUM(F51:Q51) -> 1
...

Sheet 担当者別受注率集計
C2: 受注率 集計 | F2: 1月 | G2: 2月 | H2: 3月 | I2: 4月 | J2: 5月 | K2: 6月 | L2: 7月 | M2: 8月 | N2: 9月 | O2: 10月 | P2: 11月 | Q2: 12月 | R2: 年間
C3: 総計 | D3: 面談対応件数 | F3: =SUM(F13,F21,F29,F37,F45,F53,F61,F69,F77,F85,F93,F101) -> 1.8333333 | G3: =SUM(G13,G21,G29,G37,G45,G53,G61,G69,G77,G85,G93,G101) -> 3 | H3: =SUM(H13,H21,H29,H37,H45,H53,H61,H69,H77,H85,H93,H101) -> 0.28571429 | I3: =SUM(I13,I21,I29,I37,I45,I53,I61,I69,I77,I85,I93,I101) -> 1.3928571 | J3: =SUM(J13,J21,J29,J37,J45,J53,J61,J69,J77,J85,J93,J101) -> 0 | K3: =SUM(K13,K21,K29,K37,K45,K53,K61,K69,K77,K85,K93,K101) -> 0 | L3: =SUM(L13,L21,L29,L37,L45,L53,L61,L69,L77,L85,L93,L101) -> 0 | M3: =SUM(M13,M21,M29,M37,M45,M53,M61,M69,M77,M85,M93,M101) -> 0 | ... Q3: =SUM(Q13,Q21,Q29,Q37,Q45,Q53,Q61,Q69,Q77,Q85,Q93,Q101) -> 0 | R3: =SUM(F3:Q3) -> 6.5119048
D4: 受注件数 | F4: =SUM(F14,F22,F30,F38,F46,F54,F62,F70,F78,F86,F94,F102) -> 0 | G4: =SUM(G14,G22,G30,G38,G46,G54,G62,G70,G78,G86,G94,G102) -> 2 | H4: =SUM(H14,H22,H30,H38,H46,H54,H62,H70,H78,H86,H94,H102) -> 0 | I4: =SUM(I14,I22,I30,I38,I46,I54,I62,I70,I78,I86,I94,I102) -> 1 | J4: =SUM(J14,J22,J30,J38,J46,J54,J62,J70,J78,J86,J94,J102) -> 0 | K4: =SUM(K14,K22,K30,K38,K46,K54,K62,K70,K78,K86,K94,K102) -> 0 | L4: =SUM(L14,L22,L30,L38,L46,L54,L62,L70,L78,L86,L94,L102) -> 0 | M4: =SUM(M14,M22,M30,M38,M46,M54,M62,M70,M78,M86,M94,M102) -> 0 | ... Q4: =SUM(Q14,Q22,Q30,Q38,Q46,Q54,Q62,Q70,Q78,Q86,Q94,Q102) -> 0 | R4: =SUM(F4:Q4) -> 3
D5: 受注率 | F5: =F4/F3 -> 0 | G5: =G4/G3 -> 0.66666667 | H5: =H4/H3 -> 0 | I5: =I4/I3 -> 0.71794872 | J5: =J4/J3 -> #DIV/0! | K5: =K4/K3 -> #DIV/0! | L5: =L4/L3 -> #DIV/0! | M5: =M4/M3 -> #DIV/0! | ... R5: =R4/R3 -> 0.4606947
D6: 即受注 件数 | F6: =SUM(F16,F24,F32,F40,F48,F56,F64,F72,F80,F88,F96,,F104) -> 0 | G6: =SUM(G16,G24,G32,G40,G48,G56,G64,G72,G80,G88,G96,,G104) -> 2 | H6: =SUM(H16,H24,H32,H40,H48,H56,H64,H72,H80,H88,H96,,H104) -> 0 | I6: =SUM(I16,I24,I32,I40,I48,I56,I64,I72,I80,I88,I96,,I104) -> 1 | J6: =SUM(J16,J24,J32,J40,J48,J56,J64,J72,J80,J88,J96,,J104) -> 0 | K6: =SUM(K16,K24,K32,K40,K48,K56,K64,K72,K80,K88,K96,,K104) -> 0 | L6: =SUM(L16,L24,L32,L40,L48,L56,L64,L72,L80,L88,L96,,L104) -> 0 | M6: =SUM(M16,M24,M32,M40,M48,M56,M64,M72,M80,M88,M96,,M104) -> 0 | ... Q6: =SUM(Q16,Q24,Q32,Q40,Q48,Q56,Q64,Q72,Q80,Q88,Q96,,Q104) -> 0 | R6: =SUM(F6:Q6) -> 3
D7: 即受注率 | F7: =F6/F$3 -> 0 | G7: =G6/G$3 -> 0.66666667 | H7: =H6/H$3 -> 0 | I7: =I6/I$3 -> 0.71794872 | J7: =J6/J$3 -> #DIV/0! | K7: =K6/K$3 -> #DIV/0! | L7: =L6/L$3 -> #DIV/0! | M7: =M6/M$3 -> #DIV/0! | ... Q7: =Q6/Q$3 -> #DIV/0! | R7: =R6/R3 -> 0.4606947
D8: 戻り受注 件数 | F8: =SUM(F18,F26,F34,F42,F50,F58,F66,F74,F82,F90,F98,F106) -> 3 | G8: =SUM(G18,G26,G34,G42,G50,G58,G66,G74,G82,G90,G98,G106) -> 0 | H8: =SUM(H18,H26,H34,H42,H50,H58,H66,H74,H82,H90,H98,H106) -> 1 | I8: =SUM(I18,I26,I34,I42,I50,I58,I66,I74,I82,I90,I98,I106) -> 2 | J8: =SUM(J18,J26,J34,J42,J50,J58,J66,J74,J82,J90,J98,J106) -> 0 | K8: =SUM(K18,K26,K34,K42,K50,K58,K66,K74,K82,K90,K98,K106) -> 0 | L8: =SUM(L18,L26,L34,L42,L50,L58,L66,L74,L82,L90,L98,L106) -> 0 | M8: =SUM(M18,M26,M34,M42,M50,M58,M66,M74,M82,M90,M98,M106) -> 0 | ... Q8: =SUM(Q18,Q26,Q34,Q42,Q50,Q58,Q66,Q74,Q82,Q90,Q98,Q106) -> 0 | R8: =SUM(F8:Q8) -> 6
D9: 戻り受注率 | F9: =F8/F$3 -> 1.6363636 | G9: =G8/G$3 -> 0 | H9: =H8/H$3 -> 3.5 | I9: =I8/I$3 -> 1.4358974 | J9: =J8/J$3 -> #DIV/0! | K9: =K8/K$3 -> #DIV/0! | L9: =L8/L$3 -> #DIV/0! | M9: =M8/M$3 -> #DIV/0! | ... Q9: =Q8/Q$3 -> #DIV/0! | R9: =R8/R3 -> 0.9213894
F11: 1月 | G11: 2月 | H11: 3月 | I11: 4月 | J11: 5月 | K11: 6月 | L11: 7月 | M11: 8月 | N11: 9月 | O11: 10月 | P11: 11月 | Q11: 12月
C12: 受注率 集計 | F12: 1月 | G12: 2月 | H12: 3月 | I12: 4月 | J12: 5月 | K12: 6月 | L12: 7月 | M12: 8月 | N12: 9月 | O12: 10月 | P12: 11月 | Q12: 12月 | R12: 年間
B13: D218 | C13: =設定用!J6 -> 代表 | D13: 面談対応件数 | F13: =INDIRECT(F$11&"!"&$B13) -> - | G13: =INDIRECT(G$11&"!"&$B13) -> 0 | H13: =INDIRECT(H$11&"!"&$B13) -> - | I13: =INDIRECT(I$11&"!"&$B13) -> - | J13: =INDIRECT(J$11&"!"&$B13) -> - | K13: =INDIRECT(K$11&"!"&$B13) -> 0 | L13: =INDIRECT(L$11&"!"&$B13) -> - | M13: =INDIRECT(M$11&"!"&$B13) -> 0 | ... Q13: =INDIRECT(Q$11&"!"&$B13) -> 0 | R13: =SUM(F13:Q13) -> 0
B14: D219 | D14: 受注件数 | F14: =INDIRECT(F$11&"!"&$B14) -> 0 | G14: =INDIRECT(G$11&"!"&$B14) -> - | H14: =INDIRECT(H$11&"!"&$B14) -> 0 | I14: =INDIRECT(I$11&"!"&$B14) -> 0 | J14: =INDIRECT(J$11&"!"&$B14) -> 0 | K14: =INDIRECT(K$11&"!"&$B14) -> - | L14: =INDIRECT(L$11&"!"&$B14) -> 0 | M14: =INDIRECT(M$11&"!"&$B14) -> - | ... Q14: =INDIRECT(Q$11&"!"&$B14) -> - | R14: =SUM(F14:Q14) -> 0
B15: D220 | D15: 受注率 | F15: =INDIRECT(F$11&"!"&$B15) -> - | G15: =INDIRECT(G$11&"!"&$B15) -> 0 | H15: =INDIRECT(H$11&"!"&$B15) -> - | I15: =INDIRECT(I$11&"!"&$B15) -> - | J15: =INDIRECT(J$11&"!"&$B15) -> - | K15: =INDIRECT(K$11&"!"&$B15) -> 0 | L15: =INDIRECT(L$11&"!"&$B15) -> - | M15: =INDIRECT(M$11&"!"&$B15) -> 0 | ... Q15: =INDIRECT(Q$11&"!"&$B15) -> 0 | R15: =R14/R13 -> #DIV/0!
B16: D221 | D16: 即受注 件数 | F16: =INDIRECT(F$11&"!"&$B16) -> 0 | G16: =INDIRECT(G$11&"!"&$B16) -> - | H16: =INDIRECT(H$11&"!"&$B16) -> 0 | I16: =INDIRECT(I$11&"!"&$B16) -> 0 | J16: =INDIRECT(J$11&"!"&$B16) -> 0 | K16: =INDIRECT(K$11&"!"&$B16) -> - | L16: =INDIRECT(L$11&"!"&$B16) -> 0 | M16: =INDIRECT(M$11&"!"&$B16) -> - | ... Q16: =INDIRECT(Q$11&"!"&$B16) -> - | R16: =SUM(F16:Q16) -> 0
B17: D222 | D17: 即受注率 | F17: =INDIRECT(F$11&"!"&$B17) -> - | G17: =INDIRECT(G$11&"!"&$B17) -> 0 | H17: =INDIRECT(H$11&"!"&$B17) -> - | I17: =INDIRECT(I$11&"!"&$B17) -> - | J17: =INDIRECT(J$11&"!"&$B17) -> - | K17: =INDIRECT(K$11&"!"&$B17) -> 0 | L17: =INDIRECT(L$11&"!"&$B17) -> - | M17: =INDIRECT(M$11&"!"&$B17) -> 0 | ... Q17: =INDIRECT(Q$11&"!"&$B17) -> 0 | R17: =R16/R13 -> #DIV/0!
B18: D223 | D18: 戻り受注 件数 | F18: =INDIRECT(F$11&"!"&$B18) -> 0 | G18: =INDIRECT(G$11&"!"&$B18) -> - | H18: =INDIRECT(H$11&"!"&$B18) -> 0 | I18: =INDIRECT(I$11&"!"&$B18) -> 0 | J18: =INDIRECT(J$11&"!"&$B18) -> 0 | K18: =INDIRECT(K$11&"!"&$B18) -> - | L18: =INDIRECT(L$11&"!"&$B18) -> 0 | M18: =INDIRECT(M$11&"!"&$B18) -> - | ... Q18: =INDIRECT(Q$11&"!"&$B18) -> - | R18: =SUM(F18:Q18) -> 0
B19: D224 | D19: 戻り受注率 | F19: =INDIRECT(F$11&"!"&$B19) -> - | G19: =INDIRECT(G$11&"!"&$B19) -> 0 | H19: =INDIRECT(H$11&"!"&$B19) -> - | I19: =INDIRECT(I$11&"!"&$B19) -> - | J19: =INDIRECT(J$11&"!"&$B19) -> - | K19: =INDIRECT(K$11&"!"&$B19) -> 0 | L19: =INDIRECT(L$11&"!"&$B19) -> - | M19: =INDIRECT(M$11&"!"&$B19) -> 0 | ... Q19: =INDIRECT(Q$11&"!"&$B19) -> 0 | R19: =R18/R13 -> #DIV/0!
B21: E218 | C21: =設定用!J7 -> 黒田み | D21: 面談対応件数 | F21: =INDIRECT(F$11&"!"&$B21) -> - | G21: =INDIRECT(G$11&"!"&$B21) -> 0 | H21: =INDIRECT(H$11&"!"&$B21) -> - | I21: =INDIRECT(I$11&"!"&$B21) -> - | J21: =INDIRECT(J$11&"!"&$B21) -> - | K21: =INDIRECT(K$11&"!"&$B21) -> 0 | L21: =INDIRECT(L$11&"!"&$B21) -> - | M21: =INDIRECT(M$11&"!"&$B21) -> 0 | ... Q21: =INDIRECT(Q$11&"!"&$B21) -> 0 | R21: =SUM(F21:Q21) -> 0
B22: E219 | D22: 受注件数 | F22: =INDIRECT(F$11&"!"&$B22) -> 0 | G22: =INDIRECT(G$11&"!"&$B22) -> - | H22: =INDIRECT(H$11&"!"&$B22) -> 0 | I22: =INDIRECT(I$11&"!"&$B22) -> 0 | J22: =INDIRECT(J$11&"!"&$B22) -> 0 | K22: =INDIRECT(K$11&"!"&$B22) -> - | L22: =INDIRECT(L$11&"!"&$B22) -> 0 | M22: =INDIRECT(M$11&"!"&$B22) -> - | ... Q22: =INDIRECT(Q$11&"!"&$B22) -> - | R22: =SUM(F22:Q22) -> 0
B23: E220 | D23: 受注率 | F23: =INDIRECT(F$11&"!"&$B23) -> - | G23: =INDIRECT(G$11&"!"&$B23) -> 0 | H23: =INDIRECT(H$11&"!"&$B23) -> - | I23: =INDIRECT(I$11&"!"&$B23) -> - | J23: =INDIRECT(J$11&"!"&$B23) -> - | K23: =INDIRECT(K$11&"!"&$B23) -> 0 | L23: =INDIRECT(L$11&"!"&$B23) -> - | M23: =INDIRECT(M$11&"!"&$B23) -> 0 | ... Q23: =INDIRECT(Q$11&"!"&$B23) -> 0 | R23: =R22/R21 -> #DIV/0!
B24: E221 | D24: 即受注 件数 | F24: =INDIRECT(F$11&"!"&$B24) -> 0 | G24: =INDIRECT(G$11&"!"&$B24) -> - | H24: =INDIRECT(H$11&"!"&$B24) -> 0 | I24: =INDIRECT(I$11&"!"&$B24) -> 0 | J24: =INDIRECT(J$11&"!"&$B24) -> 0 | K24: =INDIRECT(K$11&"!"&$B24) -> - | L24: =INDIRECT(L$11&"!"&$B24) -> 0 | M24: =INDIRECT(M$11&"!"&$B24) -> - | ... Q24: =INDIRECT(Q$11&"!"&$B24) -> - | R24: =SUM(F24:Q24) -> 0
B25: E222 | D25: 即受注率 | F25: =INDIRECT(F$11&"!"&$B25) -> - | G25: =INDIRECT(G$11&"!"&$B25) -> 0 | H25: =INDIRECT(H$11&"!"&$B25) -> - | I25: =INDIRECT(I$11&"!"&$B25) -> - | J25: =INDIRECT(J$11&"!"&$B25) -> - | K25: =INDIRECT(K$11&"!"&$B25) -> 0 | L25: =INDIRECT(L$11&"!"&$B25) -> - | M25: =INDIRECT(M$11&"!"&$B25) -> 0 | ... Q25: =INDIRECT(Q$11&"!"&$B25) -> 0 | R25: =R24/R21 -> #DIV/0!
B26: E223 | D26: 戻り受注 件数 | F26: =INDIRECT(F$11&"!"&$B26) -> 0 | G26: =INDIRECT(G$11&"!"&$B26) -> - | H26: =INDIRECT(H$11&"!"&$B26) -> 0 | I26: =INDIRECT(I$11&"!"&$B26) -> 0 | J26: =INDIRECT(J$11&"!"&$B26) -> 0 | K26: =INDIRECT(K$11&"!"&$B26) -> - | L26: =INDIRECT(L$11&"!"&$B26) -> 0 | M26: =INDIRECT(M$11&"!"&$B26) -> - | ... Q26: =INDIRECT(Q$11&"!"&$B26) -> - | R26: =SUM(F26:Q26) -> 0
B27: E224 | D27: 戻り受注率 | F27: =INDIRECT(F$11&"!"&$B27) -> - | G27: =INDIRECT(G$11&"!"&$B27) -> 0 | H27: =INDIRECT(H$11&"!"&$B27) -> - | I27: =INDIRECT(I$11&"!"&$B27) -> - | J27: =INDIRECT(J$11&"!"&$B27) -> - | K27: =INDIRECT(K$11&"!"&$B27) -> 0 | L27: =INDIRECT(L$11&"!"&$B27) -> - | M27: =INDIRECT(M$11&"!"&$B27) -> 0 | ... Q27: =INDIRECT(Q$11&"!"&$B27) -> 0 | R27: =R26/R21 -> #DIV/0!
B29: F218 | C29: =設定用!J8 -> 山田 | D29: 面談対応件数 | F29: =INDIRECT(F$11&"!"&$B29) -> 0.66666667 | G29: =INDIRECT(G$11&"!"&$B29) -> 1 | H29: =INDIRECT(H$11&"!"&$B29) -> 0 | I29: =INDIRECT(I$11&"!"&$B29) -> 0 | J29: =INDIRECT(J$11&"!"&$B29) -> - | K29: =INDIRECT(K$11&"!"&$B29) -> 0 | L29: =INDIRECT(L$11&"!"&$B29) -> - | M29: =INDIRECT(M$11&"!"&$B29) -> 0 | ... Q29: =INDIRECT(Q$11&"!"&$B29) -> 0 | R29: =SUM(F29:Q29) -> 1.6666667
B30: F219 | D30: 受注件数 | F30: =INDIRECT(F$11&"!"&$B30) -> 0 | G30: =INDIRECT(G$11&"!"&$B30) -> 1 | H30: =INDIRECT(H$11&"!"&$B30) -> 0 | I30: =INDIRECT(I$11&"!"&$B30) -> 1 | J30: =INDIRECT(J$11&"!"&$B30) -> 0 | K30: =INDIRECT(K$11&"!"&$B30) -> - | L30: =INDIRECT(L$11&"!"&$B30) -> 0 | M30: =INDIRECT(M$11&"!"&$B30) -> - | ... Q30: =INDIRECT(Q$11&"!"&$B30) -> - | R30: =SUM(F30:Q30) -> 2
B31: F220 | D31: 受注率 | F31: =INDIRECT(F$11&"!"&$B31) -> 0 | G31: =INDIRECT(G$11&"!"&$B31) -> 1 | H31: =INDIRECT(H$11&"!"&$B31) -> 0 | I31: =INDIRECT(I$11&"!"&$B31) -> 0.25 | J31: =INDIRECT(J$11&"!"&$B31) -> - | K31: =INDIRECT(K$11&"!"&$B31) -> 0 | L31: =INDIRECT(L$11&"!"&$B31) -> - | M31: =INDIRECT(M$11&"!"&$B31) -> 0 | ... Q31: =INDIRECT(Q$11&"!"&$B31) -> 0 | R31: =R30/R29 -> 1.2
B32: F221 | D32: 即受注 件数 | F32: =INDIRECT(F$11&"!"&$B32) -> 0 | G32: =INDIRECT(G$11&"!"&$B32) -> 1 | H32: =INDIRECT(H$11&"!"&$B32) -> 0 | I32: =INDIRECT(I$11&"!"&$B32) -> 0 | J32: =INDIRECT(J$11&"!"&$B32) -> 0 | K32: =INDIRECT(K$11&"!"&$B32) -> - | L32: =INDIRECT(L$11&"!"&$B32) -> 0 | M32: =INDIRECT(M$11&"!"&$B32) -> - | ... Q32: =INDIRECT(Q$11&"!"&$B32) -> - | R32: =SUM(F32:Q32) -> 1
B33: F222 | D33: 即受注率 | F33: =INDIRECT(F$11&"!"&$B33) -> 0 | G33: =INDIRECT(G$11&"!"&$B33) -> 0 | H33: =INDIRECT(H$11&"!"&$B33) -> 0 | I33: =INDIRECT(I$11&"!"&$B33) -> 0 | J33: =INDIRECT(J$11&"!"&$B33) -> - | K33: =INDIRECT(K$11&"!"&$B33) -> 0 | L33: =INDIRECT(L$11&"!"&$B33) -> - | M33: =INDIRECT(M$11&"!"&$B33) -> 0 | ... Q33: =INDIRECT(Q$11&"!"&$B33) -> 0 | R33: =R32/R29 -> 0.6
B34: F223 | D34: 戻り受注 件数 | F34: =INDIRECT(F$11&"!"&$B34) -> 1 | G34: =INDIRECT(G$11&"!"&$B34) -> 0 | H34: =INDIRECT(H$11&"!"&$B34) -> 0 | I34: =INDIRECT(I$11&"!"&$B34) -> 2 | J34: =INDIRECT(J$11&"!"&$B34) -> 0 | K34: =INDIRECT(K$11&"!"&$B34) -> - | L34: =INDIRECT(L$11&"!"&$B34) -> 0 | M34: =INDIRECT(M$11&"!"&$B34) -> - | ... Q34: =INDIRECT(Q$11&"!"&$B34) -> - | R34: =SUM(F34:Q34) -> 3
B35: F224 | D35: 戻り受注率 | F35: =INDIRECT(F$11&"!"&$B35) -> 0.33333333 | G35: =INDIRECT(G$11&"!"&$B35) -> 0 | H35: =INDIRECT(H$11&"!"&$B35) -> 0 | I35: =INDIRECT(I$11&"!"&$B35) -> 0.5 | J35: =INDIRECT(J$11&"!"&$B35) -> - | K35: =INDIRECT(K$11&"!"&$B35) -> 0 | L35: =INDIRECT(L$11&"!"&$B35) -> - | M35: =INDIRECT(M$11&"!"&$B35) -> 0 | ... Q35: =INDIRECT(Q$11&"!"&$B35) -> 0 | R35: =R34/R29 -> 1.8
B37: G218 | C37: =設定用!J9 -> 奥章 | D37: 面談対応件数 | F37: =INDIRECT(F$11&"!"&$B37) -> - | G37: =INDIRECT(G$11&"!"&$B37) -> 0 | H37: =INDIRECT(H$11&"!"&$B37) -> - | I37: =INDIRECT(I$11&"!"&$B37) -> - | J37: =INDIRECT(J$11&"!"&$B37) -> - | K37: =INDIRECT(K$11&"!"&$B37) -> 0 | L37: =INDIRECT(L$11&"!"&$B37) -> - | M37: =INDIRECT(M$11&"!"&$B37) -> 0 | ... Q37: =INDIRECT(Q$11&"!"&$B37) -> 0 | R37: =SUM(F37:Q37) -> 0
B38: G219 | D38: 受注件数 | F38: =INDIRECT(F$11&"!"&$B38) -> 0 | G38: =INDIRECT(G$11&"!"&$B38) -> - | H38: =INDIRECT(H$11&"!"&$B38) -> 0 | I38: =INDIRECT(I$11&"!"&$B38) -> 0 | J38: =INDIRECT(J$11&"!"&$B38) -> 0 | K38: =INDIRECT(K$11&"!"&$B38) -> - | L38: =INDIRECT(L$11&"!"&$B38) -> 0 | M38: =INDIRECT(M$11&"!"&$B38) -> - | ... Q38: =INDIRECT(Q$11&"!"&$B38) -> - | R38: =SUM(F38:Q38) -> 0
B39: G220 | D39: 受注率 | F39: =INDIRECT(F$11&"!"&$B39) -> - | G39: =INDIRECT(G$11&"!"&$B39) -> 0 | H39: =INDIRECT(H$11&"!"&$B39) -> - | I39: =INDIRECT(I$11&"!"&$B39) -> - | J39: =INDIRECT(J$11&"!"&$B39) -> - | K39: =INDIRECT(K$11&"!"&$B39) -> 0 | L39: =INDIRECT(L$11&"!"&$B39) -> - | M39: =INDIRECT(M$11&"!"&$B39) -> 0 | ... Q39: =INDIRECT(Q$11&"!"&$B39) -> 0 | R39: =R38/R37 -> #DIV/0!
B40: G221 | D40: 即受注 件数 | F40: =INDIRECT(F$11&"!"&$B40) -> 0 | G40: =INDIRECT(G$11&"!"&$B40) -> - | H40: =INDIRECT(H$11&"!"&$B40) -> 0 | I40: =INDIRECT(I$11&"!"&$B40) -> 0 | J40: =INDIRECT(J$11&"!"&$B40) -> 0 | K40: =INDIRECT(K$11&"!"&$B40) -> - | L40: =INDIRECT(L$11&"!"&$B40) -> 0 | M40: =INDIRECT(M$11&"!"&$B40) -> - | ... Q40: =INDIRECT(Q$11&"!"&$B40) -> - | R40: =SUM(F40:Q40) -> 0
B41: G222 | D41: 即受注率 | F41: =INDIRECT(F$11&"!"&$B41) -> - | G41: =INDIRECT(G$11&"!"&$B41) -> 0 | H41: =INDIRECT(H$11&"!"&$B41) -> - | I41: =INDIRECT(I$11&"!"&$B41) -> - | J41: =INDIRECT(J$11&"!"&$B41) -> - | K41: =INDIRECT(K$11&"!"&$B41) -> 0 | L41: =INDIRECT(L$11&"!"&$B41) -> - | M41: =INDIRECT(M$11&"!"&$B41) -> 0 | ... Q41: =INDIRECT(Q$11&"!"&$B41) -> 0 | R41: =R40/R37 -> #DIV/0!
B42: G223 | D42: 戻り受注 件数 | F42: =INDIRECT(F$11&"!"&$B42) -> 0 | G42: =INDIRECT(G$11&"!"&$B42) -> - | H42: =INDIRECT(H$11&"!"&$B42) -> 0 | I42: =INDIRECT(I$11&"!"&$B42) -> 0 | J42: =INDIRECT(J$11&"!"&$B42) -> 0 | K42: =INDIRECT(K$11&"!"&$B42) -> - | L42: =INDIRECT(L$11&"!"&$B42) -> 0 | M42: =INDIRECT(M$11&"!"&$B42) -> - | ... Q42: =INDIRECT(Q$11&"!"&$B42) -> - | R42: =SUM(F42:Q42) -> 0
B43: G224 | D43: 戻り受注率 | F43: =INDIRECT(F$11&"!"&$B43) -> - | G43: =INDIRECT(G$11&"!"&$B43) -> 0 | H43: =INDIRECT(H$11&"!"&$B43) -> - | I43: =INDIRECT(I$11&"!"&$B43) -> - | J43: =INDIRECT(J$11&"!"&$B43) -> - | K43: =INDIRECT(K$11&"!"&$B43) -> 0 | L43: =INDIRECT(L$11&"!"&$B43) -> - | M43: =INDIRECT(M$11&"!"&$B43) -> 0 | ... Q43: =INDIRECT(Q$11&"!"&$B43) -> 0 | R43: =R42/R37 -> #DIV/0!
B45: H218 | C45: =設定用!J10 -> 山﨑 | D45: 面談対応件数 | F45: =INDIRECT(F$11&"!"&$B45) -> - | G45: =INDIRECT(G$11&"!"&$B45) -> 2 | H45: =INDIRECT(H$11&"!"&$B45) -> - | I45: =INDIRECT(I$11&"!"&$B45) -> - | J45: =INDIRECT(J$11&"!"&$B45) -> - | K45: =INDIRECT(K$11&"!"&$B45) -> 0 | L45: =INDIRECT(L$11&"!"&$B45) -> - | M45: =INDIRECT(M$11&"!"&$B45) -> 0 | ... Q45: =INDIRECT(Q$11&"!"&$B45) -> 0 | R45: =SUM(F45:Q45) -> 2
B46: H219 | D46: 受注件数 | F46: =INDIRECT(F$11&"!"&$B46) -> 0 | G46: =INDIRECT(G$11&"!"&$B46) -> 1 | H46: =INDIRECT(H$11&"!"&$B46) -> 0 | I46: =INDIRECT(I$11&"!"&$B46) -> 0 | J46: =INDIRECT(J$11&"!"&$B46) -> 0 | K46: =INDIRECT(K$11&"!"&$B46) -> - | L46: =INDIRECT(L$11&"!"&$B46) -> 0 | M46: =INDIRECT(M$11&"!"&$B46) -> - | ... Q46: =INDIRECT(Q$11&"!"&$B46) -> - | R46: =SUM(F46:Q46) -> 1
...

Sheet 案件別受注率集計
C2: 受注率 集計 | F2: 1月 | G2: 2月 | H2: 3月 | I2: 4月 | J2: 5月 | K2: 6月 | L2: 7月 | M2: 8月 | N2: 9月 | O2: 10月 | P2: 11月 | Q2: 12月 | R2: 年間
C3: 総計 | D3: 面談対応件数 | F3: =SUM(F13,F21,F29,F37,F45,F53,F61,F69,F77,F85) -> 2.0939394 | G3: =SUM(G13,G21,G29,G37,G45,G53,G61,G69,G77,G85) -> 7 | H3: =SUM(H13,H21,H29,H37,H45,H53,H61,H69,H77,H85) -> 2.7670455 | I3: =SUM(I13,I21,I29,I37,I45,I53,I61,I69,I77,I85) -> 1.4393939 | J3: =SUM(J13,J21,J29,J37,J45,J53,J61,J69,J77,J85) -> 0 | K3: =SUM(K13,K21,K29,K37,K45,K53,K61,K69,K77,K85) -> 0 | L3: =SUM(L13,L21,L29,L37,L45,L53,L61,L69,L77,L85) -> 0 | M3: =SUM(M13,M21,M29,M37,M45,M53,M61,M69,M77,M85) -> 0 | ... Q3: =SUM(Q13,Q21,Q29,Q37,Q45,Q53,Q61,Q69,Q77,Q85) -> 0 | R3: =SUM(F3:Q3) -> 13.300379
D4: 受注件数 | F4: =SUM(F14,F22,F30,F38,F46,F54,F62,F70,F78,F86) -> 4 | G4: =SUM(G14,G22,G30,G38,G46,G54,G62,G70,G78,G86) -> 1.2357143 | H4: =SUM(H14,H22,H30,H38,H46,H54,H62,H70,H78,H86) -> 2 | I4: =SUM(I14,I22,I30,I38,I46,I54,I62,I70,I78,I86) -> 2 | J4: =SUM(J14,J22,J30,J38,J46,J54,J62,J70,J78,J86) -> 0 | K4: =SUM(K14,K22,K30,K38,K46,K54,K62,K70,K78,K86) -> 0 | L4: =SUM(L14,L22,L30,L38,L46,L54,L62,L70,L78,L86) -> 0 | M4: =SUM(M14,M22,M30,M38,M46,M54,M62,M70,M78,M86) -> 0 | ... Q4: =SUM(Q14,Q22,Q30,Q38,Q46,Q54,Q62,Q70,Q78,Q86) -> 0 | R4: =SUM(F4:Q4) -> 9.2357143
D5: 受注率 | F5: =F4/F3 -> 1.910275 | G5: =G4/G3 -> 0.17653061 | H5: =H4/H3 -> 0.72279261 | I5: =I4/I3 -> 1.3894737 | J5: =J4/J3 -> #DIV/0! | K5: =K4/K3 -> #DIV/0! | L5: =L4/L3 -> #DIV/0! | M5: =M4/M3 -> #DIV/0! | ... R5: =R4/R3 -> 0.69439483
D6: 即受注 件数 | F6: =SUM(F16,F24,F32,F40,F48,F56,F64,F72,F80,F88) -> 2 | G6: =SUM(G16,G24,G32,G40,G48,G56,G64,G72,G80,G88) -> 0.91428571 | H6: =SUM(H16,H24,H32,H40,H48,H56,H64,H72,H80,H88) -> 3 | I6: =SUM(I16,I24,I32,I40,I48,I56,I64,I72,I80,I88) -> 3 | J6: =SUM(J16,J24,J32,J40,J48,J56,J64,J72,J80,J88) -> 0 | K6: =SUM(K16,K24,K32,K40,K48,K56,K64,K72,K80,K88) -> 0 | L6: =SUM(L16,L24,L32,L40,L48,L56,L64,L72,L80,L88) -> 0 | M6: =SUM(M16,M24,M32,M40,M48,M56,M64,M72,M80,M88) -> 0 | ... Q6: =SUM(Q16,Q24,Q32,Q40,Q48,Q56,Q64,Q72,Q80,Q88) -> 0 | R6: =SUM(F6:Q6) -> 8.9142857
D7: 即受注率 | F7: =F6/F$3 -> 0.95513748 | G7: =G6/G$3 -> 0.13061224 | H7: =H6/H$3 -> 1.0841889 | I7: =I6/I$3 -> 2.0842105 | J7: =J6/J$3 -> #DIV/0! | K7: =K6/K$3 -> #DIV/0! | L7: =L6/L$3 -> #DIV/0! | M7: =M6/M$3 -> #DIV/0! | ... Q7: =Q6/Q$3 -> #DIV/0! | R7: =R6/R3 -> 0.67022796
D8: 戻り受注 件数 | F8: =SUM(F18,F26,F34,F42,F50,F58,F66,F74,F82,F90) -> 12 | G8: =SUM(G18,G26,G34,G42,G50,G58,G66,G74,G82,G90) -> 0 | H8: =SUM(H18,H26,H34,H42,H50,H58,H66,H74,H82,H90) -> 12 | I8: =SUM(I18,I26,I34,I42,I50,I58,I66,I74,I82,I90) -> 11 | J8: =SUM(J18,J26,J34,J42,J50,J58,J66,J74,J82,J90) -> 0 | K8: =SUM(K18,K26,K34,K42,K50,K58,K66,K74,K82,K90) -> 0 | L8: =SUM(L18,L26,L34,L42,L50,L58,L66,L74,L82,L90) -> 0 | M8: =SUM(M18,M26,M34,M42,M50,M58,M66,M74,M82,M90) -> 0 | ... Q8: =SUM(Q18,Q26,Q34,Q42,Q50,Q58,Q66,Q74,Q82,Q90) -> 0 | R8: =SUM(F8:Q8) -> 35
D9: 戻り受注率 | F9: =F8/F$3 -> 5.7308249 | G9: =G8/G$3 -> 0 | H9: =H8/H$3 -> 4.3367556 | I9: =I8/I$3 -> 7.6421053 | J9: =J8/J$3 -> #DIV/0! | K9: =K8/K$3 -> #DIV/0! | L9: =L8/L$3 -> #DIV/0! | M9: =M8/M$3 -> #DIV/0! | ... Q9: =Q8/Q$3 -> #DIV/0! | R9: =R8/R3 -> 2.631504
F11: 1月 | G11: 2月 | H11: 3月 | I11: 4月 | J11: 5月 | K11: 6月 | L11: 7月 | M11: 8月 | N11: 9月 | O11: 10月 | P11: 11月 | Q11: 12月
C12: 受注率 集計 | F12: 1月 | G12: 2月 | H12: 3月 | I12: 4月 | J12: 5月 | K12: 6月 | L12: 7月 | M12: 8月 | N12: 9月 | O12: 10月 | P12: 11月 | Q12: 12月 | R12: 年間
B13: D257 | C13: =設定用!D6 -> 相続手続き | D13: 面談対応件数 | F13: =INDIRECT(F$11&"!"&$B13) -> 0.36363636 | G13: =INDIRECT(G$11&"!"&$B13) -> 2 | H13: =INDIRECT(H$11&"!"&$B13) -> 0.27272727 | I13: =INDIRECT(I$11&"!"&$B13) -> 0.090909091 | J13: =INDIRECT(J$11&"!"&$B13) -> - | K13: =INDIRECT(K$11&"!"&$B13) -> 0 | L13: =INDIRECT(L$11&"!"&$B13) -> - | M13: =INDIRECT(M$11&"!"&$B13) -> 0 | ... Q13: =INDIRECT(Q$11&"!"&$B13) -> 0 | R13: =SUM(F13:Q13) -> 2.7272727
B14: D258 | D14: 受注件数 | F14: =INDIRECT(F$11&"!"&$B14) -> 0 | G14: =INDIRECT(G$11&"!"&$B14) -> 0.28571429 | H14: =INDIRECT(H$11&"!"&$B14) -> 1 | I14: =INDIRECT(I$11&"!"&$B14) -> 1 | J14: =INDIRECT(J$11&"!"&$B14) -> 0 | K14: =INDIRECT(K$11&"!"&$B14) -> - | L14: =INDIRECT(L$11&"!"&$B14) -> 0 | M14: =INDIRECT(M$11&"!"&$B14) -> - | ... Q14: =INDIRECT(Q$11&"!"&$B14) -> - | R14: =SUM(F14:Q14) -> 2.2857143
B15: D259 | D15: 受注率 | F15: =INDIRECT(F$11&"!"&$B15) -> 0 | G15: =INDIRECT(G$11&"!"&$B15) -> 2 | H15: =INDIRECT(H$11&"!"&$B15) -> 0.090909091 | I15: =INDIRECT(I$11&"!"&$B15) -> 0.090909091 | J15: =INDIRECT(J$11&"!"&$B15) -> - | K15: =INDIRECT(K$11&"!"&$B15) -> 0 | L15: =INDIRECT(L$11&"!"&$B15) -> - | M15: =INDIRECT(M$11&"!"&$B15) -> 0 | ... Q15: =INDIRECT(Q$11&"!"&$B15) -> 0 | R15: =R14/R13 -> 0.83809524
B16: D260 | D16: 即受注 件数 | F16: =INDIRECT(F$11&"!"&$B16) -> 1 | G16: =INDIRECT(G$11&"!"&$B16) -> 0.28571429 | H16: =INDIRECT(H$11&"!"&$B16) -> 1 | I16: =INDIRECT(I$11&"!"&$B16) -> 0 | J16: =INDIRECT(J$11&"!"&$B16) -> 0 | K16: =INDIRECT(K$11&"!"&$B16) -> - | L16: =INDIRECT(L$11&"!"&$B16) -> 0 | M16: =INDIRECT(M$11&"!"&$B16) -> - | ... Q16: =INDIRECT(Q$11&"!"&$B16) -> - | R16: =SUM(F16:Q16) -> 2.2857143
B17: D261 | D17: 即受注率 | F17: =INDIRECT(F$11&"!"&$B17) -> 0.090909091 | G17: =INDIRECT(G$11&"!"&$B17) -> 0 | H17: =INDIRECT(H$11&"!"&$B17) -> 0.090909091 | I17: =INDIRECT(I$11&"!"&$B17) -> 0 | J17: =INDIRECT(J$11&"!"&$B17) -> - | K17: =INDIRECT(K$11&"!"&$B17) -> 0 | L17: =INDIRECT(L$11&"!"&$B17) -> - | M17: =INDIRECT(M$11&"!"&$B17) -> 0 | ... Q17: =INDIRECT(Q$11&"!"&$B17) -> 0 | R17: =R16/R13 -> 0.83809524
B18: D262 | D18: 戻り受注 件数 | F18: =INDIRECT(F$11&"!"&$B18) -> 4 | G18: =INDIRECT(G$11&"!"&$B18) -> 0 | H18: =INDIRECT(H$11&"!"&$B18) -> 3 | I18: =INDIRECT(I$11&"!"&$B18) -> 3 | J18: =INDIRECT(J$11&"!"&$B18) -> 0 | K18: =INDIRECT(K$11&"!"&$B18) -> - | L18: =INDIRECT(L$11&"!"&$B18) -> 0 | M18: =INDIRECT(M$11&"!"&$B18) -> - | ... Q18: =INDIRECT(Q$11&"!"&$B18) -> - | R18: =SUM(F18:Q18) -> 10
B19: D263 | D19: 戻り受注率 | F19: =INDIRECT(F$11&"!"&$B19) -> 0.36363636 | G19: =INDIRECT(G$11&"!"&$B19) -> 2 | H19: =INDIRECT(H$11&"!"&$B19) -> 0.27272727 | I19: =INDIRECT(I$11&"!"&$B19) -> 0.27272727 | J19: =INDIRECT(J$11&"!"&$B19) -> - | K19: =INDIRECT(K$11&"!"&$B19) -> 0 | L19: =INDIRECT(L$11&"!"&$B19) -> - | M19: =INDIRECT(M$11&"!"&$B19) -> 0 | ... Q19: =INDIRECT(Q$11&"!"&$B19) -> 0 | R19: =R18/R13 -> 3.6666667
B21: E257 | C21: =設定用!D7 -> 名義変更 | D21: 面談対応件数 | F21: =INDIRECT(F$11&"!"&$B21) -> 0.5 | G21: =INDIRECT(G$11&"!"&$B21) -> 0 | H21: =INDIRECT(H$11&"!"&$B21) -> 1 | I21: =INDIRECT(I$11&"!"&$B21) -> 1 | J21: =INDIRECT(J$11&"!"&$B21) -> - | K21: =INDIRECT(K$11&"!"&$B21) -> 0 | L21: =INDIRECT(L$11&"!"&$B21) -> - | M21: =INDIRECT(M$11&"!"&$B21) -> 0 | ... Q21: =INDIRECT(Q$11&"!"&$B21) -> 0 | R21: =SUM(F21:Q21) -> 2.5
B22: E258 | D22: 受注件数 | F22: =INDIRECT(F$11&"!"&$B22) -> 0 | G22: =INDIRECT(G$11&"!"&$B22) -> 0 | H22: =INDIRECT(H$11&"!"&$B22) -> 0 | I22: =INDIRECT(I$11&"!"&$B22) -> 0 | J22: =INDIRECT(J$11&"!"&$B22) -> 0 | K22: =INDIRECT(K$11&"!"&$B22) -> - | L22: =INDIRECT(L$11&"!"&$B22) -> 0 | M22: =INDIRECT(M$11&"!"&$B22) -> - | ... Q22: =INDIRECT(Q$11&"!"&$B22) -> - | R22: =SUM(F22:Q22) -> 0
B23: E259 | D23: 受注率 | F23: =INDIRECT(F$11&"!"&$B23) -> 0 | G23: =INDIRECT(G$11&"!"&$B23) -> 0 | H23: =INDIRECT(H$11&"!"&$B23) -> 0 | I23: =INDIRECT(I$11&"!"&$B23) -> 0 | J23: =INDIRECT(J$11&"!"&$B23) -> - | K23: =INDIRECT(K$11&"!"&$B23) -> 0 | L23: =INDIRECT(L$11&"!"&$B23) -> - | M23: =INDIRECT(M$11&"!"&$B23) -> 0 | ... Q23: =INDIRECT(Q$11&"!"&$B23) -> 0 | R23: =R22/R21 -> 0
B24: E260 | D24: 即受注 件数 | F24: =INDIRECT(F$11&"!"&$B24) -> 0 | G24: =INDIRECT(G$11&"!"&$B24) -> 0 | H24: =INDIRECT(H$11&"!"&$B24) -> 0 | I24: =INDIRECT(I$11&"!"&$B24) -> 0 | J24: =INDIRECT(J$11&"!"&$B24) -> 0 | K24: =INDIRECT(K$11&"!"&$B24) -> - | L24: =INDIRECT(L$11&"!"&$B24) -> 0 | M24: =INDIRECT(M$11&"!"&$B24) -> - | ... Q24: =INDIRECT(Q$11&"!"&$B24) -> - | R24: =SUM(F24:Q24) -> 0
B25: E261 | D25: 即受注率 | F25: =INDIRECT(F$11&"!"&$B25) -> 0 | G25: =INDIRECT(G$11&"!"&$B25) -> 0 | H25: =INDIRECT(H$11&"!"&$B25) -> 0 | I25: =INDIRECT(I$11&"!"&$B25) -> 0 | J25: =INDIRECT(J$11&"!"&$B25) -> - | K25: =INDIRECT(K$11&"!"&$B25) -> 0 | L25: =INDIRECT(L$11&"!"&$B25) -> - | M25: =INDIRECT(M$11&"!"&$B25) -> 0 | ... Q25: =INDIRECT(Q$11&"!"&$B25) -> 0 | R25: =R24/R21 -> 0
B26: E262 | D26: 戻り受注 件数 | F26: =INDIRECT(F$11&"!"&$B26) -> 0 | G26: =INDIRECT(G$11&"!"&$B26) -> 0 | H26: =INDIRECT(H$11&"!"&$B26) -> 0 | I26: =INDIRECT(I$11&"!"&$B26) -> 0 | J26: =INDIRECT(J$11&"!"&$B26) -> 0 | K26: =INDIRECT(K$11&"!"&$B26) -> - | L26: =INDIRECT(L$11&"!"&$B26) -> 0 | M26: =INDIRECT(M$11&"!"&$B26) -> - | ... Q26: =INDIRECT(Q$11&"!"&$B26) -> - | R26: =SUM(F26:Q26) -> 0
B27: E263 | D27: 戻り受注率 | F27: =INDIRECT(F$11&"!"&$B27) -> 0 | G27: =INDIRECT(G$11&"!"&$B27) -> 0 | H27: =INDIRECT(H$11&"!"&$B27) -> 0 | I27: =INDIRECT(I$11&"!"&$B27) -> 0 | J27: =INDIRECT(J$11&"!"&$B27) -> - | K27: =INDIRECT(K$11&"!"&$B27) -> 0 | L27: =INDIRECT(L$11&"!"&$B27) -> - | M27: =INDIRECT(M$11&"!"&$B27) -> 0 | ... Q27: =INDIRECT(Q$11&"!"&$B27) -> 0 | R27: =R26/R21 -> 0
B29: F257 | C29: =設定用!D8 -> 相続税申告 | D29: 面談対応件数 | F29: =INDIRECT(F$11&"!"&$B29) -> 0.66666667 | G29: =INDIRECT(G$11&"!"&$B29) -> 0 | H29: =INDIRECT(H$11&"!"&$B29) -> 0 | I29: =INDIRECT(I$11&"!"&$B29) -> 0 | J29: =INDIRECT(J$11&"!"&$B29) -> - | K29: =INDIRECT(K$11&"!"&$B29) -> 0 | L29: =INDIRECT(L$11&"!"&$B29) -> - | M29: =INDIRECT(M$11&"!"&$B29) -> 0 | ... Q29: =INDIRECT(Q$11&"!"&$B29) -> 0 | R29: =SUM(F29:Q29) -> 0.66666667
B30: F258 | D30: 受注件数 | F30: =INDIRECT(F$11&"!"&$B30) -> 0 | G30: =INDIRECT(G$11&"!"&$B30) -> - | H30: =INDIRECT(H$11&"!"&$B30) -> 0 | I30: =INDIRECT(I$11&"!"&$B30) -> 0 | J30: =INDIRECT(J$11&"!"&$B30) -> 0 | K30: =INDIRECT(K$11&"!"&$B30) -> - | L30: =INDIRECT(L$11&"!"&$B30) -> 0 | M30: =INDIRECT(M$11&"!"&$B30) -> - | ... Q30: =INDIRECT(Q$11&"!"&$B30) -> - | R30: =SUM(F30:Q30) -> 0
B31: F259 | D31: 受注率 | F31: =INDIRECT(F$11&"!"&$B31) -> 0 | G31: =INDIRECT(G$11&"!"&$B31) -> 0 | H31: =INDIRECT(H$11&"!"&$B31) -> 0 | I31: =INDIRECT(I$11&"!"&$B31) -> 0 | J31: =INDIRECT(J$11&"!"&$B31) -> - | K31: =INDIRECT(K$11&"!"&$B31) -> 0 | L31: =INDIRECT(L$11&"!"&$B31) -> - | M31: =INDIRECT(M$11&"!"&$B31) -> 0 | ... Q31: =INDIRECT(Q$11&"!"&$B31) -> 0 | R31: =R30/R29 -> 0
B32: F260 | D32: 即受注 件数 | F32: =INDIRECT(F$11&"!"&$B32) -> 0 | G32: =INDIRECT(G$11&"!"&$B32) -> - | H32: =INDIRECT(H$11&"!"&$B32) -> 0 | I32: =INDIRECT(I$11&"!"&$B32) -> 0 | J32: =INDIRECT(J$11&"!"&$B32) -> 0 | K32: =INDIRECT(K$11&"!"&$B32) -> - | L32: =INDIRECT(L$11&"!"&$B32) -> 0 | M32: =INDIRECT(M$11&"!"&$B32) -> - | ... Q32: =INDIRECT(Q$11&"!"&$B32) -> - | R32: =SUM(F32:Q32) -> 0
B33: F261 | D33: 即受注率 | F33: =INDIRECT(F$11&"!"&$B33) -> 0 | G33: =INDIRECT(G$11&"!"&$B33) -> 0 | H33: =INDIRECT(H$11&"!"&$B33) -> 0 | I33: =INDIRECT(I$11&"!"&$B33) -> 0 | J33: =INDIRECT(J$11&"!"&$B33) -> - | K33: =INDIRECT(K$11&"!"&$B33) -> 0 | L33: =INDIRECT(L$11&"!"&$B33) -> - | M33: =INDIRECT(M$11&"!"&$B33) -> 0 | ... Q33: =INDIRECT(Q$11&"!"&$B33) -> 0 | R33: =R32/R29 -> 0
B34: F262 | D34: 戻り受注 件数 | F34: =INDIRECT(F$11&"!"&$B34) -> 1 | G34: =INDIRECT(G$11&"!"&$B34) -> - | H34: =INDIRECT(H$11&"!"&$B34) -> 0 | I34: =INDIRECT(I$11&"!"&$B34) -> 1 | J34: =INDIRECT(J$11&"!"&$B34) -> 0 | K34: =INDIRECT(K$11&"!"&$B34) -> - | L34: =INDIRECT(L$11&"!"&$B34) -> 0 | M34: =INDIRECT(M$11&"!"&$B34) -> - | ... Q34: =INDIRECT(Q$11&"!"&$B34) -> - | R34: =SUM(F34:Q34) -> 2
B35: F263 | D35: 戻り受注率 | F35: =INDIRECT(F$11&"!"&$B35) -> 0.33333333 | G35: =INDIRECT(G$11&"!"&$B35) -> 0 | H35: =INDIRECT(H$11&"!"&$B35) -> 0 | I35: =INDIRECT(I$11&"!"&$B35) -> 0.33333333 | J35: =INDIRECT(J$11&"!"&$B35) -> - | K35: =INDIRECT(K$11&"!"&$B35) -> 0 | L35: =INDIRECT(L$11&"!"&$B35) -> - | M35: =INDIRECT(M$11&"!"&$B35) -> 0 | ... Q35: =INDIRECT(Q$11&"!"&$B35) -> 0 | R35: =R34/R29 -> 3
B37: G257 | C37: =設定用!D9 -> 遺言書 | D37: 面談対応件数 | F37: =INDIRECT(F$11&"!"&$B37) -> 0 | G37: =INDIRECT(G$11&"!"&$B37) -> 2 | H37: =INDIRECT(H$11&"!"&$B37) -> 0.3125 | I37: =INDIRECT(I$11&"!"&$B37) -> 0 | J37: =INDIRECT(J$11&"!"&$B37) -> - | K37: =INDIRECT(K$11&"!"&$B37) -> 0 | L37: =INDIRECT(L$11&"!"&$B37) -> - | M37: =INDIRECT(M$11&"!"&$B37) -> 0 | ... Q37: =INDIRECT(Q$11&"!"&$B37) -> 0 | R37: =SUM(F37:Q37) -> 2.3125
B38: G258 | D38: 受注件数 | F38: =INDIRECT(F$11&"!"&$B38) -> 2 | G38: =INDIRECT(G$11&"!"&$B38) -> 0.2 | H38: =INDIRECT(H$11&"!"&$B38) -> 1 | I38: =INDIRECT(I$11&"!"&$B38) -> 0 | J38: =INDIRECT(J$11&"!"&$B38) -> 0 | K38: =INDIRECT(K$11&"!"&$B38) -> - | L38: =INDIRECT(L$11&"!"&$B38) -> 0 | M38: =INDIRECT(M$11&"!"&$B38) -> - | ... Q38: =INDIRECT(Q$11&"!"&$B38) -> - | R38: =SUM(F38:Q38) -> 3.2
B39: G259 | D39: 受注率 | F39: =INDIRECT(F$11&"!"&$B39) -> 0.28571429 | G39: =INDIRECT(G$11&"!"&$B39) -> 2 | H39: =INDIRECT(H$11&"!"&$B39) -> 0.0625 | I39: =INDIRECT(I$11&"!"&$B39) -> 0 | J39: =INDIRECT(J$11&"!"&$B39) -> - | K39: =INDIRECT(K$11&"!"&$B39) -> 0 | L39: =INDIRECT(L$11&"!"&$B39) -> - | M39: =INDIRECT(M$11&"!"&$B39) -> 0 | ... Q39: =INDIRECT(Q$11&"!"&$B39) -> 0 | R39: =R38/R37 -> 1.3837838
B40: G260 | D40: 即受注 件数 | F40: =INDIRECT(F$11&"!"&$B40) -> 0 | G40: =INDIRECT(G$11&"!"&$B40) -> 0.2 | H40: =INDIRECT(H$11&"!"&$B40) -> 2 | I40: =INDIRECT(I$11&"!"&$B40) -> 0 | J40: =INDIRECT(J$11&"!"&$B40) -> 0 | K40: =INDIRECT(K$11&"!"&$B40) -> - | L40: =INDIRECT(L$11&"!"&$B40) -> 0 | M40: =INDIRECT(M$11&"!"&$B40) -> - | ... Q40: =INDIRECT(Q$11&"!"&$B40) -> - | R40: =SUM(F40:Q40) -> 2.2
B41: G261 | D41: 即受注率 | F41: =INDIRECT(F$11&"!"&$B41) -> 0 | G41: =INDIRECT(G$11&"!"&$B41) -> 0 | H41: =INDIRECT(H$11&"!"&$B41) -> 0.125 | I41: =INDIRECT(I$11&"!"&$B41) -> 0 | J41: =INDIRECT(J$11&"!"&$B41) -> - | K41: =INDIRECT(K$11&"!"&$B41) -> 0 | L41: =INDIRECT(L$11&"!"&$B41) -> - | M41: =INDIRECT(M$11&"!"&$B41) -> 0 | ... Q41: =INDIRECT(Q$11&"!"&$B41) -> 0 | R41: =R40/R37 -> 0.95135135
B42: G262 | D42: 戻り受注 件数 | F42: =INDIRECT(F$11&"!"&$B42) -> 4 | G42: =INDIRECT(G$11&"!"&$B42) -> 0 | H42: =INDIRECT(H$11&"!"&$B42) -> 4 | I42: =INDIRECT(I$11&"!"&$B42) -> 4 | J42: =INDIRECT(J$11&"!"&$B42) -> 0 | K42: =INDIRECT(K$11&"!"&$B42) -> - | L42: =INDIRECT(L$11&"!"&$B42) -> 0 | M42: =INDIRECT(M$11&"!"&$B42) -> - | ... Q42: =INDIRECT(Q$11&"!"&$B42) -> - | R42: =SUM(F42:Q42) -> 12
B43: G263 | D43: 戻り受注率 | F43: =INDIRECT(F$11&"!"&$B43) -> 0.57142857 | G43: =INDIRECT(G$11&"!"&$B43) -> 1 | H43: =INDIRECT(H$11&"!"&$B43) -> 0.25 | I43: =INDIRECT(I$11&"!"&$B43) -> 0.5 | J43: =INDIRECT(J$11&"!"&$B43) -> - | K43: =INDIRECT(K$11&"!"&$B43) -> 0 | L43: =INDIRECT(L$11&"!"&$B43) -> - | M43: =INDIRECT(M$11&"!"&$B43) -> 0 | ... Q43: =INDIRECT(Q$11&"!"&$B43) -> 0 | R43: =R42/R37 -> 5.1891892
B45: H257 | C45: =設定用!D10 -> 生前対策 | D45: 面談対応件数 | F45: =INDIRECT(F$11&"!"&$B45) -> 0 | G45: =INDIRECT(G$11&"!"&$B45) -> 0 | H45: =INDIRECT(H$11&"!"&$B45) -> 0 | I45: =INDIRECT(I$11&"!"&$B45) -> 0 | J45: =INDIRECT(J$11&"!"&$B45) -> - | K45: =INDIRECT(K$11&"!"&$B45) -> 0 | L45: =INDIRECT(L$11&"!"&$B45) -> - | M45: =INDIRECT(M$11&"!"&$B45) -> 0 | ... Q45: =INDIRECT(Q$11&"!"&$B45) -> 0 | R45: =SUM(F45:Q45) -> 0
B46: H258 | D46: 受注件数 | F46: =INDIRECT(F$11&"!"&$B46) -> 2 | G46: =INDIRECT(G$11&"!"&$B46) -> 0 | H46: =INDIRECT(H$11&"!"&$B46) -> 0 | I46: =INDIRECT(I$11&"!"&$B46) -> 0 | J46: =INDIRECT(J$11&"!"&$B46) -> 0 | K46: =INDIRECT(K$11&"!"&$B46) -> - | L46: =INDIRECT(L$11&"!"&$B46) -> 0 | M46: =INDIRECT(M$11&"!"&$B46) -> - | ... Q46: =INDIRECT(Q$11&"!"&$B46) -> - | R46: =SUM(F46:Q46) -> 2
...

Sheet 日別受電集計
B1: 1日 | C1: 2日 | D1: 3日 | E1: 4日 | F1: 5日 | G1: 6日 | H1: 7日 | I1: 8日 | J1: 9日 | K1: 10日 | L1: 11日 | M1: 12日 | N1: 13日 | O1: 14日 | P1: 15日 | Q1: 16日 | R1: 17日 | S1: 18日 | T1: 19日 | U1: 20日 | V1: 21日 | W1: 22日 | X1: 23日 | Y1: 24日 | Z1: 25日 | AA1: 26日 | AB1: 27日 | AC1: 28日 | AD1: 29日 | AE1: 30日 | AF1: 31日 | AG1: Ave.
A2: 1月 | B2: 45292 | C2: 45293 | D2: 45294 | E2: 45295 | F2: 45296 | G2: 45297 | H2: 45298 | I2: 45299 | J2: 45300 | K2: 45301 | L2: 45302 | M2: 45303 | N2: 45304 | O2: 45305 | P2: 45306 | Q2: 45307 | R2: 45308 | S2: 45309 | T2: 45310 | U2: 45311 | V2: 45312 | W2: 45313 | X2: 45314 | Y2: 45315 | Z2: 45316 | AA2: 45317 | AB2: 45318 | AC2: 45319 | AD2: 45320 | AE2: 45321 | AF2: 45322 | AG2: Ave.
B3: =CHOOSE(WEEKDAY(B2), "日", "月", "火", "水", "木", "金", "土") -> 月 | C3: =CHOOSE(WEEKDAY(C2), "日", "月", "火", "水", "木", "金", "土") -> 火 | D3: =CHOOSE(WEEKDAY(D2), "日", "月", "火", "水", "木", "金", "土") -> 水 | E3: =CHOOSE(WEEKDAY(E2), "日", "月", "火", "水", "木", "金", "土") -> 木 | F3: =CHOOSE(WEEKDAY(F2), "日", "月", "火", "水", "木", "金", "土") -> 金 | G3: =CHOOSE(WEEKDAY(G2), "日", "月", "火", "水", "木", "金", "土") -> 土 | H3: =CHOOSE(WEEKDAY(H2), "日", "月", "火", "水", "木", "金", "土") -> 日 | I3: =CHOOSE(WEEKDAY(I2), "日", "月", "火", "水", "木", "金", "土") -> 月 | ... AF3: =CHOOSE(WEEKDAY(AF2), "日", "月", "火", "水", "木", "金", "土") -> 水
A4: =SUM(B4:AF4) -> 0 | B4: =IF(TODAY()<=B2,"", COUNTIF('1月'!$C3:$C1013,B2)) -> 0 | C4: =IF(TODAY()<=C2,"", COUNTIF('1月'!$C3:$C1013,C2)) -> 0 | D4: =IF(TODAY()<=D2,"", COUNTIF('1月'!$C3:$C1013,D2)) -> 0 | E4: =IF(TODAY()<=E2,"", COUNTIF('1月'!$C3:$C1013,E2)) -> 0 | F4: =IF(TODAY()<=F2,"", COUNTIF('1月'!$C3:$C1013,F2)) -> 0 | G4: =IF(TODAY()<=G2,"", COUNTIF('1月'!$C3:$C1013,G2)) -> 0 | H4: =IF(TODAY()<=H2,"", COUNTIF('1月'!$C3:$C1013,H2)) -> 0 | I4: =IF(TODAY()<=I2,"", COUNTIF('1月'!$C3:$C1013,I2)) -> 0 | ... AF4: =IF(TODAY()<=AF2,"", COUNTIF('1月'!$C3:$C1013,AF2)) -> 0 | AG4: =IFERROR(AVERAGE(B4:AF4),0) -> 0
A6: 2月 | B6: 45323 | C6: 45324 | D6: 45325 | E6: 45326 | F6: 45327 | G6: 45328 | H6: 45329 | I6: 45330 | J6: 45331 | K6: 45332 | L6: 45333 | M6: 45334 | N6: 45335 | O6: 45336 | P6: 45337 | Q6: 45338 | R6: 45339 | S6: 45340 | T6: 45341 | U6: 45342 | V6: 45343 | W6: 45344 | X6: 45345 | Y6: 45346 | Z6: 45347 | AA6: 45348 | AB6: 45349 | AC6: 45350 | AD6: 45351 | AG6: Ave.
B7: =CHOOSE(WEEKDAY(B6), "日", "月", "火", "水", "木", "金", "土") -> 木 | C7: =CHOOSE(WEEKDAY(C6), "日", "月", "火", "水", "木", "金", "土") -> 金 | D7: =CHOOSE(WEEKDAY(D6), "日", "月", "火", "水", "木", "金", "土") -> 土 | E7: =CHOOSE(WEEKDAY(E6), "日", "月", "火", "水", "木", "金", "土") -> 日 | F7: =CHOOSE(WEEKDAY(F6), "日", "月", "火", "水", "木", "金", "土") -> 月 | G7: =CHOOSE(WEEKDAY(G6), "日", "月", "火", "水", "木", "金", "土") -> 火 | H7: =CHOOSE(WEEKDAY(H6), "日", "月", "火", "水", "木", "金", "土") -> 水 | I7: =CHOOSE(WEEKDAY(I6), "日", "月", "火", "水", "木", "金", "土") -> 木 | ... AF7: =CHOOSE(WEEKDAY(AF6), "日", "月", "火", "水", "木", "金", "土") -> 土
A8: =SUM(B8:AF8) -> 0 | B8: =IF(TODAY()<=B6,"", COUNTIF('2月'!$C3:$C1013,B6)) -> 0 | C8: =IF(TODAY()<=C6,"", COUNTIF('2月'!$C3:$C1013,C6)) -> 0 | D8: =IF(TODAY()<=D6,"", COUNTIF('2月'!$C3:$C1013,D6)) -> 0 | E8: =IF(TODAY()<=E6,"", COUNTIF('2月'!$C3:$C1013,E6)) -> 0 | F8: =IF(TODAY()<=F6,"", COUNTIF('2月'!$C3:$C1013,F6)) -> 0 | G8: =IF(TODAY()<=G6,"", COUNTIF('2月'!$C3:$C1013,G6)) -> 0 | H8: =IF(TODAY()<=H6,"", COUNTIF('2月'!$C3:$C1013,H6)) -> 0 | I8: =IF(TODAY()<=I6,"", COUNTIF('2月'!$C3:$C1013,I6)) -> 0 | ... AD8: =IF(TODAY()<=AD6,"", COUNTIF('2月'!$C3:$C1013,AD6)) -> 0 | AG8: =IFERROR(AVERAGE(B8:AF8),0) -> 0
A10: 3月 | B10: 45352 | C10: 45353 | D10: 45354 | E10: 45355 | F10: 45356 | G10: 45357 | H10: 45358 | I10: 45359 | J10: 45360 | K10: 45361 | L10: 45362 | M10: 45363 | N10: 45364 | O10: 45365 | P10: 45366 | Q10: 45367 | R10: 45368 | S10: 45369 | T10: 45370 | U10: 45371 | V10: 45372 | W10: 45373 | X10: 45374 | Y10: 45375 | Z10: 45376 | AA10: 45377 | AB10: 45378 | AC10: 45379 | AD10: 45380 | AE10: 45381 | AF10: 45382 | AG10: Ave.
B11: =CHOOSE(WEEKDAY(B10), "日", "月", "火", "水", "木", "金", "土") -> 金 | C11: =CHOOSE(WEEKDAY(C10), "日", "月", "火", "水", "木", "金", "土") -> 土 | D11: =CHOOSE(WEEKDAY(D10), "日", "月", "火", "水", "木", "金", "土") -> 日 | E11: =CHOOSE(WEEKDAY(E10), "日", "月", "火", "水", "木", "金", "土") -> 月 | F11: =CHOOSE(WEEKDAY(F10), "日", "月", "火", "水", "木", "金", "土") -> 火 | G11: =CHOOSE(WEEKDAY(G10), "日", "月", "火", "水", "木", "金", "土") -> 水 | H11: =CHOOSE(WEEKDAY(H10), "日", "月", "火", "水", "木", "金", "土") -> 木 | I11: =CHOOSE(WEEKDAY(I10), "日", "月", "火", "水", "木", "金", "土") -> 金 | ... AF11: =CHOOSE(WEEKDAY(AF10), "日", "月", "火", "水", "木", "金", "土") -> 日
A12: =SUM(B12:AF12) -> 0 | B12: =IF(TODAY()<=B10,"", COUNTIF('3月'!$C3:$C1013,B10)) -> 0 | C12: =IF(TODAY()<=C10,"", COUNTIF('3月'!$C3:$C1013,C10)) -> 0 | D12: =IF(TODAY()<=D10,"", COUNTIF('3月'!$C3:$C1013,D10)) -> 0 | E12: =IF(TODAY()<=E10,"", COUNTIF('3月'!$C3:$C1013,E10)) -> 0 | F12: =IF(TODAY()<=F10,"", COUNTIF('3月'!$C3:$C1013,F10)) -> 0 | G12: =IF(TODAY()<=G10,"", COUNTIF('3月'!$C3:$C1013,G10)) -> 0 | H12: =IF(TODAY()<=H10,"", COUNTIF('3月'!$C3:$C1013,H10)) -> 0 | I12: =IF(TODAY()<=I10,"", COUNTIF('3月'!$C3:$C1013,I10)) -> 0 | ... AF12: =IF(TODAY()<=AF10,"", COUNTIF('3月'!$C3:$C1013,AF10)) -> 0 | AG12: =IFERROR(AVERAGE(B12:AF12),0) -> 0
A14: 4月 | B14: 45383 | C14: 45384 | D14: 45385 | E14: 45386 | F14: 45387 | G14: 45388 | H14: 45389 | I14: 45390 | J14: 45391 | K14: 45392 | L14: 45393 | M14: 45394 | N14: 45395 | O14: 45396 | P14: 45397 | Q14: 45398 | R14: 45399 | S14: 45400 | T14: 45401 | U14: 45402 | V14: 45403 | W14: 45404 | X14: 45405 | Y14: 45406 | Z14: 45407 | AA14: 45408 | AB14: 45409 | AC14: 45410 | AD14: 45411 | AE14: 45412 | AG14: Ave.
B15: =CHOOSE(WEEKDAY(B14), "日", "月", "火", "水", "木", "金", "土") -> 月 | C15: =CHOOSE(WEEKDAY(C14), "日", "月", "火", "水", "木", "金", "土") -> 火 | D15: =CHOOSE(WEEKDAY(D14), "日", "月", "火", "水", "木", "金", "土") -> 水 | E15: =CHOOSE(WEEKDAY(E14), "日", "月", "火", "水", "木", "金", "土") -> 木 | F15: =CHOOSE(WEEKDAY(F14), "日", "月", "火", "水", "木", "金", "土") -> 金 | G15: =CHOOSE(WEEKDAY(G14), "日", "月", "火", "水", "木", "金", "土") -> 土 | H15: =CHOOSE(WEEKDAY(H14), "日", "月", "火", "水", "木", "金", "土") -> 日 | I15: =CHOOSE(WEEKDAY(I14), "日", "月", "火", "水", "木", "金", "土") -> 月 | ... AF15: =CHOOSE(WEEKDAY(AF14), "日", "月", "火", "水", "木", "金", "土") -> 土
A16: =SUM(B16:AF16) -> 0 | B16: =IF(TODAY()<=B14,"", COUNTIF('4月'!$C3:$C1013,B14)) -> 0 | C16: =IF(TODAY()<=C14,"", COUNTIF('4月'!$C3:$C1013,C14)) -> 0 | D16: =IF(TODAY()<=D14,"", COUNTIF('4月'!$C3:$C1013,D14)) -> 0 | E16: =IF(TODAY()<=E14,"", COUNTIF('4月'!$C3:$C1013,E14)) -> 0 | F16: =IF(TODAY()<=F14,"", COUNTIF('4月'!$C3:$C1013,F14)) -> 0 | G16: =IF(TODAY()<=G14,"", COUNTIF('4月'!$C3:$C1013,G14)) -> 0 | H16: =IF(TODAY()<=H14,"", COUNTIF('4月'!$C3:$C1013,H14)) -> 0 | I16: =IF(TODAY()<=I14,"", COUNTIF('4月'!$C3:$C1013,I14)) -> 0 | ... AE16: =IF(TODAY()<=AE14,"", COUNTIF('4月'!$C3:$C1013,AE14)) -> 0 | AG16: =IFERROR(AVERAGE(B16:AF16),0) -> 0
A18: 5月 | B18: 45413 | C18: 45414 | D18: 45415 | E18: 45416 | F18: 45417 | G18: 45418 | H18: 45419 | I18: 45420 | J18: 45421 | K18: 45422 | L18: 45423 | M18: 45424 | N18: 45425 | O18: 45426 | P18: 45427 | Q18: 45428 | R18: 45429 | S18: 45430 | T18: 45431 | U18: 45432 | V18: 45433 | W18: 45434 | X18: 45435 | Y18: 45436 | Z18: 45437 | AA18: 45438 | AB18: 45439 | AC18: 45440 | AD18: 45441 | AE18: 45442 | AF18: 45443 | AG18: Ave.
B19: =CHOOSE(WEEKDAY(B18), "日", "月", "火", "水", "木", "金", "土") -> 水 | C19: =CHOOSE(WEEKDAY(C18), "日", "月", "火", "水", "木", "金", "土") -> 木 | D19: =CHOOSE(WEEKDAY(D18), "日", "月", "火", "水", "木", "金", "土") -> 金 | E19: =CHOOSE(WEEKDAY(E18), "日", "月", "火", "水", "木", "金", "土") -> 土 | F19: =CHOOSE(WEEKDAY(F18), "日", "月", "火", "水", "木", "金", "土") -> 日 | G19: =CHOOSE(WEEKDAY(G18), "日", "月", "火", "水", "木", "金", "土") -> 月 | H19: =CHOOSE(WEEKDAY(H18), "日", "月", "火", "水", "木", "金", "土") -> 火 | I19: =CHOOSE(WEEKDAY(I18), "日", "月", "火", "水", "木", "金", "土") -> 水 | ... AF19: =CHOOSE(WEEKDAY(AF18), "日", "月", "火", "水", "木", "金", "土") -> 金
A20: =SUM(B20:AF20) -> 0 | B20: =IF(TODAY()<=B18,"", COUNTIF('5月'!$C3:$C1013,B18)) -> 0 | C20: =IF(TODAY()<=C18,"", COUNTIF('5月'!$C3:$C1013,C18)) -> 0 | D20: =IF(TODAY()<=D18,"", COUNTIF('5月'!$C3:$C1013,D18)) -> 0 | E20: =IF(TODAY()<=E18,"", COUNTIF('5月'!$C3:$C1013,E18)) -> 0 | F20: =IF(TODAY()<=F18,"", COUNTIF('5月'!$C3:$C1013,F18)) -> 0 | G20: =IF(TODAY()<=G18,"", COUNTIF('5月'!$C3:$C1013,G18)) -> 0 | H20: =IF(TODAY()<=H18,"", COUNTIF('5月'!$C3:$C1013,H18)) -> 0 | I20: =IF(TODAY()<=I18,"", COUNTIF('5月'!$C3:$C1013,I18)) -> 0 | ... AF20: =IF(TODAY()<=AF18,"", COUNTIF('5月'!$C3:$C1013,AF18)) -> 0 | AG20: =IFERROR(AVERAGE(B20:AF20),0) -> 0
A22: 6月 | B22: 45444 | C22: 45445 | D22: 45446 | E22: 45447 | F22: 45448 | G22: 45449 | H22: 45450 | I22: 45451 | J22: 45452 | K22: 45453 | L22: 45454 | M22: 45455 | N22: 45456 | O22: 45457 | P22: 45458 | Q22: 45459 | R22: 45460 | S22: 45461 | T22: 45462 | U22: 45463 | V22: 45464 | W22: 45465 | X22: 45466 | Y22: 45467 | Z22: 45468 | AA22: 45469 | AB22: 45470 | AC22: 45471 | AD22: 45472 | AE22: 45473 | AG22: Ave.
B23: =CHOOSE(WEEKDAY(B22), "日", "月", "火", "水", "木", "金", "土") -> 土 | C23: =CHOOSE(WEEKDAY(C22), "日", "月", "火", "水", "木", "金", "土") -> 日 | D23: =CHOOSE(WEEKDAY(D22), "日", "月", "火", "水", "木", "金", "土") -> 月 | E23: =CHOOSE(WEEKDAY(E22), "日", "月", "火", "水", "木", "金", "土") -> 火 | F23: =CHOOSE(WEEKDAY(F22), "日", "月", "火", "水", "木", "金", "土") -> 水 | G23: =CHOOSE(WEEKDAY(G22), "日", "月", "火", "水", "木", "金", "土") -> 木 | H23: =CHOOSE(WEEKDAY(H22), "日", "月", "火", "水", "木", "金", "土") -> 金 | I23: =CHOOSE(WEEKDAY(I22), "日", "月", "火", "水", "木", "金", "土") -> 土 | ... AF23: =CHOOSE(WEEKDAY(AF22), "日", "月", "火", "水", "木", "金", "土") -> 土
A24: =SUM(B24:AF24) -> 0 | B24: =IF(TODAY()<=B22,"", COUNTIF('6月'!$C3:$C1013,B22)) -> 0 | C24: =IF(TODAY()<=C22,"", COUNTIF('6月'!$C3:$C1013,C22)) -> 0 | D24: =IF(TODAY()<=D22,"", COUNTIF('6月'!$C3:$C1013,D22)) -> 0 | E24: =IF(TODAY()<=E22,"", COUNTIF('6月'!$C3:$C1013,E22)) -> 0 | F24: =IF(TODAY()<=F22,"", COUNTIF('6月'!$C3:$C1013,F22)) -> 0 | G24: =IF(TODAY()<=G22,"", COUNTIF('6月'!$C3:$C1013,G22)) -> 0 | H24: =IF(TODAY()<=H22,"", COUNTIF('6月'!$C3:$C1013,H22)) -> 0 | I24: =IF(TODAY()<=I22,"", COUNTIF('6月'!$C3:$C1013,I22)) -> 0 | ... AE24: =IF(TODAY()<=AE22,"", COUNTIF('6月'!$C3:$C1013,AE22)) -> 0 | AG24: =IFERROR(AVERAGE(B24:AF24),0) -> 0
A26: 7月 | B26: 45474 | C26: 45475 | D26: 45476 | E26: 45477 | F26: 45478 | G26: 45479 | H26: 45480 | I26: 45481 | J26: 45482 | K26: 45483 | L26: 45484 | M26: 45485 | N26: 45486 | O26: 45487 | P26: 45488 | Q26: 45489 | R26: 45490 | S26: 45491 | T26: 45492 | U26: 45493 | V26: 45494 | W26: 45495 | X26: 45496 | Y26: 45497 | Z26: 45498 | AA26: 45499 | AB26: 45500 | AC26: 45501 | AD26: 45502 | AE26: 45503 | AF26: 45504 | AG26: Ave.
B27: =CHOOSE(WEEKDAY(B26), "日", "月", "火", "水", "木", "金", "土") -> 月 | C27: =CHOOSE(WEEKDAY(C26), "日", "月", "火", "水", "木", "金", "土") -> 火 | D27: =CHOOSE(WEEKDAY(D26), "日", "月", "火", "水", "木", "金", "土") -> 水 | E27: =CHOOSE(WEEKDAY(E26), "日", "月", "火", "水", "木", "金", "土") -> 木 | F27: =CHOOSE(WEEKDAY(F26), "日", "月", "火", "水", "木", "金", "土") -> 金 | G27: =CHOOSE(WEEKDAY(G26), "日", "月", "火", "水", "木", "金", "土") -> 土 | H27: =CHOOSE(WEEKDAY(H26), "日", "月", "火", "水", "木", "金", "土") -> 日 | I27: =CHOOSE(WEEKDAY(I26), "日", "月", "火", "水", "木", "金", "土") -> 月 | ... AF27: =CHOOSE(WEEKDAY(AF26), "日", "月", "火", "水", "木", "金", "土") -> 水
A28: =SUM(B28:AF28) -> 0 | B28: =IF(TODAY()<=B26,"", COUNTIF('7月'!$C3:$C1013,B26)) -> 0 | C28: =IF(TODAY()<=C26,"", COUNTIF('7月'!$C3:$C1013,C26)) -> 0 | D28: =IF(TODAY()<=D26,"", COUNTIF('7月'!$C3:$C1013,D26)) -> 0 | E28: =IF(TODAY()<=E26,"", COUNTIF('7月'!$C3:$C1013,E26)) -> 0 | F28: =IF(TODAY()<=F26,"", COUNTIF('7月'!$C3:$C1013,F26)) -> 0 | G28: =IF(TODAY()<=G26,"", COUNTIF('7月'!$C3:$C1013,G26)) -> 0 | H28: =IF(TODAY()<=H26,"", COUNTIF('7月'!$C3:$C1013,H26)) -> 0 | I28: =IF(TODAY()<=I26,"", COUNTIF('7月'!$C3:$C1013,I26)) -> 0 | ... AF28: =IF(TODAY()<=AF26,"", COUNTIF('7月'!$C3:$C1013,AF26)) -> 0 | AG28: =IFERROR(AVERAGE(B28:AF28),0) -> 0
A30: 8月 | B30: 45505 | C30: 45506 | D30: 45507 | E30: 45508 | F30: 45509 | G30: 45510 | H30: 45511 | I30: 45512 | J30: 45513 | K30: 45514 | L30: 45515 | M30: 45516 | N30: 45517 | O30: 45518 | P30: 45519 | Q30: 45520 | R30: 45521 | S30: 45522 | T30: 45523 | U30: 45524 | V30: 45525 | W30: 45526 | X30: 45527 | Y30: 45528 | Z30: 45529 | AA30: 45530 | AB30: 45531 | AC30: 45532 | AD30: 45533 | AE30: 45534 | AF30: 45535 | AG30: Ave.
B31: =CHOOSE(WEEKDAY(B30), "日", "月", "火", "水", "木", "金", "土") -> 木 | C31: =CHOOSE(WEEKDAY(C30), "日", "月", "火", "水", "木", "金", "土") -> 金 | D31: =CHOOSE(WEEKDAY(D30), "日", "月", "火", "水", "木", "金", "土") -> 土 | E31: =CHOOSE(WEEKDAY(E30), "日", "月", "火", "水", "木", "金", "土") -> 日 | F31: =CHOOSE(WEEKDAY(F30), "日", "月", "火", "水", "木", "金", "土") -> 月 | G31: =CHOOSE(WEEKDAY(G30), "日", "月", "火", "水", "木", "金", "土") -> 火 | H31: =CHOOSE(WEEKDAY(H30), "日", "月", "火", "水", "木", "金", "土") -> 水 | I31: =CHOOSE(WEEKDAY(I30), "日", "月", "火", "水", "木", "金", "土") -> 木 | ... AF31: =CHOOSE(WEEKDAY(AF30), "日", "月", "火", "水", "木", "金", "土") -> 土
A32: =SUM(B32:AF32) -> 0 | B32: =IF(TODAY()<=B30,"", COUNTIF('8月'!$C6:$C1013,B30)) -> 0 | C32: =IF(TODAY()<=C30,"", COUNTIF('8月'!$C6:$C1013,C30)) -> 0 | D32: =IF(TODAY()<=D30,"", COUNTIF('8月'!$C6:$C1013,D30)) -> 0 | E32: =IF(TODAY()<=E30,"", COUNTIF('8月'!$C6:$C1013,E30)) -> 0 | F32: =IF(TODAY()<=F30,"", COUNTIF('8月'!$C6:$C1013,F30)) -> 0 | G32: =IF(TODAY()<=G30,"", COUNTIF('8月'!$C6:$C1013,G30)) -> 0 | H32: =IF(TODAY()<=H30,"", COUNTIF('8月'!$C6:$C1013,H30)) -> 0 | I32: =IF(TODAY()<=I30,"", COUNTIF('8月'!$C6:$C1013,I30)) -> 0 | ... AF32: =IF(TODAY()<=AF30,"", COUNTIF('8月'!$C6:$C1013,AF30)) -> 0 | AG32: =IFERROR(AVERAGE(B32:AF32),0) -> 0
A34: 9月 | B34: 45536 | C34: 45537 | D34: 45538 | E34: 45539 | F34: 45540 | G34: 45541 | H34: 45542 | I34: 45543 | J34: 45544 | K34: 45545 | L34: 45546 | M34: 45547 | N34: 45548 | O34: 45549 | P34: 45550 | Q34: 45551 | R34: 45552 | S34: 45553 | T34: 45554 | U34: 45555 | V34: 45556 | W34: 45557 | X34: 45558 | Y34: 45559 | Z34: 45560 | AA34: 45561 | AB34: 45562 | AC34: 45563 | AD34: 45564 | AE34: 45565 | AG34: Ave.
